Workbook

Sheet Dashboard
A1: Sales tracking
A2: Key Metrics | B2: YTD | C2: January | D2: February | E2: March | F2: April | G2: May | H2: June | I2: July | J2: August | K2: September | L2: October | M2: November | N2: December | O2: SPARKLINES
A3: Conversion Rate: | B3: =iferror(B12/B10,"") | C3: =Jan!I2 -> #REF! | D3: =IFERROR(Feb!I2,"") | E3: =Mar!I2 -> #REF! | F3: =IFERROR(Apr!I2,"") -> 0.13333333 | G3: =IFERROR(May!I2,"") -> 0.57142857 | H3: =IFERROR(Jun!I2,"") -> 0.64285714 | I3: =IFERROR(Jul!I2,"") -> 0.61111111 | J3: =IFERROR(Aug!I2,"") -> 0.54545455 | K3: =IFERROR(Sep!L2,"") -> 0.36170213 | L3: =IFERROR(Oct!L2,"") -> 0.65957447 | M3: =IFERROR(Nov!I2,"") | N3: =IFERROR(Dec!I2,"") | O3: =IFERROR(__xludf.DUMMYFUNCTION("IFERROR(SPARKLINE(C3:N3, {""chartype"", ""line""; ""color"", ""blue""})) "),"")
A4: Offer To Close Rate: | B4: =iferror(B12/B11,"") | C4: =Jan!I3 -> #REF! | D4: =IFERROR(Feb!I3,"") | E4: =IFERROR(Mar!I3,"") | F4: =IFERROR(Apr!I3,"") -> 0.13333333 | G4: =IFERROR(May!I3,"") -> 0.57142857 | H4: =IFERROR(Jun!I3,"") -> 0.64285714 | I4: =IFERROR(Jul!I3,"") -> 0.61111111 | J4: =IFERROR(Aug!I3,"") -> 0.54545455 | K4: =IFERROR(Sep!L3,"") -> 0.36170213 | L4: =IFERROR(Oct!L3,"") -> 0.65957447 | M4: =IFERROR(Nov!I3,"") | N4: =IFERROR(Dec!I3,"") | O4: =IFERROR(__xludf.DUMMYFUNCTION("IFERROR(SPARKLINE(C4:N4, {""chartype"", ""line""; ""color"", ""blue""})) "),"")
A5: Call To Offer Rate: | B5: =IFERROR(B11/B10,"") | C5: =Jan!I4 -> #REF! | D5: =IFERROR(Feb!I4,"") | E5: =IFERROR(Mar!I4,"") | F5: =IFERROR(Apr!I4,"") -> 1 | G5: =IFERROR(May!I4,"") -> 1 | H5: =IFERROR(Jun!I4,"") -> 1 | I5: =IFERROR(Jul!I4,"") -> 1 | J5: =IFERROR(Aug!I4,"") -> 1 | K5: =IFERROR(Sep!L4,"") -> 1 | L5: =IFERROR(Oct!L4,"") -> 1 | M5: =IFERROR(Nov!I4,"") | N5: =IFERROR(Dec!I4,"") | O5: =IFERROR(__xludf.DUMMYFUNCTION("IFERROR(SPARKLINE(C5:N5, {""chartype"", ""line""; ""color"", ""blue""})) "),"")
A6: Revenue: | B6: =IFERROR(SUM(C6:N6),"") | C6: =Jan!C3 -> #REF! | D6: =IFERROR(Feb!C3,"") | E6: =IFERROR(Mar!$C3,"") | F6: =IFERROR(Apr!$C3,"") -> 9000 | G6: =IFERROR(May!$C3,"") -> 38994 | H6: =IFERROR(Jun!$C3,"") -> 60000 | I6: =IFERROR(Jul!$C3,"") -> 79500 | J6: =IFERROR(Aug!$C3,"") -> 103500 | K6: =IFERROR(Sep!$C3,"") -> 151500 | L6: =IFERROR(Oct!$C3,"") -> 276000 | M6: =IFERROR(Nov!$C3,"") -> 160500 | N6: =IFERROR(Dec!$C3,"") -> 60000 | O6: =IFERROR(__xludf.DUMMYFUNCTION("IFERROR(SPARKLINE(C6:N6, {""chartype"", ""line""; ""color"", ""blue""})) "),"")
A7: Cash: | B7: =IFERROR(SUM(C7:N7),"") | C7: =Jan!C4 -> #REF! | D7: =IFERROR(Feb!C4,"") | E7: =IFERROR(Mar!$C4,"") | F7: =IFERROR(Apr!$C4,"") -> 3000 | G7: =IFERROR(May!$C4,"") -> 31498 | H7: =IFERROR(Jun!$C4,"") -> 34500 | I7: =IFERROR(Jul!$C4,"") -> 47000 | J7: =IFERROR(Aug!$C4,"") -> 49500 | K7: =IFERROR(Sep!$C4,"") -> 52500 | L7: =IFERROR(Oct!$C4,"") -> 88500 | M7: =IFERROR(Nov!$C4,"") -> 67500 | N7: =IFERROR(Dec!$C4,"") -> 25500 | O7: =IFERROR(__xludf.DUMMYFUNCTION("IFERROR(SPARKLINE(C7:N7, {""chartype"", ""line""; ""color"", ""blue""})) "),"")
A8: Bookings: | B8: =IFERROR(SUM(C8:N8),"") | C8: =Jan!I6 -> #REF! | D8: =IFERROR(Feb!I6,"") | E8: =IFERROR(Mar!$I6,"") | F8: =IFERROR(Apr!$I6,"") -> 15 | G8: =IFERROR(May!$I6,"") -> 14 | H8: =IFERROR(Jun!$I6,"") -> 14 | I8: =IFERROR(Jul!$I6,"") -> 18 | J8: =IFERROR(Aug!$I6,"") -> 23 | K8: =IFERROR(Sep!$L6,"") -> 80 | L8: =IFERROR(Oct!$L6,"") -> 71 | M8: =IFERROR(Nov!$I6,"") -> 41 | N8: =IFERROR(Dec!$I6,"") -> 17 | O8: =IFERROR(__xludf.DUMMYFUNCTION("IFERROR(SPARKLINE(C8:N8, {""chartype"", ""line""; ""color"", ""blue""})) "),"")
A9: Shows: | B9: =sum(C9:N9) -> #REF! | C9: =Jan!I7 -> #REF! | D9: =IFERROR(Feb!$I$7,"") | E9: =IFERROR(Mar!$I$7,"") | F9: =IFERROR(Apr!$I$7,"") -> 15 | G9: =IFERROR(May!$I$7,"") -> 14 | H9: =IFERROR(Jun!$I$7,"") -> 14 | I9: =IFERROR(Jul!$I$7,"") -> 18 | J9: =IFERROR(Aug!$I$7,"") -> 22 | K9: =IFERROR(Sep!$L$7,"") -> 47 | L9: =IFERROR(Oct!$L$7,"") -> 47 | M9: =IFERROR(Nov!$I$7,"") -> 33 | N9: =IFERROR(Dec!$I$7,"") -> 11 | O9: =IFERROR(__xludf.DUMMYFUNCTION("IFERROR(SPARKLINE(C9:N9, {""chartype"", ""line""; ""color"", ""blue""})) "),"")
A10: Calls: | B10: =IFERROR(SUM(C10:N10),"") | C10: =Jan!I7 -> #REF! | D10: =IFERROR(Feb!I8,"") | E10: =IFERROR(Mar!$I8,"") | F10: =IFERROR(Apr!$I8,"") -> 15 | G10: =IFERROR(May!$I8,"") -> 14 | H10: =IFERROR(Jun!$I8,"") -> 14 | I10: =IFERROR(Jul!$I8,"") -> 18 | J10: =IFERROR(Aug!$I8,"") -> 22 | K10: =IFERROR(Sep!$L8,"") -> 47 | L10: =IFERROR(Oct!$L8,"") -> 47 | M10: =IFERROR(Nov!$I8,"") -> 33 | N10: =IFERROR(Dec!$I8,"") -> 11 | O10: =IFERROR(__xludf.DUMMYFUNCTION("IFERROR(SPARKLINE(C10:N10, {""chartype"", ""line""; ""color"", ""blue""})) "),"")
A11: Offers: | B11: =IFERROR(SUM(C11:N11),"") | C11: =Jan!I9 -> #REF! | D11: =IFERROR(Feb!I9,"") | E11: =IFERROR(Mar!$I9,"") | F11: =IFERROR(Apr!$I9,"") -> 15 | G11: =IFERROR(May!$I9,"") -> 14 | H11: =IFERROR(Jun!$I9,"") -> 14 | I11: =IFERROR(Jul!$I9,"") -> 18 | J11: =IFERROR(Aug!$I9,"") -> 22 | K11: =IFERROR(Sep!$L9,"") -> 47 | L11: =IFERROR(Oct!$L9,"") -> 47 | M11: =IFERROR(Nov!$I9,"") -> 33 | N11: =IFERROR(Dec!$I9,"") -> 11 | O11: =IFERROR(__xludf.DUMMYFUNCTION("IFERROR(SPARKLINE(C11:N11, {""chartype"", ""line""; ""color"", ""blue""})) "),"")
A12: Deals: | B12: =IFERROR(SUM(C12:N12),"") | C12: =Jan!I10 -> #REF! | D12: =IFERROR(Feb!I10,"") | E12: =IFERROR(Mar!$I10,"") | F12: =IFERROR(Apr!$I10,"") -> 2 | G12: =IFERROR(May!$I10,"") -> 8 | H12: =IFERROR(Jun!$I10,"") -> 9 | I12: =IFERROR(Jul!$I10,"") -> 11 | J12: =IFERROR(Aug!$I10,"") -> 12 | K12: =IFERROR(Sep!$L10,"") -> 17 | L12: =IFERROR(Oct!$L10,"") -> 31 | M12: =IFERROR(Nov!$I10,"") -> 17 | N12: =IFERROR(Dec!$I10,"") -> 6 | O12: =IFERROR(__xludf.DUMMYFUNCTION("IFERROR(SPARKLINE(C12:N12, {""chartype"", ""line""; ""color"", ""blue""})) "),"")
A13: Full-Pay: | B13: =IFERROR(SUM(C13:N13),"") | C13: =Jan!F2 -> #REF! | D13: =IFERROR(Feb!F2,"") | E13: =IFERROR(Mar!$F2,"") | F13: =IFERROR(Apr!$F2,"") -> 2 | G13: =IFERROR(May!$F2,"") -> 7 | H13: =IFERROR(Jun!$F2,"") -> 3 | I13: =IFERROR(Jul!$F2,"") -> 4 | J13: =IFERROR(Aug!$F2,"") -> 3 | K13: =IFERROR(Sep!$I2,"") -> 2 | L13: =IFERROR(Oct!$I2,"") -> 1 | M13: =IFERROR(Nov!$F2,"") -> 4 | N13: =IFERROR(Dec!$F2,"") -> 2 | O13: =IFERROR(__xludf.DUMMYFUNCTION("IFERROR(SPARKLINE(C13:N13, {""chartype"", ""line""; ""color"", ""blue""})) "),"")
A14: Split-Pay: | B14: =IFERROR(SUM(C14:N14),"") | C14: =Jan!F3 -> #REF! | D14: =IFERROR(Feb!F3,"") | E14: =IFERROR(Mar!$F3,"") | F14: =IFERROR(Apr!$F3,"") -> 0 | G14: =IFERROR(May!$F3,"") -> 1 | H14: =IFERROR(Jun!$F3,"") -> 6 | I14: =IFERROR(Jul!$F3,"") -> 7 | J14: =IFERROR(Aug!$F3,"") -> 9 | K14: =IFERROR(Sep!$I3,"") -> 15 | L14: =IFERROR(Oct!$I3,"") -> 30 | M14: =IFERROR(Nov!$F3,"") -> 13 | N14: =IFERROR(Dec!$F3,"") -> 4 | O14: =IFERROR(__xludf.DUMMYFUNCTION("IFERROR(SPARKLINE(C14:N14, {""chartype"", ""line""; ""color"", ""blue""})) "),"")
A15: Deposits: | B15: =IFERROR(SUM(C15:N15),"") | C15: =Jan!F4 -> #REF! | D15: =IFERROR(Feb!F4,"") | E15: =IFERROR(Mar!$F4,"") | F15: =IFERROR(Apr!$F4,"") -> 0 | G15: =IFERROR(May!$F4,"") -> 0 | H15: =IFERROR(Jun!$F4,"") -> 0 | I15: =IFERROR(Jul!$F4,"") -> 0 | J15: =IFERROR(Aug!$F4,"") -> 0 | K15: =IFERROR(Sep!$I4,"") -> 4 | L15: =IFERROR(Oct!$I4,"") -> 0 | M15: =IFERROR(Nov!$F4,"") -> 3 | N15: =IFERROR(Dec!$F4,"") -> 0 | O15: =IFERROR(__xludf.DUMMYFUNCTION("IFERROR(SPARKLINE(C15:N15, {""chartype"", ""line""; ""color"", ""blue""})) "),"")
A16: Show-Up Rate: | B16: =B9/B8 -> #REF! | C16: =C9/C8 -> #REF! | D16: =D9/D8 -> #DIV/0! | E16: =E9/E8 -> #DIV/0! | F16: =F9/F8 -> 1 | G16: =G9/G8 -> 1 | H16: =H9/H8 -> 1 | I16: =I9/I8 -> 1 | ... N16: =N9/N8 -> 0.64705882 | O16: =IFERROR(__xludf.DUMMYFUNCTION("IFERROR(SPARKLINE(C16:N16, {""chartype"", ""line""; ""color"", ""blue""})) "),"")
A17: Conducted Rate: | B17: =B10/B8 -> #DIV/0! | C17: =C10/C8 -> #REF! | D17: =D10/D8 -> #DIV/0! | E17: =E10/E8 -> #DIV/0! | F17: =F10/F8 -> 1 | G17: =G10/G8 -> 1 | H17: =H10/H8 -> 1 | I17: =I10/I8 -> 1 | ... N17: =N10/N8 -> 0.64705882 | O17: =IFERROR(__xludf.DUMMYFUNCTION("IFERROR(SPARKLINE(C17:N17, {""chartype"", ""line""; ""color"", ""blue""})) "),"")

Sheet Apr
B1: Rep: | C1: Anna | E1: Outcome | H1: KPIs% | K1: Show Rate | N1: Objections | Q1: Source | U1: Tracking
E2: Full-Pay: | F2: =IFERROR(COUNTIFS(I13:I287, "Full-Pay"),"") -> 2 | H2: Conversion Rate: | I2: =iferror(I10/I8,"") -> 0.13333333 | K2: Rescheduling Rate: | L2: =iferror(F8/I6,"") -> 0 | N2: Think About It | O2: =IFERROR(COUNTIFS(N13:N286, "think about it"),"") -> 7 | Q2: Reschedule | R2: =IFERROR(COUNTIF(H13:H286,Q2),"") -> 0 | S2: Cold Call | T2: =IFERROR(COUNTIF(H13:H286,S2),"") -> 0
B3: Revenue | C3: =IFERROR(SUM(K13:K284),"") -> 9000 | E3: Split-Pay: | F3: =IFERROR(COUNTIFS(I13:I287, "Split-Pay"),"") -> 0 | H3: Offer To Close Rate: | I3: =IFERROR(I10/I9,"") -> 0.13333333 | K3: Cancellation Rate: | L3: =iferror(F9/I6,"") -> 0 | N3: Money | O3: =IFERROR(COUNTIFS(N13:N286, "money"),"") -> 4 | Q3: YouTube | R3: =IFERROR(COUNTIF(H13:H286,Q3),"") -> 0 | S3: Twitter | T3: =IFERROR(COUNTIF(H13:H286,S3),"") -> 0
B4: Cash | C4: =IFERROR(SUM(L13:L284),"") -> 3000 | E4: Deposits: | F4: =IFERROR(COUNTIFS(I13:I287, "Deposit"),"") -> 0 | H4: Call To Offer Rate: | I4: =IFERROR(I9/I8,"") -> 1 | K4: No-Shows Rate: | L4: =iferror(F10/I6,"") -> 0 | N4: Time | O4: =IFERROR(COUNTIFS(N13:N286, "time"),"") -> 2 | Q4: YouTube Ads | R4: =IFERROR(COUNTIF(H13:H286,Q4),"") -> 0 | S4: Skool | T4: =IFERROR(COUNTIF(H13:H286,S4),"") -> 0
E5: Offer & Didn't Buy: | F5: =IFERROR(COUNTIFS(I13:I287, "Offer & Didn't Buy"),"") -> 13 | H5: Drag Over Rate: | I5: =IFERROR(F7/(C6+F7+F8),"") -> 0 | K5: Drag Over Rate: | L5: =iferror(F7/I6,"") -> 0 | N5: Partner | O5: =IFERROR(COUNTIFS(N13:N286, "partner"),"") -> 1 | Q5: Email | R5: =IFERROR(COUNTIF(H13:H286,Q5),"") -> 0 | S5: Instagram | T5: =IFERROR(COUNTIF(H13:H286,S5),"") -> 0
B6: Total Calls : | C6: =IFERROR(SUM(F2:F6),"") -> 15 | E6: Bad Fit & No Offer: | F6: =IFERROR(COUNTIFS(I13:I287, "Bad Fit & No Offer"),"") -> 0 | H6: Bookings: | I6: =IFERROR(SUM(F2:F10),"") -> 15 | K6: Show-Up Rate: | L6: =iferror(I7/I6,"") -> 1 | N6: Fear | O6: =IFERROR(COUNTIFS(N13:N286, "fear"),"") -> 0 | Q6: Facebook | R6: =IFERROR(COUNTIF(H13:H286,Q6),"") -> 0 | S6: TikTok | T6: =IFERROR(COUNTIF(H13:H286,S6),"") -> 0
B7: Total Won : | C7: =IFERROR(F2+F3,"") -> 2 | E7: Drag Over & Show: | F7: =IFERROR(COUNTIFS(I13:I287, "Drag Over & Show"),"") -> 0 | H7: Shows: | I7: =IFERROR(SUM(F2:F7),"") -> 15 | K7: Conducted Rate: | L7: =IFERROR(I8/I6,"") -> 1 | N7: Value | O7: =IFERROR(COUNTIFS(N14:N287, "value"),"") -> 0 | Q7: Facebook Ads | R7: =IFERROR(COUNTIF(H13:H286,Q7),"") -> 0 | S7: Google | T7: =IFERROR(COUNTIF(H13:H286,S7),"") -> 0
B8: Total Lost : | C8: =COUNTIF(I13:I286,"offer & didn't buy")+countif(I13:I286,"deposit")+countif(I13:I286,"bad fit & no offer") -> 13 | E8: Rescheduled: | F8: =IFERROR(COUNTIFS(I13:I287, "Rescheduled"),"") -> 0 | H8: Calls: | I8: =IFERROR(SUM(F2:F6),"") -> 15 | Q8: LinkedIn | R8: =IFERROR(COUNTIF(H13:H286,Q8),"") -> 0 | S8: Referral | T8: =IFERROR(COUNTIF(H13:H286,S8),"") -> 0
B9: Closing % : | C9: =iferror(SUM(C7/C6),"") -> 0.13333333 | E9: Cancelled: | F9: =IFERROR(COUNTIFS(I13:I287, "Cancelled"),"") -> 0 | H9: Offers: | I9: =IFERROR(sum(F2:F5),"") -> 15
E10: No-Show: | F10: =IFERROR(COUNTIFS(I13:I287, "No-Show"),"") -> 0 | H10: Deals | I10: =F2+F3 -> 2
B12: Date | C12: Name | E12: Phone No. | F12: Email | H12: Source | I12: Outcome | K12: Revenue | L12: Cash | N12: Objection | O12: Objection Notes | Q12: Length | R12: Recording Link | S12: Follow Up/Next Steps | T12: Call Summary
B13: 03.04.25 | C13: Mia Friis Knudsen | E13: 29852397 | F13: mia-friis-knudsen@hotmail.com | H13: Setter | I13: Offer & Didn't Buy | N13: Think About It | O13: Usikker på om forløbet er noget for hende | R13: https://slack-files.com/T089JBRTVMM-F08LKAN042Z-53ae7da4ea | S13: X | T13: Ender med at synes det er for mange penge, ville høre nærmere. Virkede usikker på om det var noget for hende.
B14: 04.04.25 | C14: Mira Ælmholdt Ottesen | E14: 31329041 | F14: miraottesen@gmail.com | H14: Setter | I14: Offer & Didn't Buy | N14: Think About It | O14: Overvejer at prøve selv først | R14: https://slack-files.com/T089JBRTVMM-F08M2DVVB6D-c84eeabb5d | S14: X | T14: Følte et forløb kunne være et godt suplement til den livsstil hun allerede er ved at bygge op. Er usikker på om hun skal prøve selv, eller få hjælpen til at blive skubbet godt igang. Hjælp til kostvaner, træning og rutiner i hverdagen.
B15: 04.04.25 | C15: Clara S. Been | E15: 0 459 023 332 | F15: beenclara@gmail.com | H15: Setter | I15: Offer & Didn't Buy | N15: Think About It | O15: Ville tænke over om det passede til hende, og om hun kunne finde det i budgettet. | R15: Forhindret | S15: X | T15: Har fitness coash. Med i løbeklub. Vegetar, mangler protein. Ønsker hjælp til kost.
B16: 04.04.25 | C16: (ringet og skrevet)Canan Benli | E16: 42317156 | F16: canan.benli@hotmail.com | H16: Setter | I16: Full-Pay | K16: 9000 | L16: 3000 | Q16: 5 måneder | R16: https://slack-files.com/T089JBRTVMM-F08MFE0CJD6-e1d174471b | S16: Closed | T16: Mangler struktur og den rette løsning. Prøvet meget i mange år uden held. Mega klar til at skabe foranding nu!
B17: 06.04.25 | C17: Ida Mogensen | E17: 40 74 87 87 | F17: ida.mogensen@live.dk | H17: Setter | I17: Offer & Didn't Buy | N17: Think About It | O17: På SU synes det er mange penge | R17: https://slack-files.com/T089JBRTVMM-F08LJSDM32B-e1f6fd421a | S17: X | T17: Synes forløbet lød perfekt i forhold til hendes egen tilgang. (Ikke restriktiv) Små ændringer.
B18: 06.04.25 | C18: Mathilde Nordberg | E18: 25 38 44 97 | F18: mathilde2002@icloud.com | H18: Setter | I18: Offer & Didn't Buy | N18: Money | O18: Studerende, synes det er mange penge | R18: https://slack-files.com/T089JBRTVMM-F08M9TK74BT-71681a9462 | S18: X | T18: Følte forløbet var for hende. Nervøs for at købe da hun har brugt mange penge på coaches før. Har brug for hjælp til vaner, overspisning, struktur, træning, tabe fedt. Har været utilfreds med krop siden 2018.
B19: 07.04.25 | C19: (ringet og skrevet)Ida Nyvang Lundgren Larsen | E19: 20 31 10 45 | F19: ida.nyvang@icloud.com | H19: Setter | I19: Full-Pay | K19: 9,000.00 kr | L19: 1,500.00 kr | N19: Time | O19: Stod midt i nye rammer - snart nyt studie + flytning + rejse | Q19: 5 måneder | R19: https://slack-files.com/T089JBRTVMM-F08M1FVN70D-80cf01cc98 | S19: Closed | T19: Ønsker sig en mere tonet krop, hjælp til at blive tryg i træningscenter, implementering af sunde vaner i en travl, omskiftelig hverdag.
B20: 08.04.25 | C20: Nellie Waaben | E20: 50 19 29 20 | F20: nelliewaaben@gmail.com | H20: Setter | I20: Offer & Didn't Buy | N20: Money | O20: Synes det var meget dyrt, men forløbet er perfekt for hende. | R20: https://slack-files.com/T089JBRTVMM-F08ME5NBDT4-6ab2e9895a | S20: X | T20: Havde brug for støtte til at holde fast i sunde rutiner. Ønskede vægttab, omlægning af kostvaner, hjælp til at ændre mindset og føle sig godt tilpas i sin egen krop. Utilfreds. Ønsker sig mere energi.
B21: 09.04.25 | C21: Louise Christina Gade | E21: 26 23 17 72 | F21: louisecrgade@gmail.com | H21: Setter | I21: Offer & Didn't Buy | N21: Think About It | O21: I tvivl om hun skal vælge et holistisk tarmforløb hun har været på igen, eller Olivia. | R21: https://slack-files.com/T089JBRTVMM-F08M81C5P5L-5eb99c335e | S21: X | T21: Mangler motivation til at skabe de ændringer hun ønsker sig. Når aldrig helt i mål. Har barn, kæreste og har svært ved at passe hendes valg ind med familielivet. Har irriteret tarm og har masser af indsigt i hvad der fungerer for hende, men mangler støtte til at håndtere når motivationen daler.
B22: 10.04.25 | C22: Amira A. Mouna | E22: 30 44 18 74 | F22: Amiramaliamouna1@gmail.com | H22: Setter | I22: Offer & Didn't Buy | N22: Money | O22: Intet på selve kaldet, men fortrød efterfølgende | R22: https://slack-files.com/T089JBRTVMM-F08MQ8K02EP-12dd9edf08 | S22: Follow Up | T22: Var meget motiveret for at skabe de forandringer hun ønsker. Kost og krop holder hende tilbage - ikke glad for hvad hun ser i spejlet.
B23: 11.04.25 | C23: Emma Reinholdt Nissen | E23: 23 11 55 04 | F23: emmareinholdtnissen@gmail.com | H23: Setter | I23: Offer & Didn't Buy | N23: Think About It | O23: Ville sove på det og mange penge | R23: https://slack-files.com/T089JBRTVMM-F08MWHHUFPU-0abf9ab21c | S23: Follow Up | T23: Kunne spejle sig meget i Olivias content, og fortæller at hun ønsker Olivia specifikt, da hun føler de deler samme fortid/historie - ønsker hjælp til træning, kost, søvnmønster og det mentale.
B24: 11.04.25 | C24: Kimmie Liv Sennova | E24: 53 60 69 50 | F24: kimmielivsennova@gmail.com | H24: Setter | I24: Offer & Didn't Buy | N24: Partner | O24: Sove på det og snakke med kæreste | R24: https://slack-files.com/T089JBRTVMM-F08MCD15TPH-c3e664aa76 | S24: Follow Up | T24: Havde brug for hjælp til teknik i træning (glutes) for at se resultater, kost og føle sig godt tilpas i sin krop. Fedttab og toning af kroppen og ønsker all over at skabe en sund livsstil for sig selv som også vil gavne hendes arbejdsliv som performer.
B25: 11.04.25 | C25: Eva Youseff El-Gazzi | E25: 31 31 86 99 | F25: eelghazzi@gmail.com | H25: Setter | I25: Offer & Didn't Buy | N25: Time | O25: Skulle på ferie i 14 dage og havde ikke penge til start up fee før d. 1. maj | R25: https://slack-files.com/T089JBRTVMM-F08MWLVLPFW-3165787c27 | S25: Follow Up | T25: Var meget klar til at komme igang, men blev overrasket over hun skulle betale på dagen. Hun informerer at hun ønsker opstart d. 1. maj
B26: 13.04.25 | C26: Gulpari Khan | E26: 24 43 42 36 | F26: gulparikhan@hotmail.com | H26: Setter | I26: Offer & Didn't Buy | N26: Think About It | O26: Skulle overveje motivation og penge | R26: https://slack-files.com/T089JBRTVMM-F08NA605KQR-a23a9edf51 | S26: X | T26: Var interesseret i at høre mere om hvordan coachesforløb fungerede og deres pris. Ønsker hjælp til kost, vaner, træning og mindset - fokuseret på vægt og havde et klart billede om hvordan hun gerne ville se ud, men synes der var langt. Afhængig af sukker - føler det har taget overhånd.
B27: 14.04.25 | C27: Simone Haarbo | E27: 29 80 31 86 | F27: simone2808@hotmail.dk | H27: Setter | I27: Offer & Didn't Buy | N27: Money | O27: SU | R27: https://slack-files.com/T089JBRTVMM-F08N5UW4D18-ab53728404 | S27: Follow Up | T27: Brug for hjælp til at se fremskridt - sidder fast og ser ingen resultater af sin træning og kostomlægning.
S29: Follow Up | T29: Brug for hjælp til kost og vaner. Har styr på træningsdelen. Ønsker det maksimale udbytte af sin træning - virker meget varm på et 1:1 forløb - vender tilbage inden 24 timer.
S30: Closed | T30: Brug for hjælp til at skabe varige ændringer og arbejde med selvbillede og mindset.
S31: Follow Up | T31: Brug for hjælp til vægttab og kostplan - snacker meget og ønsker mere struktur på kost og træning.
S32: Follow Up | T32: Brug for hjælp til mere tonet krop, bryde med usunde vaner, støtte til at holde de gode rutiner og få styr på kosten - har besværligheder med maven. Har kørt andet forløb før som var restriktivt.
S33: Closed | T33: Brug for hjælp til at bryde med overspisning og finde en god balance i sin kost så det matcher hendes aktivitetsniveau (svømning + løb). Føler sig utilpas i sin krop. Ønsker vægttab og mere tonet.
T34: Ønsker hjælp til vægttab, kost/overspisning, mindset - ønsker at finde den helt rette balance og få alle værktøjer til hvordan hun gør fremadrettet for at holde vægten og balancen i forhold til madvaner. Har prøvet meget selv, og været i restiktivt forløb mens hun havde det svært psykisk (kan derfor ikke huske denne periode)
S35: Closed | T35: Vægttab, opstramning/tonet, kost.
C37: Ringet til
C38: I forløb, reference efterspurgt
C39: Fulgt op 1 gang, potentielt interesseret

Sheet May
B1: Rep: | C1: Name | E1: Outcome | H1: KPIs% | K1: Show Rate | N1: Objections | Q1: Source | U1: Tracking
E2: Full-Pay: | F2: =IFERROR(COUNTIFS(I13:I287, "Full-Pay"),"") -> 7 | H2: Conversion Rate: | I2: =iferror(I10/I8,"") -> 0.57142857 | K2: Rescheduling Rate: | L2: =iferror(F8/I6,"") -> 0 | N2: Think About It | O2: =IFERROR(COUNTIFS(N13:N286, "think about it"),"") -> 2 | Q2: Reschedule | R2: =IFERROR(COUNTIF(H13:H286,Q2),"") -> 0 | S2: Cold Call | T2: =IFERROR(COUNTIF(H13:H286,S2),"") -> 0
B3: Revenue | C3: =IFERROR(SUM(K13:K283),"") -> 38994 | E3: Split-Pay: | F3: =IFERROR(COUNTIFS(I13:I287, "Split-Pay"),"") -> 1 | H3: Offer To Close Rate: | I3: =IFERROR(I10/I9,"") -> 0.57142857 | K3: Cancellation Rate: | L3: =iferror(F9/I6,"") -> 0 | N3: Money | O3: =IFERROR(COUNTIFS(N13:N286, "money"),"") -> 7 | Q3: YouTube | R3: =IFERROR(COUNTIF(H13:H286,Q3),"") -> 0 | S3: Twitter | T3: =IFERROR(COUNTIF(H13:H286,S3),"") -> 0
B4: Cash | C4: =IFERROR(SUM(L13:L284),"") -> 31498 | E4: Deposits: | F4: =IFERROR(COUNTIFS(I13:I287, "Deposit"),"") -> 0 | H4: Call To Offer Rate: | I4: =IFERROR(I9/I8,"") -> 1 | K4: No-Shows Rate: | L4: =iferror(F10/I6,"") -> 0 | N4: Time | O4: =IFERROR(COUNTIFS(N13:N286, "time"),"") -> 2 | Q4: YouTube Ads | R4: =IFERROR(COUNTIF(H13:H286,Q4),"") -> 0 | S4: Skool | T4: =IFERROR(COUNTIF(H13:H286,S4),"") -> 0
E5: Offer & Didn't Buy: | F5: =IFERROR(COUNTIFS(I13:I287, "Offer & Didn't Buy"),"") -> 6 | H5: Drag Over Rate: | I5: =IFERROR(F7/(C6+F7+F8),"") -> 0 | K5: Drag Over Rate: | L5: =iferror(F7/I6,"") -> 0 | N5: Partner | O5: =IFERROR(COUNTIFS(N13:N286, "partner"),"") -> 0 | Q5: Email | R5: =IFERROR(COUNTIF(H13:H286,Q5),"") -> 0 | S5: Instagram | T5: =IFERROR(COUNTIF(H13:H286,S5),"") -> 0
B6: Total Calls : | C6: =IFERROR(SUM(F2:F6),"") -> 14 | E6: Bad Fit & No Offer: | F6: =IFERROR(COUNTIFS(I13:I287, "Bad Fit & No Offer"),"") -> 0 | H6: Bookings: | I6: =IFERROR(SUM(F2:F10),"") -> 14 | K6: Show-Up Rate: | L6: =iferror(I7/I6,"") -> 1 | N6: Fear | O6: =IFERROR(COUNTIFS(N13:N286, "fear"),"") -> 1 | Q6: Facebook | R6: =IFERROR(COUNTIF(H13:H286,Q6),"") -> 0 | S6: TikTok | T6: =IFERROR(COUNTIF(H13:H286,S6),"") -> 0
B7: Total Won : | C7: =IFERROR(F2+F3,"") -> 8 | E7: Drag Over & Show: | F7: =IFERROR(COUNTIFS(I13:I287, "Drag Over & Show"),"") -> 0 | H7: Shows: | I7: =IFERROR(SUM(F2:F7),"") -> 14 | K7: Conducted Rate: | L7: =IFERROR(I8/I6,"") -> 1 | N7: Value | O7: =IFERROR(COUNTIFS(N14:N287, "value"),"") -> 0 | Q7: Facebook Ads | R7: =IFERROR(COUNTIF(H13:H286,Q7),"") -> 0 | S7: Google | T7: =IFERROR(COUNTIF(H13:H286,S7),"") -> 0
B8: Total Lost : | C8: =COUNTIF(I13:I286,"offer & didn't buy")+countif(I13:I286,"deposit")+countif(I13:I286,"bad fit & no offer") -> 6 | E8: Rescheduled: | F8: =IFERROR(COUNTIFS(I13:I287, "Rescheduled"),"") -> 0 | H8: Calls: | I8: =IFERROR(SUM(F2:F6),"") -> 14 | Q8: LinkedIn | R8: =IFERROR(COUNTIF(H13:H286,Q8),"") -> 0 | S8: Referral | T8: =IFERROR(COUNTIF(H13:H286,S8),"") -> 0
B9: Closing % : | C9: =iferror(SUM(C7/C6),"") -> 0.57142857 | E9: Cancelled: | F9: =IFERROR(COUNTIFS(I13:I287, "Cancelled"),"") -> 0 | H9: Offers: | I9: =IFERROR(sum(F2:F5),"") -> 14
E10: No-Show: | F10: =IFERROR(COUNTIFS(I13:I287, "No-Show"),"") -> 0 | H10: Deals | I10: =F2+F3 -> 8
B12: Date | C12: Name | E12: Phone No. | F12: Email | H12: Source | I12: Outcome | K12: Revenue | L12: Cash | N12: Objection | O12: Objection Notes | Q12: Length | R12: Recording Link | S12: Follow Up/Next Steps | T12: Call Summary
B13: 02.05.25 | C13: Alma Styrbech | E13: 42 76 48 52 | F13: astyrbech@gmail.com | H13: Setter | I13: Full-Pay | K13: 2247 | L13: 749 | N13: Think About It | O13: Overvejer opstart i start juni | Q13: Selvstændig | R13: https://slack-files.com/T089JBRTVMM-F08QR5YR1EX-62568a2bb0 | S13: Closed | T13: Brug for hjælp til kost og vaner. Har styr på træningsdelen. Ønsker det maksimale udbytte af sin træning - virker meget varm på et 1:1 forløb - vender tilbage inden 24 timer.
B14: 06.05.25 | C14: Tina Andersen | E14: 29 79 95 26 | F14: tina_and98@hotmail.com | H14: Setter | I14: Full-Pay | K14: 3000 | L14: 3000 | N14: Money | Q14: 3 måneder | R14: https://slack-files.com/T089JBRTVMM-F08QPB5BW87-2190d0f762 | S14: Closed | T14: Brug for hjælp til at skabe varige ændringer og arbejde med selvbillede og mindset.
B15: 10.05.25 | C15: Pavitha Kasirajah (skrevet besked) | E15: 42 47 43 62 | F15: ktpavitha@gmail.com | H15: Setter | I15: Offer & Didn't Buy | N15: Money | O15: På SU - overvejer budget | R15: https://slack-files.com/T089JBRTVMM-F08RUGEQXUJ-81378ae256 | S15: X | T15: Brug for hjælp til vægttab og kostplan - snacker meget og ønsker mere struktur på kost og træning.
B16: 07.05.25 | C16: Maria Hjort Tønnesen (ringer og skrevet) | E16: 22 78 05 79 | F16: mhjortt@gmail.com | H16: Setter | I16: Offer & Didn't Buy | N16: Time | O16: Står midt i jobskifte | R16: https://slack-files.com/T089JBRTVMM-F08RYPSEGN4-938d06b03b | S16: Follow Up | T16: Brug for hjælp til mere tonet krop, bryde med usunde vaner, støtte til at holde de gode rutiner og få styr på kosten - har besværligheder med maven. Har kørt andet forløb før som var restriktivt.
B17: 12.05.25 | C17: Leonora Amalie Minet Ricks | E17: 26 11 17 72 | F17: leonoraricks@gmail.com | H17: Setter | I17: Full-Pay | K17: 6000 | L17: 6000 | Q17: 3 måneder | R17: https://slack-files.com/T089JBRTVMM-F08SL8SQ796-48d7110029 | S17: Closed | T17: Brug for hjælp til at bryde med overspisning og finde en god balance i sin kost så det matcher hendes aktivitetsniveau (svømning + løb). Føler sig utilpas i sin krop. Ønsker vægttab og mere tonet.
B18: 14.05.25 | C18: Julie Kristensen | E18: 61 16 66 08 | F18: julierlk@hotmail.com | H18: Setter | I18: Offer & Didn't Buy | N18: Fear | R18: https://slack-files.com/T089JBRTVMM-F08T0P7C9FA-9c57ca676d | S18: Follow Up | T18: Ønsker hjælp til vægttab, kost/overspisning, mindset - ønsker at finde den helt rette balance og få alle værktøjer til hvordan hun gør fremadrettet for at holde vægten og balancen i forhold til madvaner. Har prøvet meget selv, og været i restiktivt forløb mens hun havde det svært psykisk (kan derfor ikke huske denne periode)
B19: 15.05.25 | C19: Melani Juul Nysom Pedersen | E19: 21 30 08 29 | F19: melanifrugthaven@gmail.com | H19: Setter | I19: Full-Pay | K19: 2247 | L19: 749 | N19: Think About It | Q19: Selvstændig | R19: https://slack-files.com/T089JBRTVMM-F08SLJP0M6G-d551736604 | S19: Closed | T19: Vægttab, opstramning/tonet, kost.
B20: 19.05.25 | C20: Laura Hvilshøj Liin | E20: 29 17 73 61 | F20: lauraliin350a@gmail.com | H20: Setter | I20: Full-Pay | K20: 6000 | L20: 6000 | O20: Penge - mellem jobs. I tvivl om det var lige nu. | Q20: 3 måneder | R20: https://slack-files.com/T089JBRTVMM-F08T1GR9AHY-cec6910858 | S20: Closed | T20: Mindset, muskelmasse, styrketræning, struktur til nye rutiner, motivation til at komme afsted (har veninde som også går i forløb), ro i sindet, kostoverblik.
B21: 20.05.25 | C21: Mia Adamsen | E21: 25 72 14 41 | F21: m@henrikadamsen.com | H21: Setter | I21: Offer & Didn't Buy | N21: Money | O21: Penge og samtale med andre coaches | R21: https://slack-files.com/T089JBRTVMM-F08TVQZ397T-e9af25da65 | S21: X | T21: Synes alt ved forløbet var perfekt. Havde brug for hjælp til balance i kost, sunde vner.
B22: 21.05.25 | C22: Freja Ladehoff | E22: 50 44 96 71 | F22: freja.ladehoff04@gmail.com | H22: Setter | I22: Full-Pay | K22: 6000 | L22: 6000 | N22: Money | R22: https://slack-files.com/T089JBRTVMM-F08SYJ51ZTR-0f551d8bd7 | S22: Closed | T22: Hjælp til kost, oppustethed, mindset og toning af krop.
B23: 21.05.25 | C23: Kirstine Braüner | E23: 27 59 73 99 | F23: kirstine_brauner@hotmail.com | H23: Setter | I23: Offer & Didn't Buy | N23: Time | Q23: Selvstændig | S23: Follow Up | T23: Ønsker hjælp til indre ro, pauser, nervesystem og meditation - mindset
B24: 28.05.25 | C24: Melissa Mortensen (skrevet) | E24: 23 62 57 15 | F24: melissaengelsted@gmail.com | H24: Setter | I24: Offer & Didn't Buy | N24: Money | R24: https://slack-files.com/T089JBRTVMM-F08V02U273J-9c1dff272e | S24: Follow Up | T24: Oppustethed, vægttab, selvbillede og selvtillid, mindset, utilpas i sin krop - mangler at finde balancen hele vejen rundt.
B25: 30.05.25 | C25: Anna Friis | E25: 30 48 50 18 | F25: annahugfriis@icloud.com | H25: Setter | I25: Split-pay | K25: 6000 | L25: 1500 | N25: Money | O25: På SU | R25: https://slack-files.com/T089JBRTVMM-F08UPR50350-e5949fc516 | S25: Closed | T25: Hjælp til mindset - opbygge selvværd. Kost. Usikker i træningscentret. Taler dårligt til sig selv - påvirker hendes parforhold.
B26: 29.05.25 | C26: Amalie Johansen | E26: 29 79 49 55 | F26: ama.johansen@live.dk | H26: Setter | I26: Full-Pay | K26: 7500 | L26: 7500 | N26: Money | R26: https://slack-files.com/T089JBRTVMM-F08UAV6UBV4-5bc0a5d8f9 | S26: Closed | T26: Motivation til styrketræning (trænet før) gør mange ting, men ser ikke fremgang, overspiser, ønsker at tabe sig 10 kg. strammet op og forbedre løb + få intro til maskiner i fitness.

Sheet Jun
B1: Rep: | C1: Name | E1: Outcome | H1: KPIs% | K1: Show Rate | N1: Objections | Q1: Source | U1: Tracking
E2: Full-Pay: | F2: =IFERROR(COUNTIFS(I13:I287, "Full-Pay"),"") -> 3 | H2: Conversion Rate: | I2: =iferror(I10/I8,"") -> 0.64285714 | K2: Rescheduling Rate: | L2: =iferror(F8/I6,"") -> 0 | N2: Think About It | O2: =IFERROR(COUNTIFS(N13:N286, "think about it"),"") -> 2 | Q2: Reschedule | R2: =IFERROR(COUNTIF(H13:H286,Q2),"") -> 0 | S2: Cold Call | T2: =IFERROR(COUNTIF(H13:H286,S2),"") -> 0
B3: Revenue | C3: =IFERROR(SUM(K13:K283),"") -> 60000 | E3: Split-Pay: | F3: =IFERROR(COUNTIFS(I13:I287, "Split-Pay"),"") -> 6 | H3: Offer To Close Rate: | I3: =IFERROR(I10/I9,"") -> 0.64285714 | K3: Cancellation Rate: | L3: =iferror(F9/I6,"") -> 0 | N3: Money | O3: =IFERROR(COUNTIFS(N13:N286, "money"),"") -> 8 | Q3: YouTube | R3: =IFERROR(COUNTIF(H13:H286,Q3),"") -> 0 | S3: Twitter | T3: =IFERROR(COUNTIF(H13:H286,S3),"") -> 0
B4: Cash | C4: =IFERROR(SUM(L13:L284),"") -> 34500 | E4: Deposits: | F4: =IFERROR(COUNTIFS(I13:I287, "Deposit"),"") -> 0 | H4: Call To Offer Rate: | I4: =IFERROR(I9/I8,"") -> 1 | K4: No-Shows Rate: | L4: =iferror(F10/I6,"") -> 0 | N4: Time | O4: =IFERROR(COUNTIFS(N13:N286, "time"),"") -> 0 | Q4: YouTube Ads | R4: =IFERROR(COUNTIF(H13:H286,Q4),"") -> 0 | S4: Skool | T4: =IFERROR(COUNTIF(H13:H286,S4),"") -> 0
E5: Offer & Didn't Buy: | F5: =IFERROR(COUNTIFS(I13:I287, "Offer & Didn't Buy"),"") -> 5 | H5: Drag Over Rate: | I5: =IFERROR(F7/(C6+F7+F8),"") -> 0 | K5: Drag Over Rate: | L5: =iferror(F7/I6,"") -> 0 | N5: Partner | O5: =IFERROR(COUNTIFS(N13:N286, "partner"),"") -> 0 | Q5: Email | R5: =IFERROR(COUNTIF(H13:H286,Q5),"") -> 0 | S5: Instagram | T5: =IFERROR(COUNTIF(H13:H286,S5),"") -> 0
B6: Total Calls : | C6: =IFERROR(SUM(F2:F6),"") -> 14 | E6: Bad Fit & No Offer: | F6: =IFERROR(COUNTIFS(I13:I287, "Bad Fit & No Offer"),"") -> 0 | H6: Bookings: | I6: =IFERROR(SUM(F2:F10),"") -> 14 | K6: Show-Up Rate: | L6: =iferror(I7/I6,"") -> 1 | N6: Fear | O6: =IFERROR(COUNTIFS(N13:N286, "fear"),"") -> 0 | Q6: Facebook | R6: =IFERROR(COUNTIF(H13:H286,Q6),"") -> 0 | S6: TikTok | T6: =IFERROR(COUNTIF(H13:H286,S6),"") -> 0
B7: Total Won : | C7: =IFERROR(F2+F3,"") -> 9 | E7: Drag Over & Show: | F7: =IFERROR(COUNTIFS(I13:I287, "Drag Over & Show"),"") -> 0 | H7: Shows: | I7: =IFERROR(SUM(F2:F7),"") -> 14 | K7: Conducted Rate: | L7: =IFERROR(I8/I6,"") -> 1 | N7: Value | O7: =IFERROR(COUNTIFS(N14:N287, "value"),"") -> 0 | Q7: Facebook Ads | R7: =IFERROR(COUNTIF(H13:H286,Q7),"") -> 0 | S7: Google | T7: =IFERROR(COUNTIF(H13:H286,S7),"") -> 0
B8: Total Lost : | C8: =COUNTIF(I13:I286,"offer & didn't buy")+countif(I13:I286,"deposit")+countif(I13:I286,"bad fit & no offer") -> 5 | E8: Rescheduled: | F8: =IFERROR(COUNTIFS(I13:I287, "Rescheduled"),"") -> 0 | H8: Calls: | I8: =IFERROR(SUM(F2:F6),"") -> 14 | Q8: LinkedIn | R8: =IFERROR(COUNTIF(H13:H286,Q8),"") -> 0 | S8: Referral | T8: =IFERROR(COUNTIF(H13:H286,S8),"") -> 0
B9: Closing % : | C9: =iferror(SUM(C7/C6),"") -> 0.64285714 | E9: Cancelled: | F9: =IFERROR(COUNTIFS(I13:I287, "Cancelled"),"") -> 0 | H9: Offers: | I9: =IFERROR(sum(F2:F5),"") -> 14
E10: No-Show: | F10: =IFERROR(COUNTIFS(I13:I287, "No-Show"),"") -> 0 | H10: Deals | I10: =F2+F3 -> 9
B12: Date | C12: Name | E12: Phone No. | F12: Email | H12: Source | I12: Outcome | K12: Revenue | L12: Cash | N12: Objection | O12: Objection Notes | Q12: Length | R12: Recording Link | S12: Follow Up/Next Steps | T12: Call Summary
B13: 02.06.25 | C13: Laura Snerle Kranker | E13: 51 20 22 33 | F13: lauracsk@gmail.com | H13: Setter | I13: Split-pay | K13: 6000 | L13: 3000 | N13: Money | Q13: 3 måneder | R13: https://slack-files.com/T089JBRTVMM-F08TVR24X5X-171325519b | S13: Closed | T13: Nyt kald aftalt d. 2. juni - Binge-eating spiral, mave, struktur, motivation, kost - mood svings, dårligt selvværd - går 8 år tilbage.
B14: 02.06.25 | C14: Sofie Pihl Rasmussen | E14: 42 75 09 15 | F14: rasmussensofiepihl@gmail.com | H14: Setter | I14: Split-pay | K14: 6000 | L14: 1500 | N14: Money | O14: Skal flytte, på SU inden længe og ud at rejse | Q14: 3 måneder | R14: https://slack-files.com/T089JBRTVMM-F08UM3C1527-ffa11987c0 | S14: Closed | T14: Haft spiseforstyrrelse - hjælp til mindset og tænke gode tanker om sig selv, nået langt men mangler det sidste. Ønsker hjælp til træningsprogram, selvtillid - fred og ro omkring mad.
B15: 04.06.25 | C15: Lykke Christine Elvstrøm | E15: 93 92 27 18 | F15: lykkeelvstroem15@gmail.com | H15: Setter | I15: Full-Pay | K15: 6000 | L15: 6000 | Q15: 3 måneder | R15: https://slack-files.com/T089JBRTVMM-F08VDB9TU2G-ad3ba23f37 | S15: Closed | T15: Hjælp til tonet krop - balancen mellem kost og træning. Alt eller intet-mentalitet. Ønsker tydelige resultater af sin indsats. Har altid trænet regulært, men ser ingen tydelige forandringer.
B16: 06.06.25 | C16: Karen-Cecilie Kortenbach | E16: 22 89 01 12 | F16: tessduus@hotmail.com | H16: Setter | I16: Full-Pay | K16: 7500 | L16: 7500 | Q16: 4 måneder | R16: https://slack-files.com/T089JBRTVMM-F08V9HLUSGP-e854fe9c76 | S16: Closed | T16: Hjemmetræningsprogram. Rigtig godt igang med gode vaner selv. Hjælp til balance mellem kost og træning - føler sig meget sulten fordi hun ikke spiser i løbet af dagen og overspiser om aftenen. Ønsker mere viden omkring kost og træning for at nå helt i mål - har tabt 20 kg. på egen hånd.
B17: 08.06.25 | C17: Rebekka Lindholm | E17: 29 44 21 39 | F17: rebekka@riislindholm.dk | H17: Setter | I17: Offer & Didn't Buy | N17: Think About It | Q17: 4 måneder | R17: https://slack-files.com/T089JBRTVMM-F090J524ASG-50f341609d | S17: X | T17: Ønsker mere viden omkring træning og kost. Har de sidste 5 år været utilfreds med sin krop hvilket går ud over hendes selvværd og selvstillid. Er gymnast. Går i gym. Har i øjeblikket stress. Føler forløbet kan hjælpe hende i mål med det hun ønsker.
B18: 09.06.25 | C18: Amalie Mikkelsen | E18: 21 75 63 03 | F18: nikitalist@hotmail.com | H18: Setter | I18: Split-pay | K18: 9000 | L18: 4500 | N18: Think About It | Q18: 5 måneder | R18: https://slack-files.com/T089JBRTVMM-F090M7X1GKW-6cdd3a3ab1 | S18: Closed | T18: Har et biologisk ur der tikker i forhold til tidlig overgangsalder hvorfor hun har brug for at skabe en livsstilsændring (28 år).
B19: 10.06.25 | C19: Emma Junker | E19: 29 28 26 72 | F19: emmathobo@gmail.com | H19: Setter | I19: Offer & Didn't Buy | N19: Money | Q19: 3 måneder | R19: https://slack-files.com/T089JBRTVMM-F090T3647U3-5467e18aaa | S19: X | T19: Vægttab - mere selvtillid og selvsikker. Hjælp til træning, kost. Mere tonet krop. Overvejet at skabe forandringer i 3 år.
B20: 11.06.25 | C20: Pernille Frederikke Juhl Rosenkilde | E20: 52 30 45 28 | F20: pf.rosenkilde@gmail.com | H20: Setter | I20: Split-pay | K20: 6000 | L20: 1500 | N20: Money | Q20: 3 måneder | R20: https://slack-files.com/T089JBRTVMM-F090STS7V0E-6489aefab7 | S20: Closed | T20: Hjælp til kost og træning. Har været i forløb før. Ser ikke resultater af sin indsats selv om hun træner jævnligt. Har været i forløb flere gange før. SU
B21: 17.06.25 | C21: Josephine Kristensen | E21: 29 85 82 72 | F21: josephinekristensen2@gmail.com | H21: Setter | I21: Offer & Didn't Buy | Q21: 3 måneder | R21: https://slack-files.com/T089JBRTVMM-F092HLN02D6-222160e8d2 | S21: Follow Up | T21: Har gang i træning men manlger hjælp til at nå det sidste - få styr på kost så hun begynder at se tydelige resultater. Vægttab, tonet, mere tilpas i krop. Klar til at der skal ske noget nu. Forsøgt de sidste 3 måneder, men mangler redskaber og viden.
B22: 17.06.25 | C22: Louise Krejberg Jensen | E22: 50 70 32 90 | F22: louisekjensen27@gmail.com | H22: Setter | I22: Offer & Didn't Buy | N22: Money | O22: Midt i flytning | Q22: 4 måneder | R22: https://slack-files.com/T089JBRTVMM-F091V4RS560-8e2e62fcee | S22: Follow Up | T22: Ønsker hjælp til vægttab, muskelmasse og kostvejledning - klar over hun er nødt til at ændre adfærd hvis hun skal nå i mål. Står stille selv om hun træner meget. Stået stille i 6 måneder. Balance og madro.
B23: 18.06.25 | C23: Janne Winther | E23: 27 39 51 76 | F23: janne@myron.dk | H23: Setter | I23: Full-Pay | K23: 7500 | L23: 7500 | N23: Money | Q23: 4 måneder | R23: https://slack-files.com/T089JBRTVMM-F091YRAUUGM-d8d2583099 | S23: Closed | T23: 57 år. Mangler hjælp til livsstilsændring. Ønsker at tabe 10 kg, spise mindre sukker og etablere sunde kostvaner og hjemmetræningsprogram. Mindset og motivation til sunde rutiner. Klar til forandring - har sagt job op og vil bruge sommeren på at bygge sig selv op.
B24: 20.06.25 | C24: Lilian Ostersen Rørby | E24: 27 58 40 96 | F24: lilianrorby@gmail.com | H24: Setter | I24: Split-pay | K24: 6000 | L24: 1500 | N24: Money | O24: Økonomi | Q24: 3 måneder | R24: https://slack-files.com/T089JBRTVMM-F092CPC6C84-d73376f8d3 | S24: Closed | T24: Hjælp til kost - træner meget og vil gerne have mere energi og overskud i en travl hverdag. Nyligt fraskilt og har taget en beslutning om en livsstilsændring. Maveproblemer - oppustethed og irritabel tyktarm. Ønsker at føle sig mæt hele dagen.
B25: 24.06.25 | C25: Freja Høgsted | E25: 24 24 67 80 | F25: frejahoegsted8@gmail.com | H25: Setter | I25: Split-pay | K25: 6000 | L25: 1500 | N25: Money | O25: Økonomi | Q25: 3 måneder | R25: https://slack-files.com/T089JBRTVMM-F092R7XC5B7-1e4b864eb2 | S25: Closed
B26: 25.06.25 | C26: Mariam Mehmood | E26: 42 25 16 31 | F26: mariam-mehmood@hotmail.com | H26: Setter | I26: Offer & Didn't Buy | O26: Måske brækket fod. Venter på svar fra læge | Q26: 3 måneder | R26: https://slack-files.com/T089JBRTVMM-F0931K0S2UC-0c286e8757 | S26: X | T26: Ønsker hjælp til sundere kostvaner - ked af fedt på maven. Mere tonet krop.

Sheet Jul
A1: e | B1: Rep: | C1: Name | E1: Outcome | H1: KPIs% | K1: Show Rate | N1: Objections | Q1: Source | U1: Tracking
E2: Full-Pay: | F2: =IFERROR(COUNTIFS(I13:I287, "Full-Pay"),"") -> 4 | H2: Conversion Rate: | I2: =iferror(I10/I8,"") -> 0.61111111 | K2: Rescheduling Rate: | L2: =iferror(F8/I6,"") -> 0 | N2: Think About It | O2: =IFERROR(COUNTIFS(N13:N286, "think about it"),"") -> 2 | Q2: Reschedule | R2: =IFERROR(COUNTIF(H13:H286,Q2),"") -> 0 | S2: Cold Call | T2: =IFERROR(COUNTIF(H13:H286,S2),"") -> 0
B3: Revenue | C3: =IFERROR(SUM(K13:K283),"") -> 79500 | E3: Split-Pay: | F3: =IFERROR(COUNTIFS(I13:I287, "Split-Pay"),"") -> 7 | H3: Offer To Close Rate: | I3: =IFERROR(I10/I9,"") -> 0.61111111 | K3: Cancellation Rate: | L3: =iferror(F9/I6,"") -> 0 | N3: Money | O3: =IFERROR(COUNTIFS(N13:N286, "money"),"") -> 9 | Q3: YouTube | R3: =IFERROR(COUNTIF(H13:H286,Q3),"") -> 0 | S3: Twitter | T3: =IFERROR(COUNTIF(H13:H286,S3),"") -> 0
B4: Cash | C4: =IFERROR(SUM(L13:L284),"") -> 47000 | E4: Deposits: | F4: =IFERROR(COUNTIFS(I13:I287, "Deposit"),"") -> 0 | H4: Call To Offer Rate: | I4: =IFERROR(I9/I8,"") -> 1 | K4: No-Shows Rate: | L4: =iferror(F10/I6,"") -> 0 | N4: Time | O4: =IFERROR(COUNTIFS(N13:N286, "time"),"") -> 0 | Q4: YouTube Ads | R4: =IFERROR(COUNTIF(H13:H286,Q4),"") -> 0 | S4: Skool | T4: =IFERROR(COUNTIF(H13:H286,S4),"") -> 0
E5: Offer & Didn't Buy: | F5: =IFERROR(COUNTIFS(I13:I287, "Offer & Didn't Buy"),"") -> 7 | H5: Drag Over Rate: | I5: =IFERROR(F7/(C6+F7+F8),"") -> 0 | K5: Drag Over Rate: | L5: =iferror(F7/I6,"") -> 0 | N5: Partner | O5: =IFERROR(COUNTIFS(N13:N286, "partner"),"") -> 0 | Q5: Email | R5: =IFERROR(COUNTIF(H13:H286,Q5),"") -> 0 | S5: Instagram | T5: =IFERROR(COUNTIF(H13:H286,S5),"") -> 0
B6: Total Calls : | C6: =IFERROR(SUM(F2:F6),"") -> 18 | E6: Bad Fit & No Offer: | F6: =IFERROR(COUNTIFS(I13:I287, "Bad Fit & No Offer"),"") -> 0 | H6: Bookings: | I6: =IFERROR(SUM(F2:F10),"") -> 18 | K6: Show-Up Rate: | L6: =iferror(I7/I6,"") -> 1 | N6: Fear | O6: =IFERROR(COUNTIFS(N13:N286, "fear"),"") -> 2 | Q6: Facebook | R6: =IFERROR(COUNTIF(H13:H286,Q6),"") -> 0 | S6: TikTok | T6: =IFERROR(COUNTIF(H13:H286,S6),"") -> 0
B7: Total Won : | C7: =IFERROR(F2+F3,"") -> 11 | E7: Drag Over & Show: | F7: =IFERROR(COUNTIFS(I13:I287, "Drag Over & Show"),"") -> 0 | H7: Shows: | I7: =IFERROR(SUM(F2:F7),"") -> 18 | K7: Conducted Rate: | L7: =IFERROR(I8/I6,"") -> 1 | N7: Value | O7: =IFERROR(COUNTIFS(N14:N287, "value"),"") -> 1 | Q7: Facebook Ads | R7: =IFERROR(COUNTIF(H13:H286,Q7),"") -> 0 | S7: Google | T7: =IFERROR(COUNTIF(H13:H286,S7),"") -> 0
B8: Total Lost : | C8: =COUNTIF(I13:I286,"offer & didn't buy")+countif(I13:I286,"deposit")+countif(I13:I286,"bad fit & no offer") -> 7 | E8: Rescheduled: | F8: =IFERROR(COUNTIFS(I13:I287, "Rescheduled"),"") -> 0 | H8: Calls: | I8: =IFERROR(SUM(F2:F6),"") -> 18 | Q8: LinkedIn | R8: =IFERROR(COUNTIF(H13:H286,Q8),"") -> 0 | S8: Referral | T8: =IFERROR(COUNTIF(H13:H286,S8),"") -> 0
B9: Closing % : | C9: =iferror(SUM(C7/C6),"") -> 0.61111111 | E9: Cancelled: | F9: =IFERROR(COUNTIFS(I13:I287, "Cancelled"),"") -> 0 | H9: Offers: | I9: =IFERROR(sum(F2:F5),"") -> 18
B10: Rev per lead | C10: =C3/C6 -> 4416.6667 | E10: No-Show: | F10: =IFERROR(COUNTIFS(I13:I287, "No-Show"),"") -> 0 | H10: Deals | I10: =F2+F3 -> 11
B12: Date | C12: Name | E12: Phone No. | F12: Email | H12: Source | I12: Outcome | K12: Revenue | L12: Cash | N12: Objection | O12: Objection Notes | Q12: Length | R12: Recording Link | S12: Follow Up/Next Steps | T12: Call Summary
B13: 01.07.25 | C13: Katia Kirstine Agri | E13: 28 78 59 01 | F13: katiac2992@gmail.com | H13: Setter | I13: Split-pay | K13: 6000 | L13: 3000 | Q13: 3 måneder | R13: https://slack-files.com/T089JBRTVMM-F093GLB4NKH-8d9f85d0df | S13: Closed | T13: Vægttab, spiseforstyrrelse siden hun var 6 år (er 33) glæden tilbage ved mad, struktur og gode vaner. Selvbillede. Har diabetes 1, IBS, glutenallergi.
B14: 01.07.25 | C14: Eva Boye Rasmussen | E14: 31 33 35 64 | F14: evabr99@gmail.com | H14: Setter | I14: Offer & Didn't Buy | N14: Money | O14: På SU. Usikker på resultater | Q14: 3 måneder | S14: X | T14: Spiseforstyrrelse. Går 13 år tilbage. Aldrig haft balance i kosten. Prøvet flere ting uden at lykkedes. Genoptrænings hos fys. Meget tvivl omkring hun kan lykkes med det.
B15: 05.07.25 | C15: Jessica Rasmussen | E15: 40 61 97 89 | F15: rasmussenjessica9@gmail.com | H15: Setter | I15: Split-pay | K15: 9000 | L15: 1500 | N15: Money | O15: På kontakthjælp | Q15: 5 måneder | R15: https://slack-files.com/T089JBRTVMM-F0943BG3G31-a11871ad1f | S15: Closed | T15: Har i 6 år kæmpet med overvægt. Været på vægttabsmedicin og tog alt på igen. Har vejet over 100 kg og ønsker forandring nu. Opstart 1. aug. Afsluttet i okt. grundet økonomi
B16: 08.07.25 | C16: Rikke Petersen | E16: 50 56 13 21 | F16: rik98@outlook.dk | H16: Setter | I16: Offer & Didn't Buy | N16: Fear | O16: Snak med partner | Q16: 4 måender | R16: https://slack-files.com/T089JBRTVMM-F094ZRKDD50-21466958f8 | S16: X | T16: Skabe opbyggende rutiner som styrker selvværd. Har svært ved at stå stærkt i sig selv og sige nej. Går 8 år tilbage - har ikke knækket koden til den livsstil hun ønsker sig. Mindset
B17: 08.07.25 | C17: Karen Magrethe René Sørensen | E17: 28 15 82 15 | F17: karsoe25@icloud.com | H17: Setter | I17: Full-Pay | K17: 7500 | L17: 7500 | Q17: 4 måneder | R17: https://slack-files.com/T089JBRTVMM-F095F4WCB08-4eec636472 | S17: Closed | T17: Manger træningsplan, motivation og lyst til at holde fast i vaner. Tabe fedt på maven og få en stærkere krop. Går 6 år tilbage.
B18: 09.07.25 | C18: Emma Kjærsgaard Gyldenvang | E18: 91 56 68 91 | F18: emmagyldenvang@gmail.com | H18: Setter | I18: Split-pay | K18: 7500 | L18: 5000 | N18: Money | O18: På SU | Q18: 4 måneder | R18: https://slack-files.com/T089JBRTVMM-F094U35EKQT-559a3c6aca | S18: Closed | T18: Døjer med konstant oppustethed (sidste 2-3 år) Mere viden omkring kost
B19: 10.07.25 | C19: Sara Pedersen | E19: 42 18 67 87 | F19: saraepedersen@hotmail.dk | H19: Setter | I19: Full-Pay | K19: 7500 | L19: 7500 | N19: Money | O19: Stor investering men ser værdien | Q19: 4 måneder | R19: https://slack-files.com/T089JBRTVMM-F09565V8VJN-716aa456e1 | S19: Closed | T19: Hjælp til at få helt styr på kosten. Er på vægttabsmedicin og vil meget gerne af den! Har tabt 17 kg. på 3 måneder via medicin og ønsker nu at skabe en sund livsstil så hun kan bevare vægttabet. Har vejet over 100 kg og altid haft svært ved sund kost og overvægt.
B20: 14.07.25 | C20: Frederikke Leonthin (ringet + skrevet) | E20: 41 15 11 41 | F20: fleonthin@hotmail.com | H20: Setter | I20: Full-Pay | K20: 9000 | L20: 9000 | Q20: 5 måneder | R20: https://slack-files.com/T089JBRTVMM-F095Q3DKSRJ-ba4b55697b | S20: Closed | T20: Ønsker viden omkring sammensætning af kost, styrketræning i fitness (teknik). Meget fokus på mindset. Har haft svært ved kost og døjet med undervægt i 20 år (hun er 30). Fik talt sig varm på at starte nu. Tilladelse til at kontakte om en måneds tid for at høre hvordan det går. Har veninde der er i forløb hun kan følges med.
B21: 14.07.25 | C21: Annette Bangshøj | E21: 28 15 05 11 | F21: annette-clausen@hotmail.com | H21: Setter | I21: Offer & Didn't Buy | N21: Value | O21: Ikke nok pain | Q21: 3 måneder | R21: https://slack-files.com/T089JBRTVMM-F096HC7U8UQ-5c0844adb4 | S21: X | T21: Ønsker at få styr på sine spisevaner - træner meget i forvejen og føler hun har godt styr på det. Kosten er også okay, men hun mangler lige det sidste. Mere energi og viden om mad
B22: 18.07.25 | C22: Ida Sjømann (skrevet og ringet) | E22: 30 48 25 14 | F22: idasjoemann@gmail.com | H22: Setter | I22: Full-Pay | K22: 7500 | L22: 7500 | Q22: 4 måneder | R22: https://slack-files.com/T089JBRTVMM-F096ELC6EGJ-67e1074c2c | S22: Closed | T22: Styr på kosten. Er ved politiet med omskiftelige arbejdstider. mangler en overskuelig madplan og ønsker hjælp til hjemmetræning. tabe 5 kg og tonet krop.
B23: 20.07.25 | C23: Sara Ingwersen (ringet og skrevet) | E23: 42 16 63 16 | F23: sara1508@hotmail.dk | H23: Setter | I23: Split-pay | K23: 9000 | L23: 3000 | N23: Money | Q23: 5 måneder | R23: https://slack-files.com/T089JBRTVMM-F09710309FT-d2831088d6 | S23: Closed | T23: Har været i coach-forløb før, men er klar på at finde den rette hjælp og investere i sig selv. Vil gerne tabe 5-10 kg. Viden om kost og særligt mindset!
B24: 22.07.25 | C24: Cecilie Dybdal Holm | E24: 24 26 16 46 | F24: cecilie.holm@hotmail.com | H24: Setter | I24: Offer & Didn't Buy | N24: Money | O24: Penge og frygt | Q24: 5 måneder | R24: https://slack-files.com/T089JBRTVMM-F096WT5M04A-aa1c520e04 | S24: X | T24: Har været i forløb før - uheldig oplevelse. Ønsker hjælp til at tabe 10+kg, mindset. Går 8 år tilbage on og off. Løber meget. Snacker. Ønsker mere balance i kosten og hjælp til styrketræning.
B25: 25.07.25 | C25: Camilla Ø. Christensen | E25: 30 28 20 39 | F25: camilla_oestergaard@hotmail.com | H25: Setter | I25: Offer & Didn't Buy | N25: Think About It | O25: Snakket med andre coaches | Q25: 5 måneder | R25: https://slack-files.com/T089JBRTVMM-F097HRZ36SG-3d8b6769d4 | S25: X | T25: Har brug for hjælp til at finde tilbage til rytmen. Tabe 8 kg. Støtte og en til at holde hende på rette vej
B26: 28.07.25 | C26: Joanna Sadiq | E26: 28 11 42 77 | F26: joannasadiq@gmail.com | H26: Setter | I26: Offer & Didn't Buy | N26: Fear | Q26: 4 måneder | R26: https://slack-files.com/T089JBRTVMM-F097R8V42R4-0b2c1429c3 | S26: X | T26: Hjælp til kostvaner - snacker meget. Har fundet et træningsprogram hun godt kan lide men er usikker på teknik (delte mavemuskler)
B27: 28.07.25 | C27: Tina Biltzing (ringet + skrevet) | E27: 24 61 58 98 | F27: tinabiltzing@hotmail.com | H27: Setter | I27: Split-pay | N27: Money | Q27: 5 måneder | R27: https://slack-files.com/T089JBRTVMM-F097R0NAJ6R-6c03255696 | S27: Closed | T27: Svært ved søvnrytme og prioritere tid til sig selv. Ønsker redskaber til at fastholde rutiner der passer ind i hendes hverdag som familiemor. Ønsker at tabe 20 kg og føle sig tilpas i sin krop.
B28: 28.07.25 | C28: Emilie Bojesen Harboe | E28: 42 77 13 32 | F28: emiliebojesenharboe@gmail.com | H28: Setter | I28: Offer & Didn't Buy | N28: Think About It | Q28: 4 måneder | R28: https://slack-files.com/T089JBRTVMM-F097R8T6WNA-3f8f89a3ed | S28: X | T28: Har fint styr på træningen, men ønsker hjælp til kosten og mere protein. Mæthed. Mere energi - finde en god struktur tabe 5 kg. Går 4 år tilbage. Overspiser op til sin cyklus.
B29: 30.07.25 | C29: Maiken Xia Engemand (forlænget) | E29: 60 48 80 41 | F29: maiken.engemand@gmail.com | H29: Setter | I29: Split-pay | K29: 7500 | L29: 1500 | N29: Money | Q29: 4 måneder | R29: https://slack-files.com/T089JBRTVMM-F0980EV9X0B-a088f9f3c9 | S29: Closed | T29: Brug for at tage 3 kg på. Har forhøjet stofskifte og har ikke kunne tage på de sidste 5 år. Har brug for balance i rutiner omkring kost og træning. Stress, søvn, angst, oppustet. Læge siger hun har en spiseforstyrrelse men det mener hun ikke selv hun har.
B30: 30.07.25 | C30: Nina Feddersen | E30: 28 18 90 56 | F30: ninafeddersen@yahoo.dk | H30: Setter | I30: Split-pay | K30: 9000 | L30: 1500 | N30: Money | Q30: 5 måneder | R30: https://slack-files.com/T089JBRTVMM-F0986P0EMKL-f55388be31 | S30: Closed | T30: Brug for ro omkring mad. Måske et vægttab på 5 kg hvis muligt men ikke målet. Struktur på sin træning. Holdbare vaner. Mindset omkring mad.

Sheet Aug
B1: Rep: | C1: Name | E1: Outcome | H1: KPIs% | K1: Show Rate | N1: Objections | Q1: Source | U1: Tracking
E2: Full-Pay: | F2: =IFERROR(COUNTIFS(I13:I287, "Full-Pay"),"") -> 3 | H2: Conversion Rate: | I2: =iferror(I10/I8,"") -> 0.54545455 | K2: Rescheduling Rate: | L2: =iferror(F8/I6,"") -> 0.043478261 | N2: Think About It | O2: =IFERROR(COUNTIFS(N13:N286, "think about it"),"") -> 2 | Q2: Reschedule | R2: =IFERROR(COUNTIF(H13:H286,Q2),"") -> 0 | S2: Cold Call | T2: =IFERROR(COUNTIF(H13:H286,S2),"") -> 0
B3: Revenue | C3: =IFERROR(SUM(K13:K283),"") -> 103500 | E3: Split-Pay: | F3: =IFERROR(COUNTIFS(I13:I287, "Split-Pay"),"") -> 9 | H3: Offer To Close Rate: | I3: =IFERROR(I10/I9,"") -> 0.54545455 | K3: Cancellation Rate: | L3: =iferror(F9/I6,"") -> 0 | N3: Money | O3: =IFERROR(COUNTIFS(N13:N286, "money"),"") -> 13 | Q3: YouTube | R3: =IFERROR(COUNTIF(H13:H286,Q3),"") -> 0 | S3: Twitter | T3: =IFERROR(COUNTIF(H13:H286,S3),"") -> 0
B4: Cash | C4: =IFERROR(SUM(L13:L284),"") -> 49500 | E4: Deposits: | F4: =IFERROR(COUNTIFS(I13:I287, "Deposit"),"") -> 0 | H4: Call To Offer Rate: | I4: =IFERROR(I9/I8,"") -> 1 | K4: No-Shows Rate: | L4: =iferror(F10/I6,"") -> 0 | N4: Time | O4: =IFERROR(COUNTIFS(N13:N286, "time"),"") -> 1 | Q4: YouTube Ads | R4: =IFERROR(COUNTIF(H13:H286,Q4),"") -> 0 | S4: Skool | T4: =IFERROR(COUNTIF(H13:H286,S4),"") -> 0
E5: Offer & Didn't Buy: | F5: =IFERROR(COUNTIFS(I13:I287, "Offer & Didn't Buy"),"") -> 10 | H5: Drag Over Rate: | I5: =IFERROR(F7/(C6+F7+F8),"") -> 0 | K5: Drag Over Rate: | L5: =iferror(F7/I6,"") -> 0 | N5: Partner | O5: =IFERROR(COUNTIFS(N13:N286, "partner"),"") -> 5 | Q5: Email | R5: =IFERROR(COUNTIF(H13:H286,Q5),"") -> 0 | S5: Instagram | T5: =IFERROR(COUNTIF(H13:H286,S5),"") -> 0
B6: Total Calls : | C6: =IFERROR(SUM(F2:F6),"") -> 22 | E6: Bad Fit & No Offer: | F6: =IFERROR(COUNTIFS(I13:I287, "Bad Fit & No Offer"),"") -> 0 | H6: Bookings: | I6: =IFERROR(SUM(F2:F10),"") -> 23 | K6: Show-Up Rate: | L6: =iferror(I7/I6,"") -> 0.95652174 | N6: Fear | O6: =IFERROR(COUNTIFS(N13:N286, "fear"),"") -> 2 | Q6: Facebook | R6: =IFERROR(COUNTIF(H13:H286,Q6),"") -> 0 | S6: TikTok | T6: =IFERROR(COUNTIF(H13:H286,S6),"") -> 0
B7: Total Won : | C7: =IFERROR(F2+F3,"") -> 12 | E7: Drag Over & Show: | F7: =IFERROR(COUNTIFS(I13:I287, "Drag Over & Show"),"") -> 0 | H7: Shows: | I7: =IFERROR(SUM(F2:F7),"") -> 22 | K7: Conducted Rate: | L7: =IFERROR(I8/I6,"") -> 0.95652174 | N7: Value | O7: =IFERROR(COUNTIFS(N14:N287, "value"),"") -> 0 | Q7: Facebook Ads | R7: =IFERROR(COUNTIF(H13:H286,Q7),"") -> 0 | S7: Google | T7: =IFERROR(COUNTIF(H13:H286,S7),"") -> 0
B8: Total Lost : | C8: =COUNTIF(I13:I286,"offer & didn't buy")+countif(I13:I286,"deposit")+countif(I13:I286,"bad fit & no offer") -> 10 | E8: Rescheduled: | F8: =IFERROR(COUNTIFS(I13:I287, "Rescheduled"),"") -> 1 | H8: Calls: | I8: =IFERROR(SUM(F2:F6),"") -> 22 | Q8: LinkedIn | R8: =IFERROR(COUNTIF(H13:H286,Q8),"") -> 0 | S8: Referral | T8: =IFERROR(COUNTIF(H13:H286,S8),"") -> 0
B9: Closing % : | C9: =iferror(SUM(C7/C6),"") -> 0.54545455 | E9: Cancelled: | F9: =IFERROR(COUNTIFS(I13:I287, "Cancelled"),"") -> 0 | H9: Offers: | I9: =IFERROR(sum(F2:F5),"") -> 22
B10: Rev per lead | C10: =C3/C6 -> 4704.5455 | E10: No-Show: | F10: =IFERROR(COUNTIFS(I13:I287, "No-Show"),"") -> 0 | H10: Deals | I10: =F2+F3 -> 12
B12: Date | C12: Name | E12: Phone No. | F12: Email | H12: Source | I12: Outcome | K12: Revenue | L12: Cash | N12: Objection | O12: Objection Notes | Q12: Length | R12: Recording Link | S12: Follow Up/Next Steps | T12: Call Summary
B13: 04.08.25 | C13: Tine Hauerslev (skrevet + ringet) | E13: 60 84 20 84 | F13: tine.hauerslev@hotmail.com | H13: Setter | I13: Full-Pay | K13: 9000 | L13: 9000 | Q13: 5 måneder | R13: https://slack-files.com/T089JBRTVMM-F098DN2HSGP-b0165539e8 | S13: Closed | T13: Har de sidste 4 år haft svært ved at finde tilbage efter en stresset periode. Har skiftet arbejde til et roligt miljø og ønsker nu at få både træningsrutine og kostvaner på plads. Har haft en spiseforstyrrelse hvor hun kontrollerer alt hun spiser. Har taget 10 kg. på - det er ikke målet i sig selv at tabe dem. Mere madro og forbinde til kroppens signaler igen.
B14: 05.08.25 | C14: Amalie Raunsbæk Hagedron | E14: 22 21 74 80 | F14: amalieraunsbk.hagedorn@hotmail.com | H14: Setter | I14: Split-pay | K14: 9000 | L14: 3000 | N14: Partner | Q14: 5 måneder | R14: https://slack-files.com/T089JBRTVMM-F0993JCB8G4-0b9f65fdc7 | S14: Closed | T14: Er konstant oppustet. Har været i forløb før hvor hun talte meget kalorier hvilket har givet hende et ubalanceret forhold til kost. Alt eller intet mentaltiet. Dårlig søvn. Hjemmetræningsprogram og balance i kosten. Mere energi og overskud.
B15: 05.08.25 | C15: Astrid Kudahl Lyngsø | E15: 81 10 03 95 | F15: askuly04@gmail.com | H15: Setter | I15: Offer & Didn't Buy | N15: Think About It | Q15: 3 måneder | R15: https://slack-files.com/T089JBRTVMM-F098Y8NCXDZ-6f8ae40844 | S15: X | T15: Snacker meget og har svært ved at finde en god balance i kosten. Har eksem og vil gerne spise efter det. Have mere energi og sund livsstil så hun kan præstere bedre. Spiller badminton 3 gange i ugen men ønsker muligvis hjemmetræningsprogram.
B16: 06.08.25 | C16: Line Sofie Pico | E16: 61 46 14 98 | F16: line_pico@hotmail.com | H16: Setter | I16: Split-pay | K16: 9000 | L16: 3000 | N16: Money | Q16: 5 måneder | R16: https://slack-files.com/T089JBRTVMM-F0991JF7DTQ-bd5e205964 | S16: Closed | T16: Line har kræft i livmoderen og er jævnligt sengelæggende 3-4 måneder af gangen pga. operationer. Har sin sidste operation 12.sep. Har tidligere været meget trænet og spise stadig sundt, men har nu meget væske og fedt i kroppen grundet sygdom. Vil gerne tilbage på sporet så hun kan føle sig som sig selv igen. Hjemmetræning og vægttab på 15 kg. Støtte til at holde gejsten oppe.
B17: 08.08.25 | C17: Sofie Madsen | E17: 53 35 44 04 | F17: svbmadsen@gmail.com | H17: Setter | I17: Full-Pay | K17: 9000 | L17: 9000 | N17: Money | Q17: 5 måneder | R17: https://slack-files.com/T089JBRTVMM-F099Q2HRZ36-b50ae346ed | S17: Closed | T17: Ønsker at føle sig tilpas i sin egen krop. Har svært ved at hendes kæreste rør hende nogle steder på kroppen fordi hun er usikker. Har prøvet at finde balance i kosten og træningen siden 8. klasse (er 21) Indre stemme fylder meget. Mindset. Har ikke knækket koden til hvad der fungerer for hende.
B18: 09.08.25 | C18: Mai Laub Nielsen | E18: 29 89 85 07 | F18: mainielsen4@gmail.com | H18: Setter | I18: Offer & Didn't Buy | N18: Partner | Q18: 5 måneder | R18: https://slack-files.com/T089JBRTVMM-F099ADUKLCX-cf9e0ade9f | S18: X | T18: Alt eller intet mentalitet. Balance i kosten. Svinger 5-10 kg. i vægt. Sundere forhold til mad så hun kan vende tilbage til sig selv. Motivation.
B19: 11.08.25 | C19: Merete Jacobsen | E19: 22 10 29 36 | F19: merete81@hotmail.com | H19: Setter | I19: Offer & Didn't Buy | N19: Money | O19: Har brug for tænketid og kigge på økonomi. Har sat et loft på 1000 kr. men vil kigge på om hun kan få det til at køre rundt. Snakket med hende om at følge op i januar | Q19: 4 måneder | R19: https://slack-files.com/T089JBRTVMM-F09ALFYT6PJ-88386d2205 | S19: Follow Up | T19: Merete er i andet forløb, men føler sig presset med den tilgang der bliver brugt og ønsker derfor at skifte forløb til noget mere balanceret. Hun har de sidste 8 måneder været ude af takt med de gode rutiner og ønsker at finde tilbage. VIl gerne have en mere tonet krop, vægttab på 5 kg, bedre søvn, balance i kosten. Har spillet fodbold på eliteplan og har en tendens til at overtærne og har derfor brug for stuktur, også på sine hvil så hun kan finde mere ro i hverdagen. Hendes tilstand stopper hende i flere ting som rejser, finde en kæreste og at søge nyt job. Løber
B20: 12.08.25 | C20: Alma Murguz | E20: 30 82 62 20 | F20: almamurguz@hotmail.com | H20: Setter | I20: Offer & Didn't Buy | N20: Money | O20: Forældre betaling | Q20: 5 måneder | R20: https://slack-files.com/T089JBRTVMM-F099UAX0E11-f28f8c81f5 | S20: X | T20: Ønsker at finde balance i kosten og finde en god træningsrutine. Tabe ca 5 kg fedt og få tonet krop. Mangler indblik og viden i forhold til kostsammensætning. Har for 1,5 år siden haft en forstyrret spisning med opkastninger. Varede 3-4 måneder og fik selv stoppet det. Ønsker hjemmetræning til en start. Det går 4-5 år tilbage.
B21: 13.08.25 | C21: Christina Kraul Møllegaard | E21: 28 71 83 89 | F21: christinamoe93@hotmail.com | H21: Setter | I21: Split-pay | K21: 7500 | L21: 1500 | N21: Money | O21: Ønsker 5 måneder men starter med 4 grundet økonomi | Q21: 4-5 måneder | R21: https://slack-files.com/T089JBRTVMM-F09A5REG4P7-98cf85d13a | S21: Closed | T21: Rejseleder og ønsker derfor et fleksibelt træningsprogram - hjemmetræning uden for mange redskaber og fitnesscenter (elsker at løfte tungt). Vægttab på 5 kg + mere muskelmasse. Føler sig ikke tilfreds med sin krop. Har fokus på at skifte mindset - kan ikke overholde aftaler med sig selv og laver altid undskyldninger for ikke at komme afsted. Oppustet, balance i kosten, overspisninger da hun kommer fra et hjem hvor man spiser op.
B22: 14.08.25 | C22: Siggi Løvstrøm | E22: 61 28 67 11 | F22: sikki-l@hotmail.com | H22: Setter | I22: Rescheduled | N22: Money | O22: Follow up dec. | Q22: 4 måneder | R22: https://slack-files.com/T089JBRTVMM-F09AFLY1WA2-7e028e4514 | S22: Follow Up | T22: ADD, misbrug af hash (går i behandling) ønsker først og fremmest at arbejde på sit mindset - taler hårdt til sig selv, dårlig selvværd - går 10 år tilbage. Træner og vil gerne leve sundt og stå skarpt. Tabe 5 kg. fedt.
