Workbook

Sheet Dashboard
A1: Sales tracking
A2: Key Metrics | B2: YTD | C2: January | D2: February | E2: March | F2: April | G2: May | H2: June | I2: July | J2: August | K2: September | L2: October | M2: November | N2: December | O2: SPARKLINES
A3: Conversion Rate: | B3: =iferror(B12/B10,"") -> 0.39364303 | D3: =IFERROR(Feb!I2,"") | E3: =Mar!I2 -> 0.44444444 | F3: =IFERROR(Apr!I2,"") -> 0.375 | G3: =IFERROR(May!I2,"") -> 0.47252747 | H3: =IFERROR(Jun!I2,"") -> 0.34259259 | I3: =IFERROR(Jul!I2,"") -> 0.37234043 | J3: =IFERROR(Aug!I2,"") | K3: =IFERROR(Sep!I2,"") | L3: =IFERROR(Oct!I2,"") | M3: =IFERROR(Nov!I2,"") | N3: =IFERROR(Dec!I2,"") | O3: =IFERROR(__xludf.DUMMYFUNCTION("IFERROR(SPARKLINE(C3:N3, {""chartype"", ""line""; ""color"", ""blue""})) "),"")
A4: Offer To Close Rate: | B4: =iferror(B12/B11,"") -> 0.39655172 | D4: =IFERROR(Feb!I3,"") | E4: =IFERROR(Mar!I3,"") -> 0.44444444 | F4: =IFERROR(Apr!I3,"") -> 0.37974684 | G4: =IFERROR(May!I3,"") -> 0.47252747 | H4: =IFERROR(Jun!I3,"") -> 0.34579439 | I4: =IFERROR(Jul!I3,"") -> 0.37634409 | J4: =IFERROR(Aug!I3,"") | K4: =IFERROR(Sep!I3,"") | L4: =IFERROR(Oct!I3,"") | M4: =IFERROR(Nov!I3,"") | N4: =IFERROR(Dec!I3,"") | O4: =IFERROR(__xludf.DUMMYFUNCTION("IFERROR(SPARKLINE(C4:N4, {""chartype"", ""line""; ""color"", ""blue""})) "),"")
A5: Call To Offer Rate: | B5: =IFERROR(B11/B10,"") -> 0.99266504 | D5: =IFERROR(Feb!I4,"") | E5: =IFERROR(Mar!I4,"") -> 1 | F5: =IFERROR(Apr!I4,"") -> 0.9875 | G5: =IFERROR(May!I4,"") -> 1 | H5: =IFERROR(Jun!I4,"") -> 0.99074074 | I5: =IFERROR(Jul!I4,"") -> 0.9893617 | J5: =IFERROR(Aug!I4,"") | K5: =IFERROR(Sep!I4,"") | L5: =IFERROR(Oct!I4,"") | M5: =IFERROR(Nov!I4,"") | N5: =IFERROR(Dec!I4,"") | O5: =IFERROR(__xludf.DUMMYFUNCTION("IFERROR(SPARKLINE(C5:N5, {""chartype"", ""line""; ""color"", ""blue""})) "),"")
A6: Revenue: | B6: =IFERROR(SUM(C6:N6),"") -> 1285000 | D6: =IFERROR(Feb!C3,"") | E6: =IFERROR(Mar!$C3,"") -> 119400 | F6: =IFERROR(Apr!$C3,"") -> 242800 | G6: =IFERROR(May!$C3,"") -> 315000 | H6: =IFERROR(Jun!$C3,"") -> 289200 | I6: =IFERROR(Jul!$C3,"") -> 318600 | J6: =IFERROR(Aug!$C3,"") | K6: =IFERROR(Sep!$C3,"") | L6: =IFERROR(Oct!$C3,"") | M6: =IFERROR(Nov!$C3,"") | N6: =IFERROR(Dec!$C3,"") | O6: =IFERROR(__xludf.DUMMYFUNCTION("IFERROR(SPARKLINE(C6:N6, {""chartype"", ""line""; ""color"", ""blue""})) "),"")
A7: Cash: | B7: =IFERROR(SUM(C7:N7),"") -> 580400 | D7: =IFERROR(Feb!C4,"") | E7: =IFERROR(Mar!$C4,"") -> 44800 | F7: =IFERROR(Apr!$C4,"") -> 85700 | G7: =IFERROR(May!$C4,"") -> 130600 | H7: =IFERROR(Jun!$C4,"") -> 162400 | I7: =IFERROR(Jul!$C4,"") -> 156900 | J7: =IFERROR(Aug!$C4,"") | K7: =IFERROR(Sep!$C4,"") | L7: =IFERROR(Oct!$C4,"") | M7: =IFERROR(Nov!$C4,"") | N7: =IFERROR(Dec!$C4,"") | O7: =IFERROR(__xludf.DUMMYFUNCTION("IFERROR(SPARKLINE(C7:N7, {""chartype"", ""line""; ""color"", ""blue""})) "),"")
A8: Bookings: | B8: =IFERROR(SUM(C8:N8),"") -> 536 | D8: =IFERROR(Feb!I6,"") | E8: =IFERROR(Mar!$I6,"") -> 40 | F8: =IFERROR(Apr!$I6,"") -> 100 | G8: =IFERROR(May!$I6,"") -> 110 | H8: =IFERROR(Jun!$I6,"") -> 146 | I8: =IFERROR(Jul!$I6,"") -> 140 | J8: =IFERROR(Aug!$I6,"") | K8: =IFERROR(Sep!$I6,"") | L8: =IFERROR(Oct!$I6,"") | M8: =IFERROR(Nov!$I6,"") | N8: =IFERROR(Dec!$I6,"") | O8: =IFERROR(__xludf.DUMMYFUNCTION("IFERROR(SPARKLINE(C8:N8, {""chartype"", ""line""; ""color"", ""blue""})) "),"")
A9: Shows: | B9: =sum(C9:N9) -> 409 | D9: =IFERROR(Feb!$I$7,"") | E9: =IFERROR(Mar!$I$7,"") -> 36 | F9: =IFERROR(Apr!$I$7,"") -> 80 | G9: =IFERROR(May!$I$7,"") -> 91 | H9: =IFERROR(Jun!$I$7,"") -> 108 | I9: =IFERROR(Jul!$I$7,"") -> 94 | J9: =IFERROR(Aug!$I$7,"") | K9: =IFERROR(Sep!$I$7,"") | L9: =IFERROR(Oct!$I$7,"") | M9: =IFERROR(Nov!$I$7,"") | N9: =IFERROR(Dec!$I$7,"") | O9: =IFERROR(__xludf.DUMMYFUNCTION("IFERROR(SPARKLINE(C9:N9, {""chartype"", ""line""; ""color"", ""blue""})) "),"")
A10: Calls: | B10: =IFERROR(SUM(C10:N10),"") -> 409 | D10: =IFERROR(Feb!I8,"") | E10: =IFERROR(Mar!$I8,"") -> 36 | F10: =IFERROR(Apr!$I8,"") -> 80 | G10: =IFERROR(May!$I8,"") -> 91 | H10: =IFERROR(Jun!$I8,"") -> 108 | I10: =IFERROR(Jul!$I8,"") -> 94 | J10: =IFERROR(Aug!$I8,"") | K10: =IFERROR(Sep!$I8,"") | L10: =IFERROR(Oct!$I8,"") | M10: =IFERROR(Nov!$I8,"") | N10: =IFERROR(Dec!$I8,"") | O10: =IFERROR(__xludf.DUMMYFUNCTION("IFERROR(SPARKLINE(C10:N10, {""chartype"", ""line""; ""color"", ""blue""})) "),"")
A11: Offers: | B11: =IFERROR(SUM(C11:N11),"") -> 406 | D11: =IFERROR(Feb!I9,"") | E11: =IFERROR(Mar!$I9,"") -> 36 | F11: =IFERROR(Apr!$I9,"") -> 79 | G11: =IFERROR(May!$I9,"") -> 91 | H11: =IFERROR(Jun!$I9,"") -> 107 | I11: =IFERROR(Jul!$I9,"") -> 93 | J11: =IFERROR(Aug!$I9,"") | K11: =IFERROR(Sep!$I9,"") | L11: =IFERROR(Oct!$I9,"") | M11: =IFERROR(Nov!$I9,"") | N11: =IFERROR(Dec!$I9,"") | O11: =IFERROR(__xludf.DUMMYFUNCTION("IFERROR(SPARKLINE(C11:N11, {""chartype"", ""line""; ""color"", ""blue""})) "),"")
A12: Deals: | B12: =IFERROR(SUM(C12:N12),"") -> 161 | D12: =IFERROR(Feb!I10,"") | E12: =IFERROR(Mar!$I10,"") -> 16 | F12: =IFERROR(Apr!$I10,"") -> 30 | G12: =IFERROR(May!$I10,"") -> 43 | H12: =IFERROR(Jun!$I10,"") -> 37 | I12: =IFERROR(Jul!$I10,"") -> 35 | J12: =IFERROR(Aug!$I10,"") | K12: =IFERROR(Sep!$I10,"") | L12: =IFERROR(Oct!$I10,"") | M12: =IFERROR(Nov!$I10,"") | N12: =IFERROR(Dec!$I10,"") | O12: =IFERROR(__xludf.DUMMYFUNCTION("IFERROR(SPARKLINE(C12:N12, {""chartype"", ""line""; ""color"", ""blue""})) "),"")
A13: Full-Pay: | B13: =IFERROR(SUM(C13:N13),"") -> 72 | D13: =IFERROR(Feb!F2,"") | E13: =IFERROR(Mar!$F2,"") -> 14 | F13: =IFERROR(Apr!$F2,"") -> 30 | G13: =IFERROR(May!$F2,"") -> 4 | H13: =IFERROR(Jun!$F2,"") -> 14 | I13: =IFERROR(Jul!$F2,"") -> 10 | J13: =IFERROR(Aug!$F2,"") | K13: =IFERROR(Sep!$F2,"") | L13: =IFERROR(Oct!$F2,"") | M13: =IFERROR(Nov!$F2,"") | N13: =IFERROR(Dec!$F2,"") | O13: =IFERROR(__xludf.DUMMYFUNCTION("IFERROR(SPARKLINE(C13:N13, {""chartype"", ""line""; ""color"", ""blue""})) "),"")
A14: Split-Pay: | B14: =IFERROR(SUM(C14:N14),"") -> 89 | D14: =IFERROR(Feb!F3,"") | E14: =IFERROR(Mar!$F3,"") -> 2 | F14: =IFERROR(Apr!$F3,"") -> 0 | G14: =IFERROR(May!$F3,"") -> 39 | H14: =IFERROR(Jun!$F3,"") -> 23 | I14: =IFERROR(Jul!$F3,"") -> 25 | J14: =IFERROR(Aug!$F3,"") | K14: =IFERROR(Sep!$F3,"") | L14: =IFERROR(Oct!$F3,"") | M14: =IFERROR(Nov!$F3,"") | N14: =IFERROR(Dec!$F3,"") | O14: =IFERROR(__xludf.DUMMYFUNCTION("IFERROR(SPARKLINE(C14:N14, {""chartype"", ""line""; ""color"", ""blue""})) "),"")
A15: Deposits: | B15: =IFERROR(SUM(C15:N15),"") -> 36 | D15: =IFERROR(Feb!F4,"") | E15: =IFERROR(Mar!$F4,"") -> 1 | F15: =IFERROR(Apr!$F4,"") -> 6 | G15: =IFERROR(May!$F4,"") -> 4 | H15: =IFERROR(Jun!$F4,"") -> 9 | I15: =IFERROR(Jul!$F4,"") -> 16 | J15: =IFERROR(Aug!$F4,"") | K15: =IFERROR(Sep!$F4,"") | L15: =IFERROR(Oct!$F4,"") | M15: =IFERROR(Nov!$F4,"") | N15: =IFERROR(Dec!$F4,"") | O15: =IFERROR(__xludf.DUMMYFUNCTION("IFERROR(SPARKLINE(C15:N15, {""chartype"", ""line""; ""color"", ""blue""})) "),"")
A16: Show-Up Rate: | B16: =B9/B8 -> 0.7630597 | D16: =IFERROR(Feb!$L6,"") | E16: =IFERROR(Mar!$L6,"") -> 0.9 | F16: =IFERROR(Apr!$L6,"") -> 0.8 | G16: =IFERROR(May!$L6,"") -> 0.82727273 | H16: =IFERROR(Jun!$L6,"") -> 0.73972603 | I16: =IFERROR(Jul!$L6,"") -> 0.67142857 | J16: =IFERROR(Aug!$L6,"") | K16: =IFERROR(Sep!$L6,"") | L16: =IFERROR(Oct!$L6,"") | M16: =IFERROR(Nov!$L6,"") | N16: =IFERROR(Dec!$L6,"") | O16: =IFERROR(__xludf.DUMMYFUNCTION("IFERROR(SPARKLINE(C16:N16, {""chartype"", ""line""; ""color"", ""blue""})) "),"")
A17: Conducted Rate: | B17: =B10/B8 -> 0.7630597 | D17: =IFERROR(Feb!$L7,"") | E17: =IFERROR(Mar!$L7,"") -> 0.9 | F17: =IFERROR(Apr!$L7,"") -> 0.8 | G17: =IFERROR(May!$L7,"") -> 0.82727273 | H17: =IFERROR(Jun!$L7,"") -> 0.73972603 | I17: =IFERROR(Jul!$L7,"") -> 0.67142857 | J17: =IFERROR(Aug!$L7,"") | K17: =IFERROR(Sep!$L7,"") | L17: =IFERROR(Oct!$L7,"") | M17: =IFERROR(Nov!$L7,"") | N17: =IFERROR(Dec!$L7,"") | O17: =IFERROR(__xludf.DUMMYFUNCTION("IFERROR(SPARKLINE(C17:N17, {""chartype"", ""line""; ""color"", ""blue""})) "),"")

Sheet Mar
B1: Rep: | C1: Name | E1: Outcome | H1: KPIs% | K1: Show Rate | N1: Objections | Q1: Source | U1: Tracking
E2: Full-Pay: | F2: =IFERROR(COUNTIFS(I16:I292, "Full-Pay"),"") -> 14 | H2: Conversion Rate: | I2: =iferror(I10/I8,"") -> 0.44444444 | K2: Rescheduling Rate: | L2: =iferror(F8/I6,"") -> 0 | N2: Think About It | O2: =IFERROR(COUNTIFS(N16:N291, "think about it"),"") -> 9 | Q2: Setter | R2: =IFERROR(COUNTIF(H16:H291,"setter"),"") -> 40 | S2: Cold Call | T2: =IFERROR(COUNTIF(H16:H291,S2),"") -> 0
B3: Revenue | C3: =IFERROR(SUM(K16:K288),"") -> 119400 | E3: Split-Pay: | F3: =IFERROR(COUNTIFS(I16:I292, "Split-Pay"),"") -> 2 | H3: Offer To Close Rate: | I3: =IFERROR(I10/I9,"") -> 0.44444444 | K3: Cancellation Rate: | L3: =iferror(F9/I6,"") -> 0.05 | N3: Money | O3: =IFERROR(COUNTIFS(N16:N291, "money"),"") -> 11 | Q3: IG | R3: =IFERROR(COUNTIF(H16:H291,"IG"),"") -> 0 | S3: Twitter | T3: =IFERROR(COUNTIF(H16:H291,S3),"") -> 0
B4: Cash | C4: =IFERROR(SUM(L16:L289),"") -> 44800 | E4: Deposits: | F4: =IFERROR(COUNTIFS(I16:I292, "Deposit"),"") -> 1 | H4: Call To Offer Rate: | I4: =IFERROR(I9/I8,"") -> 1 | K4: No-Shows Rate: | L4: =iferror(F10/I6,"") -> 0.05 | N4: Time | O4: =IFERROR(COUNTIFS(N16:N291, "time"),"") -> 1 | Q4: YouTube | R4: =IFERROR(COUNTIF(H16:H291,"youtube"),"") -> 0 | S4: Skool | T4: =IFERROR(COUNTIF(H16:H291,S4),"") -> 0
E5: Offer & Didn't Buy: | F5: =IFERROR(COUNTIFS(I16:I292, "Offer & Didn't Buy"),"") -> 19 | H5: Drag Over Rate: | I5: =IFERROR(F7/(C6+F7+F8),"") -> 0 | K5: Drag Over Rate: | L5: =iferror(F7/I6,"") -> 0 | N5: Partner | O5: =IFERROR(COUNTIFS(N16:N291, "partner"),"") -> 1 | Q5: Email | R5: =IFERROR(COUNTIF(H16:H291,"email"),"") -> 0 | S5: Instagram | T5: =IFERROR(COUNTIF(H16:H291,S5),"") -> 0
B6: Total Calls : | C6: =IFERROR(SUM(F2:F6),"") -> 36 | E6: Bad Fit & No Offer: | F6: =IFERROR(COUNTIFS(I16:I292, "Bad Fit & No Offer"),"") -> 0 | H6: Bookings: | I6: =IFERROR(SUM(F2:F10),"") -> 40 | K6: Show-Up Rate: | L6: =iferror(I7/I6,"") -> 0.9 | N6: Fear | O6: =IFERROR(COUNTIFS(N16:N291, "fear"),"") -> 2 | Q6: Facebook | R6: =IFERROR(COUNTIF(H16:H291,"facebook"),"") -> 0 | S6: TikTok | T6: =IFERROR(COUNTIF(H16:H291,S6),"") -> 0
B7: Total Won : | C7: =IFERROR(F2+F3,"") -> 16 | E7: Drag Over & Show: | F7: =IFERROR(COUNTIFS(I16:I292, "Drag Over & Show"),"") -> 0 | H7: Shows: | I7: =IFERROR(SUM(F2:F7),"") -> 36 | K7: Conducted Rate: | L7: =IFERROR(I8/I6,"") -> 0.9 | N7: Value | O7: =IFERROR(COUNTIFS(N17:N292, "value"),"") -> 0 | Q7: Facebook Ads | R7: =IFERROR(COUNTIF(H16:H291,"facebook ads"),"") -> 0 | S7: Google | T7: =IFERROR(COUNTIF(H16:H291,S7),"") -> 0
B8: Total Lost : | C8: =COUNTIF(I16:I291,"offer & didn't buy")+countif(I16:I291,"deposit")+countif(I16:I291,"bad fit & no offer") -> 20 | E8: Rescheduled: | F8: =IFERROR(COUNTIFS(I16:I292, "Rescheduled"),"") -> 0 | H8: Calls: | I8: =IFERROR(SUM(F2:F6),"") -> 36 | Q8: LinkedIn | R8: =IFERROR(COUNTIF(H16:H291,Q8),"") -> 0 | S8: Referral | T8: =IFERROR(COUNTIF(H16:H291,S8),"") -> 0
B9: Closing % : | C9: =iferror(SUM(C7/C6),"") -> 0.44444444 | E9: Cancelled: | F9: =IFERROR(COUNTIFS(I16:I292, "Cancelled"),"") -> 2 | H9: Offers: | I9: =IFERROR(sum(F2:F5),"") -> 36
C10: =C3/C6 -> 3316.6667 | E10: No-Show: | F10: =IFERROR(COUNTIFS(I16:I292, "No-Show"),"") -> 2 | H10: Deals | I10: =F2+F3 -> 16
B12: Date | C12: Name | E12: Phone No. | F12: IG Navn | H12: Source | I12: Outcome | K12: Revenue | L12: Cash | N12: Objection | O12: Objection Notes | Q12: Length | R12: Recording Link | S12: Follow Up/Next Steps | T12: Call Summary
B13: 45841 | C13: Lucas Lund | E13: 52640883 | F13: Lucaslund11 | H13: Setter | I13: Offer & Didn't Buy | N13: Money | O13: Han havde intet arbejde | S13: X | T13: Han var klar så snart der var penge i kassen
B14: 45841 | C14: Bilal | E14: 42323092 | F14: biloo_elmoro | H14: Setter | I14: Offer & Didn't Buy | N14: Money | O14: Han blev lukket, men kunne først betale efter kaldet | S14: X | T14: Han kunne først betale efter kaldet og hørte aldrig fra ham igen
B15: 45841 | C15: Adam Olsen | E15: 22776949 | F15: ady.olsen | H15: Setter | I15: Offer & Didn't Buy | N15: Think About It | O15: Skulle snakke med sin mor | S15: X | T15: Skulle snakke med sin mor og hørte aldrig fra ham
B16: 45933 | C16: Christian Sulkjaer | E16: 22624099 | F16: chrsitiansulkjaer | H16: Setter | I16: Full-Pay | K16: 8700 | L16: 2700 | Q16: 6 mdr | S16: Closed
B17: 45933 | C17: Gustav Mortensen | E17: 23231943 | F17: Mortensen_gustav | H17: Setter | I17: Full-Pay | K17: 8700 | L17: 2700 | Q17: 6 mdr | S17: Closed
B18: 45726 | C18: Lukas Kjelgaard | E18: 29342904 | F18: Lukas.kjelgaard | H18: Setter | I18: Cancelled | N18: Fear | O18: Ikke klar til at give den gas | S18: X | T18: Personen var ikke klar til at hoppe på et kald alligevel, da han ikke følte sig klar endnu
B19: 45726 | C19: Ramazan Karali | E19: 28255187 | F19: r | H19: Setter | I19: Offer & Didn't Buy | N19: Money | O19: Kostede for meget | S19: X | T19: Personen synes det var for dyrt
B20: 45726 | C20: Markus Olsen | E20: 30440961 | F20: markusriberolsen | H20: Setter | I20: Offer & Didn't Buy | N20: Money | O20: Kostede for meget | S20: X | T20: Personen synes det var for dyrt
B21: 45727 | C21: Lukas Pedersen | E21: 25127373 | F21: Lukas_p63 | H21: Setter | I21: Full-Pay | K21: 8700 | L21: 2700 | Q21: 6 mdr | S21: Closed
B22: 45994 | C22: Sebastian Pedersen | E22: 42250101 | F22: seb_mond_pedersen | H22: Setter | I22: Offer & Didn't Buy | N22: Think About It | O22: Han skulle tænke over det | S22: Hot Follow Up | T22: Han vender tilbage om han er ready eller ej
B23: 45994 | C23: Nicolas | E23: 53730010 | F23: Nicolas.haestrup | H23: Setter | I23: Offer & Didn't Buy | N23: Think About It | O23: Han skulle tænke over det | S23: Hot Follow Up | T23: Han vender tilbage om han er ready eller ej
B24: 13/03/2025 | C24: Arpen | F24: arpencc | H24: Setter | I24: No-Show
B25: 13/03/2025 | C25: Erik Bjerregaard | E25: 25739488 | F25: erikgbjerregaard | H25: Setter | I25: Full-Pay | K25: 13500 | L25: 2700 | Q25: 10 mdr | S25: Closed
B26: 14/03/2025 | C26: Christoffer | E26: 30425868 | F26: christofferhellmann | H26: Setter | I26: No-Show | N26: Think About It
B27: 14/03/2025 | C27: Jibril | E27: 31359020 | F27: jibreel.ch.j | H27: Setter | I27: Offer & Didn't Buy | N27: Think About It | O27: Han skulle tænke over det | S27: X | T27: Han vender tilbage
B28: 15/03/2025 | C28: Tobias Nillson | E28: 42724780 | F28: toby_261006 | H28: Setter | I28: Offer & Didn't Buy | N28: Money | O28: Han startede, men hoppede så fra | S28: Hot Follow Up
B29: 15/03/2025 | C29: William Oscar | E29: 27859070 | F29: williamoscarjensen | H29: Setter | I29: Cancelled | N29: Fear | O29: Han aflyste | S29: X
B30: 16/03/2025 | C30: Magnus Johansen | E30: 42317712 | F30: magnus___j | H30: Setter | I30: Offer & Didn't Buy | N30: Money | O30: Han startede ikke op pga penge | S30: Hot Follow Up | T30: Han kan snildt lukkes
B31: 18/03/2025 | C31: simon.dinitzen | E31: 53810095 | F31: simon.dinitzen | H31: Setter | I31: Full-Pay | K31: 4600 | L31: 2200 | Q31: 3 mdr | S31: Closed
B32: 18/03/2025 | C32: Murad Adam | E32: over instagram | F32: murad__simsek | H32: Setter | I32: Full-Pay | K32: 8700 | L32: 2700 | Q32: 6 mdr | S32: Closed
B33: 19/03/2025 | C33: Tobias Kirketerp | E33: over instagram | F33: tobias.kirketerp | H33: Setter | I33: Full-Pay | K33: 6300 | L33: 2700 | Q33: 4 Mdr | S33: Closed
B34: 25/03/2025 | C34: Mikkel Andreassen | E34: Over instagram | F34: Ingen ide | H34: Setter | I34: Full-Pay | K34: 6300 | L34: 2700 | Q34: 4 Mdr | S34: Closed
B35: 25/03/2025 | C35: Sylvester | E35: Over instagram | F35: sylvester_e_schoier | H35: Setter | I35: Offer & Didn't Buy | N35: Money | O35: Han havde ikke penge | S35: Follow Up Set | T35: Manden havde ikke et arbejde og ingen penge
B36: 25/03/2026 | C36: Marcus Thiersen | E36: Over instagram | F36: Ingen ide | H36: Setter | I36: Full-Pay | K36: 8700 | L36: 2700 | N36: Money | S36: Closed
B37: 26/03/2027 | C37: Casper Bess | E37: 91544085 | F37: bess.casper | H37: Setter | I37: Offer & Didn't Buy | N37: Think About It | O37: Han synes det var dyrt | S37: Hot Follow Up | T37: Han har allerede haft anders trust som coach, men han synes det var dyrt
B38: 26/03/2027 | C38: Volkan Deniz | E38: over instagram | F38: volle_de | H38: Setter | I38: Split-Pay | K38: 6300 | L38: 2700 | Q38: 4 Mdr | S38: Closed
B39: 26/03/2027 | C39: Marvin Bøckel | E39: 29833828 | F39: marvin_boeckel | H39: Setter | I39: Offer & Didn't Buy | N39: Think About It | O39: Han skulle snakke med sin mor | S39: Hot Follow Up | T39: Han skulle snakke med sin mor
B40: 26/03/2027 | C40: Albert Trillingsgaard | E40: 53654401 | F40: Albert.Trillingsgaard | H40: Setter | I40: Full-Pay | K40: 5600 | L40: 2000 | Q40: 4 Mdr | S40: Closed
B41: 26/03/2027 | C41: Bashar mageed | E41: Over instagram | F41: Bashar.mageed | H41: Setter | I41: Full-Pay | K41: 8700 | L41: 2700 | Q41: 6 mdr | S41: Closed
...

Sheet Apr
B1: Rep: | C1: Name | E1: Outcome | H1: KPIs% | K1: Show Rate | N1: Objections | Q1: Source | U1: Tracking
E2: Full-Pay: | F2: =IFERROR(COUNTIFS(I13:I286, "Full-Pay"),"") -> 30 | H2: Conversion Rate: | I2: =iferror(I10/I8,"") -> 0.375 | K2: Rescheduling Rate: | L2: =iferror(F8/I6,"") -> 0 | N2: Think About It | O2: =IFERROR(COUNTIFS(N13:N285, "think about it"),"") -> 10 | Q2: Reschedule | R2: =IFERROR(COUNTIF(H13:H285,Q2),"") -> 0 | S2: Cold Call | T2: =IFERROR(COUNTIF(H13:H285,S2),"") -> 0
B3: Revenue | C3: =IFERROR(SUM(K13:K282),"") -> 242800 | E3: Split-Pay: | F3: =IFERROR(COUNTIFS(I13:I286, "Split-Pay"),"") -> 0 | H3: Offer To Close Rate: | I3: =IFERROR(I10/I9,"") -> 0.37974684 | K3: Cancellation Rate: | L3: =iferror(F9/I6,"") -> 0.08 | N3: Money | O3: =IFERROR(COUNTIFS(N13:N285, "money"),"") -> 26 | Q3: YouTube | R3: =IFERROR(COUNTIF(H13:H285,Q3),"") -> 0 | S3: Twitter | T3: =IFERROR(COUNTIF(H13:H285,S3),"") -> 0
B4: Cash | C4: =IFERROR(SUM(L13:L283),"") -> 85700 | E4: Deposits: | F4: =IFERROR(COUNTIFS(I13:I286, "Deposit"),"") -> 6 | H4: Call To Offer Rate: | I4: =IFERROR(I9/I8,"") -> 0.9875 | K4: No-Shows Rate: | L4: =iferror(F10/I6,"") -> 0.12 | N4: Time | O4: =IFERROR(COUNTIFS(N13:N285, "time"),"") -> 2 | Q4: YouTube Ads | R4: =IFERROR(COUNTIF(H13:H285,Q4),"") -> 0 | S4: Skool | T4: =IFERROR(COUNTIF(H13:H285,S4),"") -> 0
E5: Offer & Didn't Buy: | F5: =IFERROR(COUNTIFS(I13:I286, "Offer & Didn't Buy"),"") -> 43 | H5: Drag Over Rate: | I5: =IFERROR(F7/(C6+F7+F8),"") -> 0 | K5: Drag Over Rate: | L5: =iferror(F7/I6,"") -> 0 | N5: Partner | O5: =IFERROR(COUNTIFS(N13:N285, "partner"),"") -> 3 | Q5: Email | R5: =IFERROR(COUNTIF(H13:H285,Q5),"") -> 0 | S5: Instagram | T5: =IFERROR(COUNTIF(H13:H285,S5),"") -> 0
B6: Total Calls : | C6: =IFERROR(SUM(F2:F6),"") -> 80 | E6: Bad Fit & No Offer: | F6: =IFERROR(COUNTIFS(I13:I286, "Bad Fit & No Offer"),"") -> 1 | H6: Bookings: | I6: =IFERROR(SUM(F2:F10),"") -> 100 | K6: Show-Up Rate: | L6: =iferror(I7/I6,"") -> 0.8 | N6: Fear | O6: =IFERROR(COUNTIFS(N13:N285, "fear"),"") -> 2 | Q6: Facebook | R6: =IFERROR(COUNTIF(H13:H285,Q6),"") -> 0 | S6: TikTok | T6: =IFERROR(COUNTIF(H13:H285,S6),"") -> 0
B7: Total Won : | C7: =IFERROR(F2+F3,"") -> 30 | E7: Drag Over & Show: | F7: =IFERROR(COUNTIFS(I13:I286, "Drag Over & Show"),"") -> 0 | H7: Shows: | I7: =IFERROR(SUM(F2:F7),"") -> 80 | K7: Conducted Rate: | L7: =IFERROR(I8/I6,"") -> 0.8 | N7: Value | O7: =IFERROR(COUNTIFS(N14:N286, "value"),"") -> 0 | Q7: Facebook Ads | R7: =IFERROR(COUNTIF(H13:H285,Q7),"") -> 0 | S7: Google | T7: =IFERROR(COUNTIF(H13:H285,S7),"") -> 0
B8: Total Lost : | C8: =COUNTIF(I13:I285,"offer & didn't buy")+countif(I13:I285,"deposit")+countif(I13:I285,"bad fit & no offer") -> 50 | E8: Rescheduled: | F8: =IFERROR(COUNTIFS(I13:I286, "Rescheduled"),"") -> 0 | H8: Calls: | I8: =IFERROR(SUM(F2:F6),"") -> 80 | Q8: LinkedIn | R8: =IFERROR(COUNTIF(H13:H285,Q8),"") -> 0 | S8: Referral | T8: =IFERROR(COUNTIF(H13:H285,S8),"") -> 0
B9: Closing % : | C9: =iferror(SUM(C7/C6),"") -> 0.375 | E9: Cancelled: | F9: =IFERROR(COUNTIFS(I13:I286, "Cancelled"),"") -> 8 | H9: Offers: | I9: =IFERROR(sum(F2:F5),"") -> 79
C10: =C3/C6 -> 3035 | E10: No-Show: | F10: =IFERROR(COUNTIFS(I13:I286, "No-Show"),"") -> 12 | H10: Deals | I10: =F2+F3 -> 30
B12: Date | C12: Name | E12: Phone No. | F12: Ig navn | H12: Source | I12: Outcome | K12: Revenue | L12: Cash | N12: Objection | O12: Objection Notes | Q12: Length | R12: Recording Link | S12: Follow Up/Next Steps | T12: Call Summary
B13: 45661 | C13: Sayed | E13: 45 28 73 83 06 | F13: Sayed_srh | H13: Setter | I13: Full-Pay | K13: 10500 | L13: 3000 | O13: han havde ikke råd | Q13: 6 mdr | S13: Closed
B14: 45661 | C14: Oliver Jensen | E14: 22 55 37 95 | F14: olij06 | H14: Setter | I14: Offer & Didn't Buy | N14: Money | S14: Hot Follow Up
B15: 45661 | C15: Mikkel Nielsen | E15: 93 92 30 65 | F15: mikkel.niels | H15: Setter | I15: Full-Pay | K15: 3750 | L15: 3750 | Q15: 3 mdr | S15: Closed
B16: 45661 | C16: Jakob Voss | E16: 61 42 42 32 | F16: Hey Navn, jeg kom lige i tanke om dig og vores gode snak for ikke så længe siden, hvor vi aldrig kom igang pga økonomien stod i vejen - er det stadig det samme tilfælde? | H16: Setter | I16: Offer & Didn't Buy | N16: Money | O16: han havde ikke råd | S16: Follow Up Set | T16: Han havde ikke penge til det
B17: 45661 | C17: Emil | E17: 26 46 69 55 | F17: Emilbgqvist | H17: Setter | I17: No-Show
B18: 45661 | C18: Andreas Tøndø | E18: 53 53 86 56 | F18: Andreas_t_a | H18: Setter | I18: Full-Pay | K18: 8700 | L18: 2700 | Q18: 6 mdr | S18: Closed
B19: 45661 | C19: Noah | E19: 61608516 | F19: noah_b.j | H19: Setter | I19: Offer & Didn't Buy | N19: Partner | O19: Forældre sagde nej | S19: X | T19: Han var sygt klar, men hans forældre sagde nej. Han ville gerne når han blev 18 år gammel til sep
B20: 45661 | C20: Jonas | E20: 30 23 39 02 | F20: joneswww_ | H20: Setter | I20: Offer & Didn't Buy | N20: Money | O20: Kostede for meget | S20: Hot Follow Up | T20: Han var sygt frisk, men pengene holdte ham tilbage
B21: 45661 | C21: Oliver Kolze | E21: 53 80 23 77 | F21: oliver_kolze | H21: Setter | I21: No-Show
B22: 45692 | C22: Sebastian ladesea | E22: 30 26 22 34 | F22: Sebastianladesea | H22: Setter | I22: No-Show
B23: 45692 | C23: Silas molter | E23: 42 76 60 06 | F23: Silasmolter | H23: Setter | I23: Full-Pay | K23: 8700 | L23: 2700 | Q23: 6 mdr | S23: Closed
B24: 45692 | C24: Andreas arendal | E24: 28 86 68 75 | F24: Andreasarendal | H24: Setter | I24: Full-Pay | K24: 8700 | L24: 2700 | Q24: 6 mdr | S24: Closed
B25: 45692 | C25: William Østergaard | E25: 60 79 01 40 | F25: williamostergaard | H25: Setter | I25: Offer & Didn't Buy | N25: Partner | O25: Forældre sagde nej | S25: Hot Follow Up | T25: Han var SYGT klar, men hans forældre sagde nej, da de synes det var for dyrt
B26: 45692 | C26: Lucas Andersen | E26: 27 84 04 21 | F26: Lucas_Andersen1 | H26: Setter | I26: Full-Pay | K26: 5200 | L26: 2700 | Q26: 3 mdr | S26: Closed
B27: 45692 | C27: hakim Bcheinia | E27: 31 18 22 89 | F27: hakimBcheinia | H27: Setter | I27: No-Show
B28: 45692 | C28: Peter johansen | E28: 29 12 40 55 | F28: Peter_johansen_ | H28: Setter | I28: Full-Pay | K28: 8700 | L28: 2700 | Q28: 6 mdr | S28: Closed
B29: 45720 | C29: Søren | E29: 60 53 62 65 | F29: Soren456 | H29: Setter | I29: Offer & Didn't Buy | N29: Money | O29: Penge holdte ham tilbage | S29: Hot Follow Up | T29: Han skal 100% kontaktes igen om nogen måneder, da han var ready
B30: 45720 | C30: Billy | E30: 31 76 21 09 | F30: Billylindeblad | H30: Setter | I30: Offer & Didn't Buy | N30: Money | O30: Penge holdte ham tilbage | S30: X | T30: 17 årige gut som ikke var 100% klar endnu
B31: 45720 | C31: Haris husedzinivic | E31: 42 72 68 24 | F31: Harishusedzinivic | H31: Setter | I31: Full-Pay | K31: 8750 | L31: 2750 | Q31: 6 mdr | S31: Closed
B32: 45720 | C32: Jeppe Olsen | E32: 27 52 00 60 | F32: ingen ide | H32: Setter | I32: Full-Pay | K32: 8750 | L32: 2750 | Q32: 6 mdr | S32: Closed
B33: 45720 | C33: Amien dahhak | E33: 42 32 06 55 | F33: Amiendahhak1 | H33: Setter | I33: Offer & Didn't Buy | N33: Money | O33: Penge holdte ham tilbage | S33: X | T33: Han var slet ikke der
B34: 45720 | C34: Anders | E34: 42 66 41 68 | F34: anders_staer | H34: Setter | I34: Full-Pay | K34: 5100 | L34: 2700 | Q34: 3 mdr | S34: Closed
B35: 45751 | C35: Frederik sørensen | E35: 21 30 07 40 | F35: Sorensen_frederik129 | H35: Setter | I35: Offer & Didn't Buy | N35: Money | O35: synes det var dyrt | S35: Hot Follow Up | T35: Frederik havde fuldtidsarbejde, havde pengene til det, men tror ikke jeg fik ham comitted nok og derfor ikke så værdien i det. rigtig godt follow up
B36: 45751 | C36: Lucas | E36: 42 65 40 96 | F36: lucas.2.7.4.0 | H36: Setter | I36: Offer & Didn't Buy | N36: Think About It | O36: Han skulle tænke over det | S36: Hot Follow Up | T36: Han var også håndværker og er et rigtig godt follow up
B37: 45751 | C37: Jakob | E37: 40 84 23 99 | F37: Jakobjanum | H37: Setter | I37: Offer & Didn't Buy | N37: Time | O37: Han var ikke klar endnu | S37: X | T37: Ham skal jeg ikke arbejde med
B38: 45751 | C38: Nikolai Louis Møllegaard | E38: 42 23 75 41 | F38: ungnico69 | H38: Setter | I38: Full-Pay | K38: 8750 | L38: 2750 | Q38: 6 mdr | S38: Closed
B39: 45781 | C39: Martin Hellesøe | E39: Over instagram | F39: martin_hellese | H39: Setter | I39: Offer & Didn't Buy | N39: Money | O39: Ikke råd | S39: Hot Follow Up | T39: Rigtig godt lead som faktisk var 100%, havde fuldtidsjob, men da han skulle snakke med fruen, så blev det til et nej
B40: 45781 | C40: Anders Frederiksen | E40: 24201093 | F40: anders_hf | H40: Setter | I40: Offer & Didn't Buy | N40: Money | O40: Ikke råd | S40: Hot Follow Up | T40: Rigtig godt lead, men ville gerne tjene lidt flere penge før han var klar
B41: 45812 | C41: malthe | E41: 22102612 | F41: malthehj__ | H41: Setter | I41: Offer & Didn't Buy | N41: Money | O41: han var klar | S41: X | T41: Han var klar og sagde han ville betale efter kaldet, efter kaldet skriver han at hans mor sagde nej selvom han er 18 år gammel
...

Sheet May
B1: Rep: | C1: Name | E1: Outcome | H1: KPIs% | K1: Show Rate | N1: Objections | Q1: Source | U1: Tracking
E2: Full-Pay: | F2: =IFERROR(COUNTIFS(I13:I287, "Full-Pay"),"") -> 4 | H2: Conversion Rate: | I2: =iferror(I10/I8,"") -> 0.47252747 | K2: Rescheduling Rate: | L2: =iferror(F8/I6,"") -> 0 | N2: Think About It | O2: =IFERROR(COUNTIFS(N13:N286, "think about it"),"") -> 10 | Q2: Reschedule | R2: =IFERROR(COUNTIF(H13:H286,Q2),"") -> 0 | S2: Cold Call | T2: =IFERROR(COUNTIF(H13:H286,S2),"") -> 0
B3: Revenue | C3: =IFERROR(SUM(K13:K283),"") -> 315000 | E3: Split-Pay: | F3: =IFERROR(COUNTIFS(I13:I287, "Split-Pay"),"") -> 39 | H3: Offer To Close Rate: | I3: =IFERROR(I10/I9,"") -> 0.47252747 | K3: Cancellation Rate: | L3: =iferror(F9/I6,"") -> 0.045454545 | N3: Money | O3: =IFERROR(COUNTIFS(N13:N286, "money"),"") -> 26 | Q3: YouTube | R3: =IFERROR(COUNTIF(H13:H286,Q3),"") -> 0 | S3: Twitter | T3: =IFERROR(COUNTIF(H13:H286,S3),"") -> 0
B4: Cash | C4: =IFERROR(SUM(L13:L284),"") -> 130600 | E4: Deposits: | F4: =IFERROR(COUNTIFS(I13:I287, "Deposit"),"") -> 4 | H4: Call To Offer Rate: | I4: =IFERROR(I9/I8,"") -> 1 | K4: No-Shows Rate: | L4: =iferror(F10/I6,"") -> 0.12727273 | N4: Time | O4: =IFERROR(COUNTIFS(N13:N286, "time"),"") -> 2 | Q4: YouTube Ads | R4: =IFERROR(COUNTIF(H13:H286,Q4),"") -> 0 | S4: Skool | T4: =IFERROR(COUNTIF(H13:H286,S4),"") -> 0
E5: Offer & Didn't Buy: | F5: =IFERROR(COUNTIFS(I13:I287, "Offer & Didn't Buy"),"") -> 44 | H5: Drag Over Rate: | I5: =IFERROR(F7/(C6+F7+F8),"") -> 0 | K5: Drag Over Rate: | L5: =iferror(F7/I6,"") -> 0 | N5: Partner | O5: =IFERROR(COUNTIFS(N13:N286, "partner"),"") -> 2 | Q5: Email | R5: =IFERROR(COUNTIF(H13:H286,Q5),"") -> 0 | S5: Instagram | T5: =IFERROR(COUNTIF(H13:H286,S5),"") -> 0
B6: Total Calls : | C6: =IFERROR(SUM(F2:F6),"") -> 91 | E6: Bad Fit & No Offer: | F6: =IFERROR(COUNTIFS(I13:I287, "Bad Fit & No Offer"),"") -> 0 | H6: Bookings: | I6: =IFERROR(SUM(F2:F10),"") -> 110 | K6: Show-Up Rate: | L6: =iferror(I7/I6,"") -> 0.82727273 | N6: Fear | O6: =IFERROR(COUNTIFS(N13:N286, "fear"),"") -> 2 | Q6: Facebook | R6: =IFERROR(COUNTIF(H13:H286,Q6),"") -> 0 | S6: TikTok | T6: =IFERROR(COUNTIF(H13:H286,S6),"") -> 0
B7: Total Won : | C7: =IFERROR(F2+F3,"") -> 43 | E7: Drag Over & Show: | F7: =IFERROR(COUNTIFS(I13:I287, "Drag Over & Show"),"") -> 0 | H7: Shows: | I7: =IFERROR(SUM(F2:F7),"") -> 91 | K7: Conducted Rate: | L7: =IFERROR(I8/I6,"") -> 0.82727273 | N7: Value | O7: =IFERROR(COUNTIFS(N14:N287, "value"),"") -> 0 | Q7: Facebook Ads | R7: =IFERROR(COUNTIF(H13:H286,Q7),"") -> 0 | S7: Google | T7: =IFERROR(COUNTIF(H13:H286,S7),"") -> 0
B8: Total Lost : | C8: =COUNTIF(I13:I286,"offer & didn't buy")+countif(I13:I286,"deposit")+countif(I13:I286,"bad fit & no offer") -> 48 | E8: Rescheduled: | F8: =IFERROR(COUNTIFS(I13:I287, "Rescheduled"),"") -> 0 | H8: Calls: | I8: =IFERROR(SUM(F2:F6),"") -> 91 | Q8: LinkedIn | R8: =IFERROR(COUNTIF(H13:H286,Q8),"") -> 0 | S8: Referral | T8: Referral
B9: Closing % : | C9: =iferror(SUM(C7/C6),"") -> 0.47252747 | E9: Cancelled: | F9: =IFERROR(COUNTIFS(I13:I287, "Cancelled"),"") -> 5 | H9: Offers: | I9: =IFERROR(sum(F2:F5),"") -> 91
C10: =C3/C6 -> 3461.5385 | E10: No-Show: | F10: =IFERROR(COUNTIFS(I13:I287, "No-Show"),"") -> 14 | H10: Deals | I10: =F2+F3 -> 43
B12: Date | C12: Name | E12: Phone No. | F12: IG-handle | H12: Source | I12: Outcome | K12: Revenue | L12: Cash | N12: Objection | O12: Objection Notes | Q12: Length | R12: Recording Link | S12: Follow Up/Next Steps | T12: Call Summary
B13: 45662 | C13: Rune | E13: 29 91 97 07 | H13: Setter | I13: Split-Pay | K13: 8700 | L13: 2700 | Q13: 6 mdr | S13: Closed
B14: 45662 | C14: Marcus Poulsen | E14: 53 70 41 15 | F14: Marcus Poulsen | H14: Setter | I14: Split-Pay | K14: 8700 | L14: 2700 | Q14: 6 mdr | S14: Closed
B15: 45662 | C15: Mikkel touvdal | E15: 71 78 98 52 | F15: Mikkel touvdal | H15: Setter | I15: Split-Pay | K15: 8700 | L15: 2700 | Q15: 6 mdr | S15: Closed
B16: 45662 | C16: Christian | E16: 50 39 78 05 | F16: Christian Veselinovski | H16: Setter | I16: Split-Pay | K16: 5500 | L16: 2500 | Q16: 4 mdr | S16: Closed
B17: 45662 | C17: Benjamin | E17: 28 51 68 13 | F17: Benjaminnymann0 | H17: Setter | I17: Split-Pay | K17: 8700 | L17: 2700 | Q17: 6 mdr | S17: Closed | T17: Ingen deposit da manden var på farten, men han betaler 1500 d 1 og 1200 hver måned
B18: 45662 | C18: Valdemar Drejer hansen | E18: 42 72 12 78 | F18: Valdemar Drejer hansen | H18: Setter | I18: Deposit | L18: 100 | Q18: 6 mdr | S18: Closed
B19: 45662 | C19: Jonas Clausen | E19: 61 30 82 12 | F19: Jonas Clausen | H19: Setter | I19: Split-Pay | K19: 5100 | L19: 2700 | Q19: 3 mdr | S19: Closed
B20: 45662 | C20: Marcus | E20: 42 78 43 25 | F20: Marcushff | H20: Setter | I20: Offer & Didn't Buy | N20: Money | O20: penge | S20: Hot Follow Up | T20: han var i bund og grund klar, vi havde sat deposit op, men han hoppede fra. så han skal følges op på lønningsdag
B21: 45662 | C21: Jay | E21: 22 27 04 20 | F21: Jayegbach | H21: Setter | I21: Split-Pay | K21: 8700 | L21: 2700 | Q21: 6 mdr | S21: Closed
B22: 45662 | C22: Elias Busk Hansen | E22: 50 66 39 31 | F22: Elias Busk Hansen | H22: Setter | I22: Offer & Didn't Buy | N22: Money | O22: Money | S22: Follow Up | T22: Han er fin at følge op på, men penge holdte ham tilbage
B23: 45662 | C23: Christian Laursen | E23: 31 39 48 18 | F23: Christian Laursen | H23: Setter | I23: Split-Pay | K23: 8700 | L23: 2700 | Q23: 6 mdr | S23: Closed
B24: 45662 | C24: Stubbe | E24: 42 16 64 76 | F24: stubbe_junior | H24: Setter | I24: Split-Pay | K24: 6300 | L24: 2700 | Q24: 4 mdr | S24: Closed
B25: 45662 | C25: Robert rankeberg | E25: 24 21 00 94 | F25: Robert rankeberg | H25: Setter | I25: Split-Pay | K25: 6300 | L25: 2700 | Q25: 4 mdr | S25: Closed
B26: 45662 | C26: Sebastian pedersen | E26: 42 25 01 01 | F26: Sebastian pedersen | H26: Setter | I26: No-Show
B27: 45693 | C27: Mikkel | E27: 20 43 74 48 | F27: mikkel234s | H27: Setter | I27: Offer & Didn't Buy | N27: Partner | O27: Han skulle snakke med fruen | S27: Hot Follow Up | T27: Skal snakke med ham igen imorgen!
B28: 45693 | C28: Faik | E28: 71 49 17 44 | F28: Faik_1206 | H28: Setter | I28: Split-Pay | K28: 8700 | L28: 2700 | Q28: 6 mdr | S28: Closed
B29: 45693 | C29: Jeppe | E29: 28 18 80 17 | F29: Jeppe S. Nymark | H29: Setter | I29: Split-Pay | K29: 5100 | L29: 2700 | Q29: 3 mdr | S29: Closed
B30: 45693 | C30: Jannick | E30: 50 42 52 26 | F30: Jannickhalme | H30: Setter | I30: Offer & Didn't Buy | N30: Money | O30: Penge | S30: Hot Follow Up | T30: Han var super frisk, men han havde for høje omkostninger
B31: 45693 | C31: Mikkel | E31: 52 81 55 82 | F31: M.hc2620 | H31: Setter | I31: Deposit | Q31: 3 mdr | S31: Deposit (Follow Up Set) | T31: Han betaler og starter d 1 juni
B32: 45693 | C32: Oliver | E32: 22 82 12 57 | F32: oli13106 | H32: Setter | I32: Split-Pay | K32: 5100 | L32: 2700 | Q32: 3 mdr | S32: Closed
B33: 45693 | C33: John | E33: 53 89 25 26 | F33: johnsarfo04 | H33: Setter | I33: Split-Pay | K33: 8700 | L33: 2700 | Q33: 6 mdr | S33: Closed
B34: 45693 | C34: Jacob | E34: 30 38 60 35 | F34: _jacob_olsen | H34: Setter | I34: Full-Pay | K34: 7200 | L34: 7200 | Q34: 6 mdr | S34: Closed
B35: 45721 | C35: Emil Jægershof Rudbeck | E35: 25 70 00 74 | F35: Emil Jægershof Rudbeck | H35: Setter | I35: Offer & Didn't Buy | N35: Money | O35: Penge | S35: Follow Up | T35: Han havde et fuldtids arbejde, boede ude og havde en del omkostninger, så han synes at prisen ikke lige passede ind, men ellers var han super varm!
B36: 45721 | C36: Frederik mogensen | E36: 61 73 14 95 | F36: Frederik mogensen | H36: Setter | I36: Offer & Didn't Buy | N36: Think About It | O36: tænke over det | S36: Follow Up | T36: han lød super frisk, men lige da vi kom til prisen, så begyndte han at lagge, sagde han skulle give mig svar tilbage 30 min efter kaldet og vi hørte aldrig fra ham igen
B37: 45721 | C37: Frederik | E37: 25 98 05 98 | F37: frederik_norre_henriksen | H37: Setter | I37: No-Show | O37: Adam blokere
B38: 45721 | C38: Lucas Sørensen | E38: 42 64 43 17 | F38: Lucas Sørensen | H38: Setter | I38: Split-Pay | K38: 5400 | L38: 2800 | Q38: 3 mdr | S38: Closed
B39: 45721 | C39: Niklas | E39: 21 32 83 73 | F39: 21 32 83 73 | H39: Setter | I39: Offer & Didn't Buy | N39: Think About It | O39: Han havde ikke penge til det | S39: Follow Up | T39: Han var 17 år gammel og var super klar til at starte op. Lige da vi kommer til betalingen, så laggede han. tror det var fordi han troede det var 1500kr første måned og ikke 2800kr
B40: 45721 | C40: Samuel | E40: 81 61 45 28 | F40: Samuel_hanning | H40: Setter | I40: Split-Pay | K40: 5400 | L40: 2800 | Q40: 3 mdr | S40: Closed
B41: 45752 | C41: Sefa | E41: 42 76 15 68 | F41: Sefo_bdk | H41: Setter | I41: Split-Pay | K41: 8700 | L41: 2700 | Q41: 6 mdr | S41: Closed
...

Sheet Jun
B1: Rep: | C1: Name | E1: Outcome | H1: KPIs% | K1: Show Rate | N1: Objections | Q1: Source | U1: Tracking
E2: Full-Pay: | F2: =IFERROR(COUNTIFS(I13:I288, "Full-Pay"),"") -> 14 | H2: Conversion Rate: | I2: =iferror(I10/I8,"") -> 0.34259259 | K2: Rescheduling Rate: | L2: =iferror(F8/I6,"") -> 0.075342466 | N2: Think About It | O2: =IFERROR(COUNTIFS(N13:N287, "think about it"),"") -> 17 | Q2: Reschedule | R2: =IFERROR(COUNTIF(H13:H287,Q2),"") -> 0 | S2: Cold Call | T2: =IFERROR(COUNTIF(H13:H287,S2),"") -> 0
B3: Revenue | C3: =IFERROR(SUM(K13:K284),"") -> 289200 | E3: Split-Pay: | F3: =IFERROR(COUNTIFS(I13:I288, "Split-Pay"),"") -> 23 | H3: Offer To Close Rate: | I3: =IFERROR(I10/I9,"") -> 0.34579439 | K3: Cancellation Rate: | L3: =iferror(F9/I6,"") -> 0.02739726 | N3: Money | O3: =IFERROR(COUNTIFS(N13:N287, "money"),"") -> 31 | Q3: YouTube | R3: =IFERROR(COUNTIF(H13:H287,Q3),"") -> 0 | S3: Twitter | T3: =IFERROR(COUNTIF(H13:H287,S3),"") -> 0
B4: Cash | C4: =IFERROR(SUM(L13:L285),"") -> 162400 | E4: Deposits: | F4: =IFERROR(COUNTIFS(I13:I288, "Deposit"),"") -> 9 | H4: Call To Offer Rate: | I4: =IFERROR(I9/I8,"") -> 0.99074074 | K4: No-Shows Rate: | L4: =iferror(F10/I6,"") -> 0.15753425 | N4: Time | O4: =IFERROR(COUNTIFS(N13:N287, "time"),"") -> 6 | Q4: YouTube Ads | R4: =IFERROR(COUNTIF(H13:H287,Q4),"") -> 0 | S4: Skool | T4: =IFERROR(COUNTIF(H13:H287,S4),"") -> 0
E5: Offer & Didn't Buy: | F5: =IFERROR(COUNTIFS(I13:I288, "Offer & Didn't Buy"),"") -> 61 | H5: Drag Over Rate: | I5: =IFERROR(F7/(C6+F7+F8),"") -> 0 | K5: Drag Over Rate: | L5: =iferror(F7/I6,"") -> 0 | N5: Partner | O5: =IFERROR(COUNTIFS(N13:N287, "partner"),"") -> 0 | Q5: Email | R5: =IFERROR(COUNTIF(H13:H287,Q5),"") -> 0 | S5: Instagram | T5: =IFERROR(COUNTIF(H13:H287,S5),"") -> 0
B6: Total Calls : | C6: =IFERROR(SUM(F2:F6),"") -> 108 | E6: Bad Fit & No Offer: | F6: =IFERROR(COUNTIFS(I13:I288, "Bad Fit & No Offer"),"") -> 1 | H6: Bookings: | I6: =IFERROR(SUM(F2:F10),"") -> 146 | K6: Show-Up Rate: | L6: =iferror(I7/I6,"") -> 0.73972603 | N6: Fear | O6: =IFERROR(COUNTIFS(N13:N287, "fear"),"") -> 6 | Q6: Facebook | R6: =IFERROR(COUNTIF(H13:H287,Q6),"") -> 0 | S6: TikTok | T6: =IFERROR(COUNTIF(H13:H287,S6),"") -> 0
B7: Total Won : | C7: =IFERROR(F2+F3,"") -> 37 | E7: Drag Over & Show: | F7: =IFERROR(COUNTIFS(I13:I288, "Drag Over & Show"),"") -> 0 | H7: Shows: | I7: =IFERROR(SUM(F2:F7),"") -> 108 | K7: Conducted Rate: | L7: =IFERROR(I8/I6,"") -> 0.73972603 | N7: Value | O7: =IFERROR(COUNTIFS(N14:N288, "value"),"") -> 0 | Q7: Facebook Ads | R7: =IFERROR(COUNTIF(H13:H287,Q7),"") -> 0 | S7: Google | T7: =IFERROR(COUNTIF(H13:H287,S7),"") -> 0
B8: Total Lost : | C8: =COUNTIF(I13:I287,"offer & didn't buy")+countif(I13:I287,"deposit")+countif(I13:I287,"bad fit & no offer") -> 71 | E8: Rescheduled: | F8: =IFERROR(COUNTIFS(I13:I288, "Rescheduled"),"") -> 11 | H8: Calls: | I8: =IFERROR(SUM(F2:F6),"") -> 108 | Q8: LinkedIn | R8: =IFERROR(COUNTIF(H13:H287,Q8),"") -> 0 | S8: Referral | T8: =IFERROR(COUNTIF(H13:H287,S8),"") -> 0
B9: Closing % : | C9: =iferror(SUM(C7/C6),"") -> 0.34259259 | E9: Cancelled: | F9: =IFERROR(COUNTIFS(I13:I288, "Cancelled"),"") -> 4 | H9: Offers: | I9: =IFERROR(sum(F2:F5),"") -> 107
C10: =C3/C6 -> 2677.7778 | E10: No-Show: | F10: =IFERROR(COUNTIFS(I13:I288, "No-Show"),"") -> 23 | H10: Deals | I10: =F2+F3 -> 37
B12: Date | C12: Name | E12: Phone No. | F12: Email | H12: Source | I12: Outcome | K12: Revenue | L12: Cash | N12: Objection | O12: Objection Notes | Q12: Length | R12: Recording Link | S12: Follow Up/Next Steps | T12: Call Summary
B13: 45663 | C13: Michael | E13: 53 50 02 29 | F13: Michaelchristiansen87 | H13: Setter | I13: Split-Pay | K13: 8700 | L13: 2700 | Q13: 6 mdr | S13: Closed | T13: starter og betaler d 1 juni
B14: 45663 | C14: Jonas | E14: 51 36 91 61 | F14: Jonas_skov09 | H14: Setter | I14: Split-Pay | K14: 8700 | L14: 2700 | Q14: 6 mdr | S14: Closed | T14: starter og betaler d 1 juni
B15: 45663 | C15: Mikkel | E15: 52 81 55 82 | F15: M.hc2620 | H15: Setter | I15: Split-Pay | K15: 5100 | L15: 2700 | Q15: 3 mdr | S15: Closed | T15: Han betaler og starter d 1 juni
B16: 45662 | C16: Valdemar Drejer hansen | E16: 42 72 12 78 | F16: Valdemar Drejer hansen | H16: Setter | I16: Deposit | L16: 100 | Q16: 6 mdr | S16: Closed | T16: mangler stadig betaling fra ham
B17: 45663 | C17: Jimmi Pedersen | E17: 29834939 | F17: jimmip1987 | H17: Setter | I17: Split-Pay | K17: 8700 | L17: 2700 | Q17: 6 mdr | S17: Closed | T17: Han starter d 1 juni
B18: 45663 | C18: Maddy | E18: 22 20 06 80 | F18: Kongen_Maddy | H18: Setter | I18: No-Show
B19: 45694 | C19: Adib | E19: 50 51 95 58 | F19: Adib_aa1912 | H19: Setter | I19: Full-Pay | K19: 7200 | L19: 7200 | Q19: 6 mdr | S19: Closed
B20: 45694 | C20: Ademir | E20: 22 71 77 05 | F20: Aboosabanoovic | H20: Setter | I20: Offer & Didn't Buy | N20: Think About It | O20: Økonomien | S20: Follow Up | T20: ældre mand, fuldtidsarbejde, fodbold træner og havde meget travlt, han ville tænke over det for at finde ud af om det gav mening for ham
B21: 45694 | C21: Blerand | E21: 50 70 13 41 | F21: Bleroo_h | H21: Setter | I21: Full-Pay | K21: 7200 | L21: 7200 | Q21: 6 mdr | S21: Closed
B22: 45694 | C22: Mikkel | E22: 42 91 62 43 | F22: Frandsennn | H22: Setter | I22: Offer & Didn't Buy | N22: Money | O22: Penge | S22: X | T22: ung fyr som ikke havde pengene til det, men han var super varm!
B23: 45694 | C23: Magnus | E23: 27 15 55 06 | F23: Magnus.022 | H23: Setter | I23: No-Show
B24: 45694 | C24: Oscar | E24: 42 37 70 13 | F24: Oscarbundgaard4 | H24: Setter | I24: Split-Pay | K24: 6300 | L24: 2700 | Q24: 6 mdr | S24: Closed
B25: 45722 | C25: Kasper | E25: 42 43 53 66 | F25: Kasperbg22 | H25: Setter | I25: Split-Pay | K25: 5100 | L25: 2700 | Q25: 3 mdr | S25: Closed
B26: 45722 | C26: Milan | E26: 28 12 28 09 | F26: Milan_ban | H26: Setter | I26: Offer & Didn't Buy | N26: Think About It | S26: Follow Up | T26: ældre herre, fuldtidsarbejde, ville gerne tabe sig og stå skarpt, men han havde ikke besluttet sig, så han ville tænke over det
B27: 45722 | C27: Mikkel | E27: 60 56 59 26 | F27: Mikkel.dencker | H27: Setter | I27: No-Show
B28: 45722 | C28: Noah | E28: 50 11 64 65 | F28: Noahstreett | H28: Setter | I28: Offer & Didn't Buy | N28: Money | O28: Penge | S28: Hot Follow Up | T28: Han var vold klar lige indtil han fandt ud af at det var 1500+1200 første måned, så han skal kontaktes igen og give ham noget tilbud på opstart
B29: 45753 | C29: Frederik | E29: 50 71 00 09 | F29: Frederik_damsgaard_ | H29: Setter | I29: Offer & Didn't Buy | N29: Money | O29: penge | S29: Follow Up | T29: Han havde ikke pengene til det. en average gym dreng som arbejdede i ny og næ
B30: 45753 | C30: Linus | E30: 61 41 58 45 | F30: Linus_leffler | H30: Setter | I30: Offer & Didn't Buy | N30: Time | O30: han skulle på højskole | S30: Follow Up | T30: Han var fkn ready, men han skulle på højskole så han er klar til dec senere i år
B31: 45783 | C31: Mads | E31: 31 15 04 52 | F31: Madsdragsbaek | H31: Setter | I31: Offer & Didn't Buy | N31: Money | O31: Penge | S31: Follow Up | T31: Han var totalt klar, men pengene var ikke til det lige nu. han skrev at havde det været 700-800, så havde han været klar nu
B32: 45814 | C32: Gustav Poulsen | E32: 22 22 08 73 | F32: Gustav Poulsen | H32: Setter | I32: Offer & Didn't Buy | N32: Think About It | O32: penge | S32: X | T32: Han havde slet ikke penge til det, men han lød super varm
B33: 45814 | C33: Jonas | E33: 42 83 54 48 | F33: Jonas.Kyndesen | H33: Setter | I33: Offer & Didn't Buy | N33: Think About It | O33: Ikke comittet | S33: X | T33: Han var slet ikke comittet og virkede totalt træls på en måde
B34: 45814 | C34: Sebastian | E34: 53386494 | F34: Sebastianhalsted | H34: Setter | I34: Offer & Didn't Buy | N34: Money | O34: penge | S34: Follow Up | T34: 17 år, får arbejde d 1 august, så der skal han kontaktes igen, da han lige nu kun går på skole og rigtig varm gut
B35: 45814 | C35: Noah | E35: 30 31 72 07 | F35: Noah_toft | H35: Setter | I35: Split-Pay | K35: 8700 | L35: 2700 | Q35: 6 mdr | S35: Closed
B36: 45814 | C36: Simon | E36: 71 72 98 36 | F36: Simon_nordbylino | H36: Setter | I36: Deposit | Q36: 6 mdr | S36: Deposit (Follow Up Set) | T36: starter op d 5 august
B37: 45814 | C37: Artan | E37: 42 83 74 78 | F37: Artan_rmz | H37: Setter | I37: Offer & Didn't Buy | N37: Time | S37: X | T37: Meget spøjs gut
B38: 45814 | C38: Kenneth | E38: 22 54 10 67 | F38: silva.beatbox | H38: Setter | I38: Full-Pay | K38: 7200 | L38: 7200 | Q38: 6 mdr | S38: Closed
B39: 45814 | C39: Lucas | E39: 50 25 93 38 | F39: lucas_fussing | H39: Setter | I39: Full-Pay | K39: 7200 | L39: 7200 | Q39: 6 mdr | S39: Closed
B40: 45844 | C40: Aleksander | E40: 53 85 13 07 | F40: Aleksander.kamp | H40: Setter | I40: Full-Pay | K40: 7200 | L40: 7200 | Q40: 6 mdr | S40: Closed
B41: 45844 | C41: Bertram | E41: 30 27 51 55 | F41: Bertramlindrasmussen | H41: Setter | I41: Offer & Didn't Buy | N41: Think About It | O41: tænke over det | S41: Hot Follow Up | T41: Han var vold varm, tømre, men skulle lige hjem og tjekke det hele igennem og så ville han give svar!
...

Sheet Jul
B1: Rep: | C1: Name | E1: Outcome | H1: KPIs% | K1: Show Rate | N1: Objections | Q1: Source | U1: Tracking
E2: Full-Pay: | F2: =IFERROR(COUNTIFS(I13:I287, "Full-Pay"),"") -> 10 | H2: Conversion Rate: | I2: =iferror(I10/I8,"") -> 0.37234043 | K2: Rescheduling Rate: | L2: =iferror(F8/I6,"") -> 0.085714286 | N2: Think About It | O2: =IFERROR(COUNTIFS(N13:N286, "think about it"),"") -> 6 | Q2: Reschedule | R2: =IFERROR(COUNTIF(H13:H286,Q2),"") -> 0 | S2: Cold Call | T2: =IFERROR(COUNTIF(H13:H286,S2),"") -> 0
B3: Revenue | C3: =IFERROR(SUM(K13:K283),"") -> 318600 | E3: Split-Pay: | F3: =IFERROR(COUNTIFS(I13:I287, "Split-Pay"),"") -> 25 | H3: Offer To Close Rate: | I3: =IFERROR(I10/I9,"") -> 0.37634409 | K3: Cancellation Rate: | L3: =iferror(F9/I6,"") -> 0.071428571 | N3: Money | O3: =IFERROR(COUNTIFS(N13:N286, "money"),"") -> 23 | Q3: YouTube | R3: =IFERROR(COUNTIF(H13:H286,Q3),"") -> 0 | S3: Twitter | T3: =IFERROR(COUNTIF(H13:H286,S3),"") -> 0
B4: Cash | C4: =IFERROR(SUM(L13:L284),"") -> 156900 | E4: Deposits: | F4: =IFERROR(COUNTIFS(I13:I287, "Deposit"),"") -> 16 | H4: Call To Offer Rate: | I4: =IFERROR(I9/I8,"") -> 0.9893617 | K4: No-Shows Rate: | L4: =iferror(F10/I6,"") -> 0.17142857 | N4: Time | O4: =IFERROR(COUNTIFS(N13:N286, "time"),"") -> 7 | Q4: YouTube Ads | R4: =IFERROR(COUNTIF(H13:H286,Q4),"") -> 0 | S4: Skool | T4: =IFERROR(COUNTIF(H13:H286,S4),"") -> 0
E5: Offer & Didn't Buy: | F5: =IFERROR(COUNTIFS(I13:I287, "Offer & Didn't Buy"),"") -> 42 | H5: Drag Over Rate: | I5: =IFERROR(F7/(C6+F7+F8),"") -> 0 | K5: Drag Over Rate: | L5: =iferror(F7/I6,"") -> 0 | N5: Partner | O5: =IFERROR(COUNTIFS(N13:N286, "partner"),"") -> 3 | Q5: Email | R5: =IFERROR(COUNTIF(H13:H286,Q5),"") -> 0 | S5: Instagram | T5: =IFERROR(COUNTIF(H13:H286,S5),"") -> 0
B6: Total Calls : | C6: =IFERROR(SUM(F2:F6),"") -> 94 | E6: Bad Fit & No Offer: | F6: =IFERROR(COUNTIFS(I13:I287, "Bad Fit & No Offer"),"") -> 1 | H6: Bookings: | I6: =IFERROR(SUM(F2:F10),"") -> 140 | K6: Show-Up Rate: | L6: =iferror(I7/I6,"") -> 0.67142857 | N6: Fear | O6: =IFERROR(COUNTIFS(N13:N286, "fear"),"") -> 3 | Q6: Facebook | R6: =IFERROR(COUNTIF(H13:H286,Q6),"") -> 0 | S6: TikTok | T6: =IFERROR(COUNTIF(H13:H286,S6),"") -> 0
B7: Total Won : | C7: =IFERROR(F2+F3,"") -> 35 | E7: Drag Over & Show: | F7: =IFERROR(COUNTIFS(I13:I287, "Drag Over & Show"),"") -> 0 | H7: Shows: | I7: =IFERROR(SUM(F2:F7),"") -> 94 | K7: Conducted Rate: | L7: =IFERROR(I8/I6,"") -> 0.67142857 | N7: Value | O7: =IFERROR(COUNTIFS(N14:N287, "value"),"") -> 0 | Q7: Facebook Ads | R7: =IFERROR(COUNTIF(H13:H286,Q7),"") -> 0 | S7: Google | T7: =IFERROR(COUNTIF(H13:H286,S7),"") -> 0
B8: Total Lost : | C8: =COUNTIF(I13:I286,"offer & didn't buy")+countif(I13:I286,"deposit")+countif(I13:I286,"bad fit & no offer") -> 59 | E8: Rescheduled: | F8: =IFERROR(COUNTIFS(I13:I287, "Rescheduled"),"") -> 12 | H8: Calls: | I8: =IFERROR(SUM(F2:F6),"") -> 94 | Q8: LinkedIn | R8: =IFERROR(COUNTIF(H13:H286,Q8),"") -> 0 | S8: Referral | T8: =IFERROR(COUNTIF(H13:H286,S8),"") -> 0
B9: Closing % : | C9: =iferror(SUM(C7/C6),"") -> 0.37234043 | E9: Cancelled: | F9: =IFERROR(COUNTIFS(I13:I287, "Cancelled"),"") -> 10 | H9: Offers: | I9: =IFERROR(sum(F2:F5),"") -> 93
C10: =C3/C6 -> 3389.3617 | E10: No-Show: | F10: =IFERROR(COUNTIFS(I13:I287, "No-Show"),"") -> 24 | H10: Deals | I10: =F2+F3 -> 35
B12: Date | C12: Name | E12: Phone No. | F12: Email | H12: Source | I12: Outcome | K12: Revenue | L12: Cash | N12: Objection | O12: Objection Notes | Q12: Length | R12: Recording Link | S12: Follow Up/Next Steps | T12: Call Summary
C13: Valdemar Drejer hansen | E13: 42 72 12 78 | F13: Valdemar Drejer hansen | H13: Setter | I13: Deposit | L13: 100 | Q13: 6 mdr | S13: Deposit (Follow Up Set) | T13: mangler stadig betaling fra ham
B14: 45664 | C14: Simon | E14: 71 72 98 36 | F14: Simon_nordbylino | H14: Setter | I14: Deposit | Q14: 6 mdr | S14: Deposit (Follow Up Set) | T14: starter op d 20 august
B15: 45664 | C15: Mick | E15: 42 66 41 68 | F15: Mickriis | H15: Setter | I15: Split-Pay | K15: 8700 | L15: 2700 | Q15: 6 mdr | S15: Closed | T15: Starter og betaler d 1 juli
B16: 45664 | C16: Emil | E16: 54 34 67 32 | F16: Emil Munch | H16: Setter | I16: Split-Pay | K16: 8700 | L16: 2700 | Q16: 6 mdr | S16: Closed | T16: starter og betaler d 1 juli | V16: parveenparshant@yahoo.com
B17: 45664 | C17: Oliver | E17: 42 32 00 70 | F17: Oliver_Thyregod | H17: Setter | I17: Split-Pay | K17: 8700 | L17: 2700 | Q17: 6 mdr | S17: Closed | T17: Starter d 7 juli og betaler d 1
B18: 45664 | C18: Oliver | E18: 50 57 73 43 | F18: oliversarto | H18: Setter | I18: Deposit | Q18: 6 mdr | S18: Deposit (Follow Up Set) | T18: starter og betaler d 1 august
B19: 45664 | C19: Kaspar | E19: 28 18 36 14 | F19: Kaspar_privat9 | H19: Setter | I19: Deposit | Q19: 6 mdr | S19: Deposit (Follow Up Set) | T19: starter og betaler d 1 august
B20: 45664 | C20: Thomas | E20: 41 27 20 30 | F20: Thomas_hampen_andersen | H20: Setter | I20: Split-Pay | K20: 10500 | L20: 3000 | Q20: 6 mdr | S20: Closed
B21: 45664 | C21: Mathias | E21: 28 51 05 94 | F21: Mathiashvid12 | H21: Setter | I21: Offer & Didn't Buy | N21: Time | S21: Hot Follow Up | T21: vold varmt lead som gerne ville stå skarpt til hans bryllup hvor ham og hans kone gerne ville blive coachet sammen og de var begge klar på at betale 9kx2 upfront, men han var først klar i det nye år hvilket er træls!
B22: 45695 | C22: Kristian | E22: 50 15 03 56 | F22: Kristiandrechsler | H22: Setter | I22: Deposit | Q22: 6 mdr | S22: Deposit (Follow Up Set) | T22: Starter og betaler d 1 august!
B23: 45695 | C23: Phillip | E23: 29 68 20 12 | F23: Phillipolsen1 | H23: Setter | I23: Split-Pay | K23: 10500 | L23: 3000 | Q23: 6 mdr | S23: Closed
B24: 45723 | C24: Lucca | E24: 60 48 53 55 | F24: lucca_Breck | H24: Setter | I24: No-Show
B25: 45723 | C25: Oliver | E25: 60 48 47 15 | F25: Oliverhallsvensson | H25: Setter | I25: Offer & Didn't Buy | N25: Money | O25: Penge | S25: Hot Follow Up | T25: rigtig godt lead som gerne ville komme i bedre form, men lige gav det ikke mening penge mæssigt, men han var ready så snart der var styr på det hele!
B26: 45723 | C26: phillip | E26: 50 15 03 56 | F26: Phillip_gre_gersen | H26: Setter | I26: Cancelled
B27: 45723 | C27: Nikolai | E27: 29 39 13 98 | F27: Nikolainissen_ | H27: Setter | I27: Cancelled
B28: 45723 | C28: Oliver | E28: 26 31 45 57 | F28: oliver_groening | H28: Setter | I28: Deposit | Q28: 6 mdr | S28: Deposit (Follow Up Set) | T28: starter og betaler d 11 august
B29: 45723 | C29: Thomas | E29: 42 78 67 47 | F29: Thomas.olsen9 | H29: Setter | I29: Split-Pay | K29: 10500 | L29: 3000 | Q29: 6 mdr | S29: Closed
B30: 45723 | C30: Mads | E30: 22 28 71 45 | F30: Madsryttergaardjacobsen | H30: Setter | I30: Offer & Didn't Buy | N30: Time | S30: Hot Follow Up | T30: varmt lead som gerne ville i bedre form. Han vidste godt det ikke var mange penge, men han ville hellere skrive tilbage efter sommeren
B31: 45754 | C31: Lasse | E31: 434 595 517 | F31: Lasdalgaard | H31: Setter | I31: Full-Pay | K31: 9000 | L31: 9000 | Q31: 6 mdr | S31: Closed
B32: 45754 | C32: Dominik | E32: 25 77 80 77 | F32: domcapik | H32: Setter | I32: Offer & Didn't Buy | N32: Money | O32: Penge | S32: Hot Follow Up | T32: varmeste lead som ikke ture at tage springet. han ville gerne tabe sig og stå skarpere. snakkede med ham i 30 min kunne mærke han var klar til at købe, men han kunne bare ikke tage springet
B33: 45754 | C33: Malthe | E33: 23 92 28 08 | F33: malt2662 | H33: Setter | I33: Split-Pay | K33: 10500 | L33: 3000 | Q33: 6 mdr | S33: Closed
B34: 45754 | C34: Mike | E34: 91 99 20 43 | F34: ekelundmike | H34: Setter | I34: No-Show
B35: 45754 | C35: Nicolas | E35: 28 71 73 16 | F35: nicolas_iordanov | H35: Setter | I35: Offer & Didn't Buy | N35: Money | O35: penge | S35: Hot Follow Up | T35: rigtig varmt lead, men pengene var ikke store da han ikke tjente udlærte penge endnu, så han ville skrive når han var ready
B36: 45754 | C36: Victor | E36: 29 71 80 09 | F36: Schwarz0106 | H36: Setter | I36: Split-Pay | K36: 10500 | L36: 3000 | Q36: 6 mdr | S36: Closed
B37: 45815 | C37: Sander | E37: 53 83 80 71 | F37: sander_dam00 | H37: Setter | I37: Offer & Didn't Buy | N37: Money | O37: Penge | S37: Follow Up | T37: han ville gerne igang og bygge mere muskelmasse op, men han var ikke klar til at investere det i forløbet
B38: 45815 | C38: Gustav | E38: 30 23 05 92 | F38: gustavhansen48 | H38: Setter | I38: Cancelled
B39: 45815 | C39: Matin | E39: 91 97 16 68 | F39: Matin.assadi_ | H39: Setter | I39: Offer & Didn't Buy | N39: Money | O39: Penge | S39: Hot Follow Up | T39: Han var så klar og vi nåede endda også at lave en binding, men så skrev han dagen efter at det ikke passede så godt, fordi han havde en masse regninger
B40: 45815 | C40: Frey | E40: 42 15 17 44 | F40: freyager1 | H40: Setter | I40: Offer & Didn't Buy | N40: Money | O40: Penge | S40: Hot Follow Up | T40: Han var så klar og ville bare gerne give den gas og blive større, men han var ikke klar til at investere halvdelen af hans løn hver måned på det
B41: 45845 | C41: Gustav | E41: 60 84 44 20 | F41: gustav_lundgren13 | H41: Setter | I41: Cancelled
...

Sheet Aug
A1: $ | B1: Rep: | C1: Name | E1: Anton KPI's | H1: Outcome | K1: KPIs% | N1: Show Rate | Q1: Objections | T1: Source
E2: Rev per call | F2: =C3/C6 -> 3519.5876 | H2: Full-Pay: | I2: =IFERROR(COUNTIFS(I13:I311, "Full-Pay"),"") -> 14 | K2: Conversion Rate: | L2: =iferror(L10/L8,"") -> 0.39175258 | N2: Rescheduling Rate: | O2: =iferror(I8/L6,"") -> 0.0084033613 | Q2: Think About It | R2: =IFERROR(COUNTIFS(N35:N310, "think about it"),"") -> 10 | T2: Setter | U2: =IFERROR(COUNTIF(H16:H291,"setter"),"") -> 116
B3: Revenue | C3: =IFERROR(SUM(K13:K288),"") -> 341400 | E3: Cash per call | F3: =C4/C6 -> 1800 | H3: Split-Pay: | I3: =IFERROR(COUNTIFS(I13:I311, "Split-Pay"),"") -> 24 | K3: Offer To Close Rate: | L3: =IFERROR(L10/L9,"") -> 0.40425532 | N3: Cancellation Rate: | O3: =iferror(I9/L6,"") -> 0.050420168 | Q3: Money | R3: =IFERROR(COUNTIFS(N35:N310, "money"),"") -> 24 | T3: IG | U3: =IFERROR(COUNTIF(H16:H291,"IG"),"") -> 0
B4: Cash | C4: =IFERROR(SUM(L13:L289),"") -> 174600 | E4: Cash upfront % | F4: =C4/C3*100 -> 51.142355 | H4: Deposits: | I4: =IFERROR(COUNTIFS(I13:I311, "Deposit"),"") -> 11 | K4: Call To Offer Rate: | L4: =IFERROR(L9/L8,"") -> 0.96907216 | N4: No-Shows Rate: | O4: =iferror(I10/L6,"") -> 0.12605042 | Q4: Time | R4: =IFERROR(COUNTIFS(N35:N310, "time"),"") -> 3 | T4: YouTube | U4: =IFERROR(COUNTIF(H16:H291,"youtube"),"") -> 0
E5: PIF % | F5: =I2/C7*100 -> 36.842105 | H5: Offer & Didn't Buy: | I5: =IFERROR(COUNTIFS(I13:I311, "Offer & Didn't Buy"),"") -> 45 | K5: Drag Over Rate: | L5: =IFERROR(I7/(C6+I7+I8),"") -> 0 | N5: Drag Over Rate: | O5: =iferror(I7/L6,"") -> 0 | Q5: Partner | R5: =IFERROR(COUNTIFS(N35:N310, "partner"),"") -> 3 | T5: Email | U5: =IFERROR(COUNTIF(H16:H291,"email"),"") -> 0
B6: Total Calls : | C6: =IFERROR(SUM(I2:I6),"") -> 97 | E6: Average Binding | F6: =AVERAGE(Q13:Q104) -> 5.5263158 | H6: Bad Fit & No Offer: | I6: =IFERROR(COUNTIFS(I13:I311, "Bad Fit & No Offer"),"") -> 3 | K6: Bookings: | L6: =IFERROR(SUM(I2:I10),"") -> 119 | N6: Show-Up Rate: | O6: =iferror(L7/L6,"") -> 0.81512605 | Q6: Fear | R6: =IFERROR(COUNTIFS(N35:N310, "fear"),"") -> 1 | T6: Facebook | U6: =IFERROR(COUNTIF(H16:H291,"facebook"),"") -> 0
B7: Total Won : | C7: =IFERROR(I2+I3,"") -> 38 | E7: Average deal | F7: =C3/C7 -> 8984.2105 | H7: Drag Over & Show: | I7: =IFERROR(COUNTIFS(I13:I311, "Drag Over & Show"),"") -> 0 | K7: Shows: | L7: =IFERROR(SUM(I2:I7),"") -> 97 | N7: Conducted Rate: | O7: =IFERROR(L8/L6,"") -> 0.81512605 | Q7: Value | R7: =IFERROR(COUNTIFS(N36:N311, "value"),"") -> 0 | T7: Facebook Ads | U7: =IFERROR(COUNTIF(H16:H291,"facebook ads"),"") -> 0
B8: Total Lost : | C8: =COUNTIF(I13:I291,"offer & didn't buy")+COUNTIF(I16:I291,"deposit")+COUNTIF(I16:I291,"bad fit & no offer") -> 57 | E8: Average cash | F8: =C4/C7 -> 4594.7368 | H8: Rescheduled: | I8: =IFERROR(COUNTIFS(I13:I311, "Rescheduled"),"") -> 1 | K8: Calls: | L8: =IFERROR(SUM(I2:I6),"") -> 97 | T8: LinkedIn | U8: =IFERROR(COUNTIF(H16:H291,T8),"") -> 0
B9: Closing % : | C9: =iferror(SUM(C7/C6),"") -> 0.39175258 | H9: Cancelled: | I9: =IFERROR(COUNTIFS(I13:I311, "Cancelled"),"") -> 6 | K9: Offers: | L9: =IFERROR(sum(I2:I5),"") -> 94
C10: =C3/C6 -> 3519.5876 | H10: No-Show: | I10: =IFERROR(COUNTIFS(I13:I311, "No-Show"),"") -> 15 | K10: Deals | L10: =I2+I3 -> 38
B12: Date | C12: Name | E12: Phone No. | F12: IG Navn | H12: Source | I12: Outcome | K12: Revenue | L12: Cash | N12: Objection | O12: Objection Notes | Q12: Length | R12: Recording Link | S12: Follow Up/Next Steps | T12: Call Summary
B13: 45665 | C13: Valdemar Drejer hansen | E13: 42 72 12 78 | F13: Valdemar Drejer hansen | H13: Setter | I13: Split-Pay | K13: 8700 | L13: 2700 | Q13: 6 | S13: Closed | T13: Fik endelig betaling fra ham
B14: 45665 | C14: Simon | E14: 71 72 98 36 | F14: Simon_nordbylino | H14: Setter | I14: Deposit | Q14: 6 | S14: Deposit (Follow Up Set) | T14: starter op d 20 august
B15: 45665 | C15: Oliver | E15: 50 57 73 43 | F15: oliversarto | H15: Setter | I15: Deposit | Q15: 6 | S15: Deposit (Follow Up Set) | T15: starter og betaler d 31 august, selvom meningen var at vi startede d 1 august
B16: 45665 | C16: Kaspar | E16: 28 18 36 14 | F16: Kaspar_privat9 | H16: Setter | I16: No-Show | Q16: 6 | S16: Deposit (Follow Up Set) | T16: starter og betaler d 1 august (Han svarer ikke på mine beskeder)
B17: 45665 | C17: Kristian | E17: 50 15 03 56 | F17: Kristiandrechsler | H17: Setter | I17: Split-Pay | K17: 7700 | L17: 1700 | Q17: 6 | S17: Closed | T17: Starter og betaler d 1 august!
B18: 45665 | C18: Oliver | E18: 26 31 45 57 | F18: oliver_groening | H18: Setter | I18: Deposit | Q18: 6 | S18: Deposit (Follow Up Set) | T18: starter og betaler d 11 august
B19: 45665 | C19: Mads | E19: 29 13 40 54 | F19: _madsskov | H19: Setter | I19: Split-Pay | K19: 10500 | L19: 3000 | Q19: 6 | S19: Deposit (Follow Up Set) | T19: betaler 1 august og starter 1 sep (Venter svar fra ham)
B20: 45665 | C20: Laurits | E20: 22 56 74 16 | F20: laurits_viholt | H20: Setter | I20: Deposit | L20: 100 | Q20: 6 | S20: Deposit (Follow Up Set) | T20: starter og betaler d 1 august (bumsen har blokeret mig)
B21: 45665 | C21: William | E21: 52 17 82 58 | F21: william.kjellberg | H21: Setter | I21: Split-Pay | K21: 10500 | L21: 1500 | Q21: 6 | S21: Closed | T21: han starter d 1 august, men betalte for opstartsgebyr nu
B22: 45665 | C22: Bjarke | E22: 22 58 58 48 | F22: Bjarkewinther6 | H22: Setter | I22: Deposit | L22: 100 | S22: Deposit (Follow Up Set) | T22: starter og betaler d 31 juli (han har ikke råd, vi udskyder til 31 august istedet)
B23: 45665 | C23: Frederik | E23: 27 28 26 03 | F23: Frederikmolander | H23: Setter | I23: Split-Pay | K23: 10500 | L23: 2500 | Q23: 6 | S23: Closed | T23: Han betalte 500 sidste måned
B24: 45665 | C24: Max | E24: 23 11 86 23 | F24: max_thybo_ | H24: Setter | I24: Split-Pay | K24: 10500 | L24: 3000 | Q24: 6 | S24: Closed | T24: Han starter d 11 august og han betaler der
B25: 45665 | C25: Christian | E25: 26 33 05 88 | F25: christianhuus | H25: Setter | I25: Deposit | Q25: 6 | S25: Deposit (Follow Up Set) | T25: Han er klar 31 august og der betaler han
B26: 45665 | C26: Martin | E26: 31 95 58 15 | F26: Martin.daoudd | H26: Setter | I26: Full-Pay | K26: 4500 | L26: 4500 | Q26: 4 | S26: Closed
B27: 45665 | C27: Mads | E27: 53 63 09 43 | F27: madspc004 | H27: Setter | I27: Bad Fit & No Offer
B28: 45665 | C28: Axel | E28: 28 60 86 02 | F28: axelhauerslev | H28: Setter | I28: Offer & Didn't Buy | N28: Money | O28: Penge | S28: Follow Up | T28: Han var super nice, men han ville slet ikke smide pengene i det
B29: 45665 | C29: Jonas | E29: 23 86 09 52 | F29: brunduss | H29: Setter | I29: Offer & Didn't Buy | N29: Think About It | O29: tænke over det | S29: Follow Up | T29: fin fyr, men han ville gerne tænke over det!
