Workbook

Sheet Dashboard
A1: Sales tracking
A2: Key Metrics | B2: YTD | C2: January | D2: February | E2: March | F2: April | G2: May | H2: June | I2: July | J2: August | K2: September | L2: October | M2: November | N2: December | O2: SPARKLINES
A3: Conversion Rate: | B3: =iferror(B12/B10,"") | C3: =Jan!I2 -> #REF! | D3: =IFERROR(Feb!I2,"") | E3: =Mar!I2 -> #REF! | F3: =IFERROR(Template!I2,"") | G3: =IFERROR(May!I2,"") | H3: =IFERROR(Jun!I2,"") -> 0.32 | I3: =IFERROR(Jul!I2,"") -> 0.52941176 | J3: =IFERROR(Aug!I2,"") -> 0.4137931 | K3: =IFERROR(Sep!L2,"") -> 0.31147541 | L3: =IFERROR(Oct!I2,"") | M3: =IFERROR(Nov!I2,"") | N3: =IFERROR(Dec!I2,"") | O3: =IFERROR(__xludf.DUMMYFUNCTION("IFERROR(SPARKLINE(C3:N3, {""chartype"", ""line""; ""color"", ""blue""})) "),"")
A4: Offer To Close Rate: | B4: =iferror(B12/B11,"") | C4: =Jan!I3 -> #REF! | D4: =IFERROR(Feb!I3,"") | E4: =IFERROR(Mar!I3,"") | F4: =IFERROR(Template!I3,"") | G4: =IFERROR(May!I3,"") | H4: =IFERROR(Jun!I3,"") -> 0.34782609 | I4: =IFERROR(Jul!I3,"") -> 0.52941176 | J4: =IFERROR(Aug!I3,"") -> 0.4137931 | K4: =IFERROR(Sep!L3,"") -> 0.3220339 | L4: =IFERROR(Oct!L3,"") -> 0.39655172 | M4: =IFERROR(Nov!I3,"") | N4: =IFERROR(Dec!I3,"") | O4: =IFERROR(__xludf.DUMMYFUNCTION("IFERROR(SPARKLINE(C4:N4, {""chartype"", ""line""; ""color"", ""blue""})) "),"")
A5: Call To Offer Rate: | B5: =IFERROR(B11/B10,"") | C5: =Jan!I4 -> #REF! | D5: =IFERROR(Feb!I4,"") | E5: =IFERROR(Mar!I4,"") | F5: =IFERROR(Template!I4,"") | G5: =IFERROR(May!I4,"") | H5: =IFERROR(Jun!I4,"") -> 0.92 | I5: =IFERROR(Jul!I4,"") -> 1 | J5: =IFERROR(Aug!I4,"") -> 1 | K5: =IFERROR(Sep!L4,"") -> 0.96721311 | L5: =IFERROR(Oct!L4,"") -> 0.98305085 | M5: =IFERROR(Nov!I4,"") | N5: =IFERROR(Dec!I4,"") | O5: =IFERROR(__xludf.DUMMYFUNCTION("IFERROR(SPARKLINE(C5:N5, {""chartype"", ""line""; ""color"", ""blue""})) "),"")
A6: Revenue: | B6: =IFERROR(SUM(C6:N6),"") | C6: =Jan!C3 -> #REF! | D6: =IFERROR(Feb!C3,"") | E6: =IFERROR(Mar!$C3,"") | F6: =IFERROR(Template!$C3,"") -> 0 | G6: =IFERROR(May!$C3,"") -> 0 | H6: =IFERROR(Jun!$C3,"") -> 69500 | I6: =IFERROR(Jul!$C3,"") -> 162000 | J6: =IFERROR(Aug!$C3,"") -> 111000 | K6: =IFERROR(Sep!$C3,"") -> 202500 | L6: =IFERROR(Oct!$C3,"") -> 238500 | M6: =IFERROR(Nov!$C3,"") -> 155000 | N6: =IFERROR(Dec!$C3,"") -> 239000 | O6: =IFERROR(__xludf.DUMMYFUNCTION("IFERROR(SPARKLINE(C6:N6, {""chartype"", ""line""; ""color"", ""blue""})) "),"")
A7: Cash: | B7: =IFERROR(SUM(C7:N7),"") | C7: =Jan!C4 -> #REF! | D7: =IFERROR(Feb!C4,"") | E7: =IFERROR(Mar!$C4,"") | F7: =IFERROR(Template!$C4,"") -> 0 | G7: =IFERROR(May!$C4,"") -> 0 | H7: =IFERROR(Jun!$C4,"") -> 22100 | I7: =IFERROR(Jul!$C4,"") -> 88550 | J7: =IFERROR(Aug!$C4,"") -> 43875 | K7: =IFERROR(Sep!$C4,"") -> 55150 | L7: =IFERROR(Oct!$C4,"") -> 75349.5 | M7: =IFERROR(Nov!$C4,"") -> 64800 | N7: =IFERROR(Dec!$C4,"") -> 80950 | O7: =IFERROR(__xludf.DUMMYFUNCTION("IFERROR(SPARKLINE(C7:N7, {""chartype"", ""line""; ""color"", ""blue""})) "),"")
A8: Bookings: | B8: =IFERROR(SUM(C8:N8),"") | C8: =Jan!I6 -> #REF! | D8: =IFERROR(Feb!I6,"") | E8: =IFERROR(Mar!$I6,"") | F8: =IFERROR(Template!$I6,"") -> 0 | G8: =IFERROR(May!$I6,"") -> 0 | H8: =IFERROR(Jun!$I6,"") -> 31 | I8: =IFERROR(Jul!$I6,"") -> 42 | J8: =IFERROR(Aug!$I6,"") -> 32 | K8: =IFERROR(Sep!$L6,"") -> 70 | L8: =IFERROR(Oct!$L6,"") -> 73 | M8: =IFERROR(Nov!$L6,"") -> 67 | N8: =IFERROR(Dec!$L6,"") -> 65 | O8: =IFERROR(__xludf.DUMMYFUNCTION("IFERROR(SPARKLINE(C8:N8, {""chartype"", ""line""; ""color"", ""blue""})) "),"")
A9: Shows: | B9: =sum(C9:N9) -> #REF! | C9: =Jan!I7 -> #REF! | D9: =IFERROR(Feb!$I$7,"") | E9: =IFERROR(Mar!$I$7,"") | F9: =IFERROR(Template!$I$7,"") -> 0 | G9: =IFERROR(May!$I$7,"") -> 0 | H9: =IFERROR(Jun!$I$7,"") -> 25 | I9: =IFERROR(Jul!$I$7,"") -> 34 | J9: =IFERROR(Aug!$I$7,"") -> 29 | K9: =IFERROR(Sep!$L$7,"") -> 61 | L9: =IFERROR(Oct!$L$7,"") -> 59 | M9: =IFERROR(Nov!$L$7,"") -> 57 | N9: =IFERROR(Dec!$L$7,"") -> 55 | O9: =IFERROR(__xludf.DUMMYFUNCTION("IFERROR(SPARKLINE(C9:N9, {""chartype"", ""line""; ""color"", ""blue""})) "),"")
A10: Calls: | B10: =IFERROR(SUM(C10:N10),"") | C10: =Jan!I7 -> #REF! | D10: =IFERROR(Feb!I8,"") | E10: =IFERROR(Mar!$I8,"") | F10: =IFERROR(Template!$I8,"") -> 0 | G10: =IFERROR(May!$I8,"") -> 0 | H10: =IFERROR(Jun!$I8,"") -> 25 | I10: =IFERROR(Jul!$I8,"") -> 34 | J10: =IFERROR(Aug!$I8,"") -> 29 | K10: =IFERROR(Sep!$L8,"") -> 61 | L10: =IFERROR(Oct!$L8,"") -> 59 | M10: =IFERROR(Nov!$L8,"") -> 57 | N10: =IFERROR(Dec!$L8,"") -> 55 | O10: =IFERROR(__xludf.DUMMYFUNCTION("IFERROR(SPARKLINE(C10:N10, {""chartype"", ""line""; ""color"", ""blue""})) "),"")
A11: Offers: | B11: =IFERROR(SUM(C11:N11),"") | C11: =Jan!I9 -> #REF! | D11: =IFERROR(Feb!I9,"") | E11: =IFERROR(Mar!$I9,"") | F11: =IFERROR(Template!$I9,"") -> 0 | G11: =IFERROR(May!$I9,"") -> 0 | H11: =IFERROR(Jun!$I9,"") -> 23 | I11: =IFERROR(Jul!$I9,"") -> 34 | J11: =IFERROR(Aug!$I9,"") -> 29 | K11: =IFERROR(Sep!$L9,"") -> 59 | L11: =IFERROR(Oct!$L9,"") -> 58 | M11: =IFERROR(Nov!$L9,"") -> 55 | N11: =IFERROR(Dec!$L9,"") -> 52 | O11: =IFERROR(__xludf.DUMMYFUNCTION("IFERROR(SPARKLINE(C11:N11, {""chartype"", ""line""; ""color"", ""blue""})) "),"")
A12: Deals: | B12: =IFERROR(SUM(C12:N12),"") | C12: =Jan!I10 -> #REF! | D12: =IFERROR(Feb!I10,"") | E12: =IFERROR(Mar!$I10,"") | F12: =IFERROR(Template!$I10,"") -> 0 | G12: =IFERROR(May!$I10,"") -> 0 | H12: =IFERROR(Jun!$I10,"") -> 8 | I12: =IFERROR(Jul!$I10,"") -> 18 | J12: =IFERROR(Aug!$I10,"") -> 12 | K12: =IFERROR(Sep!$L10,"") -> 19 | L12: =IFERROR(Oct!$L10,"") -> 23 | M12: =IFERROR(Nov!$L10,"") -> 17 | N12: =IFERROR(Dec!$L10,"") -> 23 | O12: =IFERROR(__xludf.DUMMYFUNCTION("IFERROR(SPARKLINE(C12:N12, {""chartype"", ""line""; ""color"", ""blue""})) "),"")
A13: Full-Pay: | B13: =IFERROR(SUM(C13:N13),"") | C13: =Jan!F2 -> #REF! | D13: =IFERROR(Feb!F2,"") | E13: =IFERROR(Mar!$F2,"") | F13: =IFERROR(Template!$F2,"") -> 0 | G13: =IFERROR(May!$F2,"") -> 0 | H13: =IFERROR(Jun!$F2,"") -> 1 | I13: =IFERROR(Jul!$F2,"") -> 7 | J13: =IFERROR(Aug!$F2,"") -> 3 | K13: =IFERROR(Sep!$I2,"") -> 1 | L13: =IFERROR(Oct!$I2,"") -> 1 | M13: =IFERROR(Nov!$I2,"") -> 5 | N13: =IFERROR(Dec!$I2,"") -> 3 | O13: =IFERROR(__xludf.DUMMYFUNCTION("IFERROR(SPARKLINE(C13:N13, {""chartype"", ""line""; ""color"", ""blue""})) "),"")
A14: Split-Pay: | B14: =IFERROR(SUM(C14:N14),"") | C14: =Jan!F3 -> #REF! | D14: =IFERROR(Feb!F3,"") | E14: =IFERROR(Mar!$F3,"") | F14: =IFERROR(Template!$F3,"") -> 0 | G14: =IFERROR(May!$F3,"") -> 0 | H14: =IFERROR(Jun!$F3,"") -> 7 | I14: =IFERROR(Jul!$F3,"") -> 11 | J14: =IFERROR(Aug!$F3,"") -> 9 | K14: =IFERROR(Sep!$I3,"") -> 18 | L14: =IFERROR(Oct!$I3,"") -> 22 | M14: =IFERROR(Nov!$I3,"") -> 12 | N14: =IFERROR(Dec!$I3,"") -> 20 | O14: =IFERROR(__xludf.DUMMYFUNCTION("IFERROR(SPARKLINE(C14:N14, {""chartype"", ""line""; ""color"", ""blue""})) "),"")
A15: Deposits: | B15: =IFERROR(SUM(C15:N15),"") | C15: =Jan!F4 -> #REF! | D15: =IFERROR(Feb!F4,"") | E15: =IFERROR(Mar!$F4,"") | F15: =IFERROR(Template!$F4,"") -> 0 | G15: =IFERROR(May!$F4,"") -> 0 | H15: =IFERROR(Jun!$F4,"") -> 0 | I15: =IFERROR(Jul!$F4,"") -> 1 | J15: =IFERROR(Aug!$F4,"") -> 1 | K15: =IFERROR(Sep!$I4,"") -> 8 | L15: =IFERROR(Oct!$I4,"") -> 4 | M15: =IFERROR(Nov!$I4,"") -> 7 | N15: =IFERROR(Dec!$I4,"") -> 6 | O15: =IFERROR(__xludf.DUMMYFUNCTION("IFERROR(SPARKLINE(C15:N15, {""chartype"", ""line""; ""color"", ""blue""})) "),"")
A16: Show-Up Rate: | B16: =B9/B8 -> #REF! | C16: =C9/C8 -> #REF! | D16: =D9/D8 -> #DIV/0! | E16: =E9/E8 -> #DIV/0! | F16: =F9/F8 -> #DIV/0! | G16: =G9/G8 -> #DIV/0! | H16: =H9/H8 -> 0.80645161 | I16: =I9/I8 -> 0.80952381 | ... N16: =N9/N8 -> 0.84615385 | O16: =IFERROR(__xludf.DUMMYFUNCTION("IFERROR(SPARKLINE(C16:N16, {""chartype"", ""line""; ""color"", ""blue""})) "),"")
A17: Conducted Rate: | B17: =B10/B8 -> #DIV/0! | C17: =C10/C8 -> #REF! | D17: =D10/D8 -> #DIV/0! | E17: =E10/E8 -> #DIV/0! | F17: =F10/F8 -> #DIV/0! | G17: =G10/G8 -> #DIV/0! | H17: =H10/H8 -> 0.80645161 | I17: =I10/I8 -> 0.80952381 | ... N17: =N10/N8 -> 0.84615385 | O17: =IFERROR(__xludf.DUMMYFUNCTION("IFERROR(SPARKLINE(C17:N17, {""chartype"", ""line""; ""color"", ""blue""})) "),"")

Sheet Template
B1: Rep: | C1: Anna | E1: Outcome | H1: KPIs% | K1: Show Rate | N1: Objections | Q1: Source | U1: Tracking
E2: Full-Pay: | F2: =IFERROR(COUNTIFS(I13:I287, "Full-Pay"),"") -> 0 | H2: Conversion Rate: | I2: =iferror(I10/I8,"") | K2: Rescheduling Rate: | L2: =iferror(F8/I6,"") | N2: Think About It | O2: =IFERROR(COUNTIFS(N13:N286, "think about it"),"") -> 0 | Q2: Reschedule | R2: =IFERROR(COUNTIF(H13:H286,Q2),"") -> 0 | S2: Cold Call | T2: =IFERROR(COUNTIF(H13:H286,S2),"") -> 0
B3: Revenue | C3: =IFERROR(SUM(K13:K284),"") -> 0 | E3: Split-Pay: | F3: =IFERROR(COUNTIFS(I13:I287, "Split-Pay"),"") -> 0 | H3: Offer To Close Rate: | I3: =IFERROR(I10/I9,"") | K3: Cancellation Rate: | L3: =iferror(F9/I6,"") | N3: Money | O3: =IFERROR(COUNTIFS(N13:N286, "money"),"") -> 0 | Q3: YouTube | R3: =IFERROR(COUNTIF(H13:H286,Q3),"") -> 0 | S3: Twitter | T3: =IFERROR(COUNTIF(H13:H286,S3),"") -> 0
B4: Cash | C4: =IFERROR(SUM(L13:L284),"") -> 0 | E4: Deposits: | F4: =IFERROR(COUNTIFS(I13:I287, "Deposit"),"") -> 0 | H4: Call To Offer Rate: | I4: =IFERROR(I9/I8,"") | K4: No-Shows Rate: | L4: =iferror(F10/I6,"") | N4: Time | O4: =IFERROR(COUNTIFS(N13:N286, "time"),"") -> 0 | Q4: YouTube Ads | R4: =IFERROR(COUNTIF(H13:H286,Q4),"") -> 0 | S4: Skool | T4: =IFERROR(COUNTIF(H13:H286,S4),"") -> 0
E5: Offer & Didn't Buy: | F5: =IFERROR(COUNTIFS(I13:I287, "Offer & Didn't Buy"),"") -> 0 | H5: Drag Over Rate: | I5: =IFERROR(F7/(C6+F7+F8),"") | K5: Drag Over Rate: | L5: =iferror(F7/I6,"") | N5: Partner | O5: =IFERROR(COUNTIFS(N13:N286, "partner"),"") -> 0 | Q5: Email | R5: =IFERROR(COUNTIF(H13:H286,Q5),"") -> 0 | S5: Instagram | T5: =IFERROR(COUNTIF(H13:H286,S5),"") -> 0
B6: Total Calls : | C6: =IFERROR(SUM(F2:F6),"") -> 0 | E6: Bad Fit & No Offer: | F6: =IFERROR(COUNTIFS(I13:I287, "Bad Fit & No Offer"),"") -> 0 | H6: Bookings: | I6: =IFERROR(SUM(F2:F10),"") -> 0 | K6: Show-Up Rate: | L6: =iferror(I7/I6,"") | N6: Fear | O6: =IFERROR(COUNTIFS(N13:N286, "fear"),"") -> 0 | Q6: Facebook | R6: =IFERROR(COUNTIF(H13:H286,Q6),"") -> 0 | S6: TikTok | T6: =IFERROR(COUNTIF(H13:H286,S6),"") -> 0
B7: Total Won : | C7: =IFERROR(F2+F3,"") -> 0 | E7: Drag Over & Show: | F7: =IFERROR(COUNTIFS(I13:I287, "Drag Over & Show"),"") -> 0 | H7: Shows: | I7: =IFERROR(SUM(F2:F7),"") -> 0 | K7: Conducted Rate: | L7: =IFERROR(I8/I6,"") | N7: Value | O7: =IFERROR(COUNTIFS(N14:N287, "value"),"") -> 0 | Q7: Facebook Ads | R7: =IFERROR(COUNTIF(H13:H286,Q7),"") -> 0 | S7: Google | T7: =IFERROR(COUNTIF(H13:H286,S7),"") -> 0
B8: Total Lost : | C8: =COUNTIF(I13:I286,"offer & didn't buy")+countif(I13:I286,"deposit")+countif(I13:I286,"bad fit & no offer") -> 0 | E8: Rescheduled: | F8: =IFERROR(COUNTIFS(I13:I287, "Rescheduled"),"") -> 0 | H8: Calls: | I8: =IFERROR(SUM(F2:F6),"") -> 0 | Q8: LinkedIn | R8: =IFERROR(COUNTIF(H13:H286,Q8),"") -> 0 | S8: Referral | T8: =IFERROR(COUNTIF(H13:H286,S8),"") -> 0
B9: Closing % : | C9: =iferror(SUM(C7/C6),"") | E9: Cancelled: | F9: =IFERROR(COUNTIFS(I13:I287, "Cancelled"),"") -> 0 | H9: Offers: | I9: =IFERROR(sum(F2:F5),"") -> 0
E10: No-Show: | F10: =IFERROR(COUNTIFS(I13:I287, "No-Show"),"") -> 0 | H10: Deals | I10: =F2+F3 -> 0
B12: Date | C12: Name | E12: Phone No. | F12: IG | H12: Source | I12: Outcome | K12: Revenue | L12: Cash | N12: Objection | O12: Objection Notes | Q12: Length | R12: Recording Link | S12: Follow Up/Next Steps | T12: Call Summary

Sheet May
B1: Rep: | C1: Name | E1: Outcome | H1: KPIs% | K1: Show Rate | N1: Objections | Q1: Source | U1: Tracking
E2: Full-Pay: | F2: =IFERROR(COUNTIFS(I13:I287, "Full-Pay"),"") -> 0 | H2: Conversion Rate: | I2: =iferror(I10/I8,"") | K2: Rescheduling Rate: | L2: =iferror(F8/I6,"") | N2: Think About It | O2: =IFERROR(COUNTIFS(N13:N286, "think about it"),"") -> 0 | Q2: Reschedule | R2: =IFERROR(COUNTIF(H13:H286,Q2),"") -> 0 | S2: Cold Call | T2: =IFERROR(COUNTIF(H13:H286,S2),"") -> 0
B3: Revenue | C3: =IFERROR(SUM(K13:K283),"") -> 0 | E3: Split-Pay: | F3: =IFERROR(COUNTIFS(I13:I287, "Split-Pay"),"") -> 0 | H3: Offer To Close Rate: | I3: =IFERROR(I10/I9,"") | K3: Cancellation Rate: | L3: =iferror(F9/I6,"") | N3: Money | O3: =IFERROR(COUNTIFS(N13:N286, "money"),"") -> 0 | Q3: YouTube | R3: =IFERROR(COUNTIF(H13:H286,Q3),"") -> 0 | S3: Twitter | T3: =IFERROR(COUNTIF(H13:H286,S3),"") -> 0
B4: Cash | C4: =IFERROR(SUM(L13:L284),"") -> 0 | E4: Deposits: | F4: =IFERROR(COUNTIFS(I13:I287, "Deposit"),"") -> 0 | H4: Call To Offer Rate: | I4: =IFERROR(I9/I8,"") | K4: No-Shows Rate: | L4: =iferror(F10/I6,"") | N4: Time | O4: =IFERROR(COUNTIFS(N13:N286, "time"),"") -> 0 | Q4: YouTube Ads | R4: =IFERROR(COUNTIF(H13:H286,Q4),"") -> 0 | S4: Skool | T4: =IFERROR(COUNTIF(H13:H286,S4),"") -> 0
E5: Offer & Didn't Buy: | F5: =IFERROR(COUNTIFS(I13:I287, "Offer & Didn't Buy"),"") -> 0 | H5: Drag Over Rate: | I5: =IFERROR(F7/(C6+F7+F8),"") | K5: Drag Over Rate: | L5: =iferror(F7/I6,"") | N5: Partner | O5: =IFERROR(COUNTIFS(N13:N286, "partner"),"") -> 0 | Q5: Email | R5: =IFERROR(COUNTIF(H13:H286,Q5),"") -> 0 | S5: Instagram | T5: =IFERROR(COUNTIF(H13:H286,S5),"") -> 0
B6: Total Calls : | C6: =IFERROR(SUM(F2:F6),"") -> 0 | E6: Bad Fit & No Offer: | F6: =IFERROR(COUNTIFS(I13:I287, "Bad Fit & No Offer"),"") -> 0 | H6: Bookings: | I6: =IFERROR(SUM(F2:F10),"") -> 0 | K6: Show-Up Rate: | L6: =iferror(I7/I6,"") | N6: Fear | O6: =IFERROR(COUNTIFS(N13:N286, "fear"),"") -> 0 | Q6: Facebook | R6: =IFERROR(COUNTIF(H13:H286,Q6),"") -> 0 | S6: TikTok | T6: =IFERROR(COUNTIF(H13:H286,S6),"") -> 0
B7: Total Won : | C7: =IFERROR(F2+F3,"") -> 0 | E7: Drag Over & Show: | F7: =IFERROR(COUNTIFS(I13:I287, "Drag Over & Show"),"") -> 0 | H7: Shows: | I7: =IFERROR(SUM(F2:F7),"") -> 0 | K7: Conducted Rate: | L7: =IFERROR(I8/I6,"") | N7: Value | O7: =IFERROR(COUNTIFS(N14:N287, "value"),"") -> 0 | Q7: Facebook Ads | R7: =IFERROR(COUNTIF(H13:H286,Q7),"") -> 0 | S7: Google | T7: =IFERROR(COUNTIF(H13:H286,S7),"") -> 0
B8: Total Lost : | C8: =COUNTIF(I13:I286,"offer & didn't buy")+countif(I13:I286,"deposit")+countif(I13:I286,"bad fit & no offer") -> 0 | E8: Rescheduled: | F8: =IFERROR(COUNTIFS(I13:I287, "Rescheduled"),"") -> 0 | H8: Calls: | I8: =IFERROR(SUM(F2:F6),"") -> 0 | Q8: LinkedIn | R8: =IFERROR(COUNTIF(H13:H286,Q8),"") -> 0 | S8: Referral | T8: =IFERROR(COUNTIF(H13:H286,S8),"") -> 0
B9: Closing % : | C9: =iferror(SUM(C7/C6),"") | E9: Cancelled: | F9: =IFERROR(COUNTIFS(I13:I287, "Cancelled"),"") -> 0 | H9: Offers: | I9: =IFERROR(sum(F2:F5),"") -> 0
E10: No-Show: | F10: =IFERROR(COUNTIFS(I13:I287, "No-Show"),"") -> 0 | H10: Deals | I10: =F2+F3 -> 0
B12: Date | C12: Name | E12: Phone No. | F12: Email | H12: Source | I12: Outcome | K12: Revenue | L12: Cash | N12: Objection | O12: Objection Notes | Q12: Length | R12: Recording Link | S12: Follow Up/Next Steps | T12: Call Summary

Sheet Jun
B1: Rep: | C1: Name | E1: Outcome | H1: KPIs% | K1: Show Rate | N1: Objections | Q1: Source | U1: Tracking
E2: Full-Pay: | F2: =IFERROR(COUNTIFS(I13:I287, "Full-Pay"),"") -> 1 | H2: Conversion Rate: | I2: =iferror(I10/I8,"") -> 0.32 | K2: Rescheduling Rate: | L2: =iferror(F8/I6,"") -> 0.064516129 | N2: Think About It | O2: =IFERROR(COUNTIFS(N13:N286, "think about it"),"") -> 1 | Q2: Reschedule | R2: =IFERROR(COUNTIF(H13:H286,Q2),"") -> 0 | S2: Cold Call | T2: =IFERROR(COUNTIF(H13:H286,S2),"") -> 0
B3: Revenue | C3: =IFERROR(SUM(K13:K283),"") -> 69500 | E3: Split-Pay: | F3: =IFERROR(COUNTIFS(I13:I287, "Split-Pay"),"") -> 7 | H3: Offer To Close Rate: | I3: =IFERROR(I10/I9,"") -> 0.34782609 | K3: Cancellation Rate: | L3: =iferror(F9/I6,"") -> 0.032258065 | N3: Money | O3: =IFERROR(COUNTIFS(N13:N286, "money"),"") -> 10 | Q3: YouTube | R3: =IFERROR(COUNTIF(H13:H286,Q3),"") -> 0 | S3: Twitter | T3: =IFERROR(COUNTIF(H13:H286,S3),"") -> 0
B4: Cash | C4: =IFERROR(SUM(L13:L284),"") -> 22100 | E4: Deposits: | F4: =IFERROR(COUNTIFS(I13:I287, "Deposit"),"") -> 0 | H4: Call To Offer Rate: | I4: =IFERROR(I9/I8,"") -> 0.92 | K4: No-Shows Rate: | L4: =iferror(F10/I6,"") -> 0.096774194 | N4: Time | O4: =IFERROR(COUNTIFS(N13:N286, "time"),"") -> 2 | Q4: YouTube Ads | R4: =IFERROR(COUNTIF(H13:H286,Q4),"") -> 0 | S4: Skool | T4: =IFERROR(COUNTIF(H13:H286,S4),"") -> 0
E5: Offer & Didn't Buy: | F5: =IFERROR(COUNTIFS(I13:I287, "Offer & Didn't Buy"),"") -> 15 | H5: Drag Over Rate: | I5: =IFERROR(F7/(C6+F7+F8),"") -> 0 | K5: Drag Over Rate: | L5: =iferror(F7/I6,"") -> 0 | N5: Partner | O5: =IFERROR(COUNTIFS(N13:N286, "partner"),"") -> 1 | Q5: Email | R5: =IFERROR(COUNTIF(H13:H286,Q5),"") -> 0 | S5: Instagram | T5: =IFERROR(COUNTIF(H13:H286,S5),"") -> 0
B6: Total Calls : | C6: =IFERROR(SUM(F2:F6),"") -> 25 | E6: Bad Fit & No Offer: | F6: =IFERROR(COUNTIFS(I13:I287, "Bad Fit & No Offer"),"") -> 2 | H6: Bookings: | I6: =IFERROR(SUM(F2:F10),"") -> 31 | K6: Show-Up Rate: | L6: =iferror(I7/I6,"") -> 0.80645161 | N6: Fear | O6: =IFERROR(COUNTIFS(N13:N286, "fear"),"") -> 3 | Q6: Facebook | R6: =IFERROR(COUNTIF(H13:H286,Q6),"") -> 0 | S6: TikTok | T6: =IFERROR(COUNTIF(H13:H286,S6),"") -> 0
B7: Total Won : | C7: =IFERROR(F2+F3,"") -> 8 | E7: Drag Over & Show: | F7: =IFERROR(COUNTIFS(I13:I287, "Drag Over & Show"),"") -> 0 | H7: Shows: | I7: =IFERROR(SUM(F2:F7),"") -> 25 | K7: Conducted Rate: | L7: =IFERROR(I8/I6,"") -> 0.80645161 | N7: Value | O7: =IFERROR(COUNTIFS(N14:N287, "value"),"") -> 0 | Q7: Facebook Ads | R7: =IFERROR(COUNTIF(H13:H286,Q7),"") -> 7 | S7: Google | T7: =IFERROR(COUNTIF(H13:H286,S7),"") -> 0
B8: Total Lost : | C8: =COUNTIF(I13:I286,"offer & didn't buy")+countif(I13:I286,"deposit")+countif(I13:I286,"bad fit & no offer") -> 17 | E8: Rescheduled: | F8: =IFERROR(COUNTIFS(I13:I287, "Rescheduled"),"") -> 2 | H8: Calls: | I8: =IFERROR(SUM(F2:F6),"") -> 25 | Q8: LinkedIn | R8: =IFERROR(COUNTIF(H13:H286,Q8),"") -> 0 | S8: Referral | T8: =IFERROR(COUNTIF(H13:H286,S8),"") -> 0
B9: Closing % : | C9: =iferror(SUM(C7/C6),"") -> 0.32 | E9: Cancelled: | F9: =IFERROR(COUNTIFS(I13:I287, "Cancelled"),"") -> 1 | H9: Offers: | I9: =IFERROR(sum(F2:F5),"") -> 23
E10: No-Show: | F10: =IFERROR(COUNTIFS(I13:I287, "No-Show"),"") -> 3 | H10: Deals | I10: =F2+F3 -> 8
B12: Date | C12: Name | E12: Phone No. | F12: Email | H12: Source | I12: Outcome | K12: Revenue | L12: Cash | N12: Objection | O12: Objection Notes | Q12: Length | R12: Recording Link | S12: Follow Up/Next Steps | T12: Call Summary
B13: 2. juni | C13: Alex Pedersen | E13: 20742600 | F13: alexelfving@hotmail.dk | H13: Setter | I13: Offer & Didn't Buy | N13: Money | O13: Nævnt både tid og pengene, men var nok i bund og grund pengene | S13: X | T13: Var i bund og grund ikke klar til a committe og syntes det var dyrt, i forhold til hvad han ville lægge i det
B14: 2. juni | C14: Malte Brix | E14: 30209070 | F14: brixmalte392@gmail.com | H14: Landing page | I14: Rescheduled | S14: Follow Up
B15: 3. juni | C15: Patrick Hansen | E15: 22584551 | F15: paatrickkh@gmail.com | H15: Landing page | I15: Offer & Didn't Buy | N15: Money | O15: Syntes det var dyrt og lige pludseligt var der det ene og andet i vejen | S15: X | T15: Havde ikke tænkt over hvorfor det var vigtigt for ham, tror ikke rigtigt han havde tænkt det igennem
B16: 3. juni | C16: Pia Mattheisen | E16: 26361821 | F16: blomst1981@hotmail.com | H16: Setter | I16: Split-pay | K16: 6500 | L16: 500 | N16: Money | O16: Var det økonomisk med 4 børn der trykkede | Q16: 4 Måneder | S16: Closed | T16: Syntes det var en god samtale jeg havde med hende lød ret klar og følger op på hende i morgen kl 16:15
B17: 5. juni | C17: Agnes Balch | E17: 60549433 | F17: agnesbalch@gmail.com | H17: Setter | I17: Offer & Didn't Buy | N17: Partner | O17: Skulle snakke med sin mor om det, fordi hun også ville støtte hende økonomisk, føler først det gav mening efter sommerferien, hvor skoledagen pressed på igen. Har tilbudt hende en plads efter sommerferien, hvis hun lægger et depositum | S17: Follow Up Set | T17: Rigtig god snak hun virker varm, jeg hører noget om et par timer
B18: 5.juni | C18: Marie Rasmussen | E18: 20872787 | F18: marielrasmussen01@gmail.com | H18: Setter | I18: Split-pay | K18: 9000 | L18: 3000 | Q18: 5 Måneder | S18: Closed | T18: Havde ikke tænkt over hvorfor det var vigtigt for ham, tror ikke rigtigt han havde tænkt det igennem
B19: 6. juni | C19: Cathrine NIlson | E19: 40195943 | F19: cathrinehn@hotmail.com | H19: Facebook Ads | I19: No-Show
B20: 6. juni | C20: Malthe Reilund | E20: 53607017 | F20: malthereilund@icloud.com | H20: Facebook Ads | I20: Offer & Didn't Buy | N20: Fear | O20: Sagde han skulle tænke over, og det var hverken penge, værdi, eller noget andet | S20: X | T20: Han sagde jeg til alt i forhold til om at følte det var det rette for ham kunne bare ikke commite sig og endte med at lægge på
B21: 6. juni | C21: Nana Sommer | E21: 51160980 | F21: nanasommer99@gmail.com | H21: Setter | I21: Split-pay | K21: 9000 | L21: 1800 | Q21: 5 Måneder | S21: Closed | T21: God samtale, vi havde, hun kunne nemmere få det til at fungere med en højere månedlig pris end en opstart
B22: 9. juni | C22: Line Chan Larsen | E22: 61418828 | F22: linechanlarsen@gmail.com | H22: Setter | I22: Offer & Didn't Buy | N22: Time | O22: Sagde det var dårlig timing i forhold til hvor hun var lige nu, følger op på hende 1. august, der sagde hun det ville passe | S22: Follow Up Set | T22: Samtalen, kunne godt have gået bedre, var ikke god nok i discovery og gik ikke skabt nok pain og urgency
B23: 9. juni | C23: Johannes Jensen | E23: 24228199 | F23: jensenjohannes5@gmail.com | H23: Landing page | I23: Split-pay | K23: 9000 | L23: 3000 | Q23: 5 Måneder
B24: 11. juni | C24: Malte Brix | E24: 30209070 | F24: brixmalte392@gmail.com | H24: Landing page | I24: No-Show
B25: 11. juni | C25: Nikoline Pilgaard Nielsen | E25: 20829235 | F25: nikoline.pilgaard@gmail.com | H25: Setter | I25: Offer & Didn't Buy | N25: Think About It | O25: Hun sagde nu ikke var sikker på om en online træner var noget for hende, nu nok havde mere gavn af en fysisk | S25: X | T25: Var bedre i discovery fandt noget pain og havde fokus på at frame samtalen godt.(kom til at sprøge om de samme spørgsmål for mange gang.) Fucker nok lidt op ved pricedrop, og corner hende lidt for meget i forhold til objection handling, skal være/lyde mere hjælpsom. Hun endte med at lægge på
B26: 13. juni | C26: Lucas Starup | E26: 23919060 | F26: lucas.jorgensen.starup@gmail.com | H26: Setter | I26: Bad Fit & No Offer | S26: X | T26: God snak med lucas, fucker lidt på med hans money objection, ved ikke hvorfor jeg ikke bare følger frameworket. Han havde ingen penge nu, så kunne først lade sig gøre 1. august, derfor ingen startup :(. Viser sig han ikke har fået forældre tilladelse (under 18) selvom han sagde det ikke var et problem
B27: 16. juni | C27: Carina Jensen | E27: 22662912 | F27: carinawj@hotmail.com | H27: Setter | I27: Offer & Didn't Buy | N27: Money | O27: Det kunne simpelthen ikke lade sig gøre økonomisk. Hun sagde udgifterne var større end indkomsten, og sådan havde det egenligt været de sidste par måneder | S27: X | T27: God snak, hun syntes det virkede fedt, skulle bare tjekke op på det økonomiske. Kunne simpelthen ikke lade sig gøre
B28: 16. juni | C28: Sofia Bogarch | E28: 30747351 | F28: sofia.bogarch@gmail.com | H28: Setter | I28: Split-pay | K28: 9000 | L28: 1000 | Q28: 5 Måneder | S28: Closed | T28: Gik godt, havde ikke de store indsigelser, godt være skarpere på nogle spørgsmål. betalte 1000 upfront og resten delt i 3
B29: 17. juni | C29: Naya Lindevang-Hilstrø, | E29: 26643009 | F29: aya_hil@hotmail.con | H29: Facebook Ads | I29: Offer & Didn't Buy | N29: Money | O29: Hun var pt på barsel, så hun skulle lige undersøge økonomien i det | S29: Follow Up Set | T29: Hun var klar, det var kun pengene, der var problemet, eller så var hun 100 procent klar når hun kom tilbage fra barsel
B30: 17 juni | C30: Jeppe Bach Olesen | E30: 61319741 | F30: jeppebacholesen@gmail.com | H30: Facebook Ads | I30: Offer & Didn't Buy | N30: Money | O30: Han skulle simpelthen, bare kigge på det økonomien i det | S30: X | T30: Har en aftale med ham i morgen kl 17. Skulle have brugt den med "jeg ved hvad der sker når vi lægger på nu her...." Ved ikke hvorfor jeg ikke gjorde det
B31: 17. juni | C31: William Holm Carlson | E31: 20866807 | F31: williamholm.carlson@icloud.com | H31: Landing page | I31: Rescheduled | T31: Skal have forældrene med var under 18
B32: 18. juni | C32: Hørður í geil | E32: 52232168 | F32: hig1998@gmail.com | H32: Setter | I32: Cancelled
B33: 18. juni | C33: Tommy Lindevang Hansen | E33: 20652890 | F33: tommylhansen@hotmail.com | H33: Facebook Ads | I33: Full-Pay | K33: 9000 | L33: 9000 | Q33: 5 måneder | S33: Closed | T33: Klasse snak, prøvede at arbejde med med tonailty, og brugte feedback i picth
B34: 22. juni | C34: Cecilie H | E34: 42154443 | F34: madison.hartwich@gmail.com | H34: Setter | I34: Offer & Didn't Buy | N34: Money | O34: Hun var på SU, skulle betale husleje og havde bil, så kunne ikke lade sig gøre | S34: Follow Up Set | T34: Syntes, vi havde en god snak, skulle have brugt commitment noget mere. Har en aftale med at kontakte hende igen slut august, når hun skal i lære og har nogle flere penge
B35: 22. juni | C35: Jesper Mortensen | E35: 20473963 | F35: soegaard96@gmail.com | H35: Facebook Ads | I35: Offer & Didn't Buy | N35: Money | O35: Økonomien var ikke til har ikke job fra næste måned af så nok også timing | T35: Havde en god snak med ham, lød virkeligt på. Lød til ham super gerne ville, men det var pengene, der kom i vejen. Han sagde det nok godt kunne lade sig gøre, men han stod uden job i slutningen af den her måned, så det holdte ham tilbage. Han endte med at lægge på
B36: 23. juni | C36: Mette Møller | E36: 26496120 | F36: mette@family-moeller.net | H36: Setter | I36: Offer & Didn't Buy | N36: Fear | O36: Det er faktisk kan hjælpe hende, da nu har noget løs hud hun ikke er sikker på kan trænes væk | S36: Follow Up Set | T36: Virker virkeligt på bare usikker på om vi kan få hende i mål. Hun har tidligere været på et andet forløb, hvor hun ikke kom i mål. Ringer tilbage til hende i morgen
B37: 23. juni | C37: Michelle Als | E37: 53382706 | F37: missals@live.dk | H37: Facebook Ads | I37: Bad Fit & No Offer | T37: Ville være et dårligt fit hun har en sclerose og det er ikke noget vi normalt arbejder med
B38: 24. juni | C38: Lykke Henckel | E38: 25781914 | H38: Setter | I38: Offer & Didn't Buy | N38: Money | O38: Skulle høre om mor ikke kunne hjælpe | S38: Follow Up | T38: Ville virkeligt gerne, men havde ikke pengene selv, så ville hører sin mor
B39: 24. juni | C39: Jack andersen | E39: 23238865 | F39: jackandersen66@gmail.com | H39: Setter | I39: Offer & Didn't Buy | N39: Fear | O39: Han ghoestede mig selvom han sagde ja til det, så havde en lige pludseligt ikket et kort det virkede | S39: X | T39: Endte jo med han sagde ja, men var nok stadig i tvivel eller turde ikke sige nej, så kunne godt blive bedre
B40: 25. juni | C40: Lasse Lund | E40: 61519344 | F40: lasselund2404@gmail.com | H40: Landing page | I40: Split-pay | K40: 9000 | L40: 1800 | Q40: 5 måneder | S40: Closed | T40: Vidste ikke hvorfor han ikke skulle gøre det, der var i hvert fald noget fear, men endte med han gjorde det
B41: 28. juni | C41: David Silva | E41: 50184073 | F41: ds8.1999@gmail.com | H41: Setter | I41: Split-pay | K41: 9000 | L41: 2000 | N41: Time | O41: Han vil første starte til August | S41: Closed | T41: God snak, han ville udfylde mailen og kort oplysninger i dag
...

Sheet Jul
B1: Rep: | C1: Name | E1: Outcome | H1: KPIs% | K1: Show Rate | N1: Objections | Q1: Source | U1: Tracking
E2: Full-Pay: | F2: =IFERROR(COUNTIFS(I13:I287, "Full-Pay"),"") -> 7 | H2: Conversion Rate: | I2: =iferror(I10/I8,"") -> 0.52941176 | K2: Rescheduling Rate: | L2: =iferror(F8/I6,"") -> 0.047619048 | N2: Think About It | O2: =IFERROR(COUNTIFS(N13:N286, "think about it"),"") -> 0 | Q2: Reschedule | R2: =IFERROR(COUNTIF(H13:H286,Q2),"") -> 0 | S2: Cold Call | T2: =IFERROR(COUNTIF(H13:H286,S2),"") -> 0
B3: Revenue | C3: =IFERROR(SUM(K13:K283),"") -> 162000 | E3: Split-Pay: | F3: =IFERROR(COUNTIFS(I13:I287, "Split-Pay"),"") -> 11 | H3: Offer To Close Rate: | I3: =IFERROR(I10/I9,"") -> 0.52941176 | K3: Cancellation Rate: | L3: =iferror(F9/I6,"") -> 0.071428571 | N3: Money | O3: =IFERROR(COUNTIFS(N13:N286, "money"),"") -> 12 | Q3: YouTube | R3: =IFERROR(COUNTIF(H13:H286,Q3),"") -> 0 | S3: Twitter | T3: =IFERROR(COUNTIF(H13:H286,S3),"") -> 0
B4: Cash | C4: =IFERROR(SUM(L13:L284),"") -> 88550 | E4: Deposits: | F4: =IFERROR(COUNTIFS(I13:I287, "Deposit"),"") -> 1 | H4: Call To Offer Rate: | I4: =IFERROR(I9/I8,"") -> 1 | K4: No-Shows Rate: | L4: =iferror(F10/I6,"") -> 0.071428571 | N4: Time | O4: =IFERROR(COUNTIFS(N13:N286, "time"),"") -> 1 | Q4: YouTube Ads | R4: =IFERROR(COUNTIF(H13:H286,Q4),"") -> 0 | S4: Skool | T4: =IFERROR(COUNTIF(H13:H286,S4),"") -> 0
E5: Offer & Didn't Buy: | F5: =IFERROR(COUNTIFS(I13:I287, "Offer & Didn't Buy"),"") -> 15 | H5: Drag Over Rate: | I5: =IFERROR(F7/(C6+F7+F8),"") -> 0 | K5: Drag Over Rate: | L5: =iferror(F7/I6,"") -> 0 | N5: Partner | O5: =IFERROR(COUNTIFS(N13:N286, "partner"),"") -> 3 | Q5: Email | R5: =IFERROR(COUNTIF(H13:H286,Q5),"") -> 0 | S5: Instagram | T5: =IFERROR(COUNTIF(H13:H286,S5),"") -> 0
B6: Total Calls : | C6: =IFERROR(SUM(F2:F6),"") -> 34 | E6: Bad Fit & No Offer: | F6: =IFERROR(COUNTIFS(I13:I287, "Bad Fit & No Offer"),"") -> 0 | H6: Bookings: | I6: =IFERROR(SUM(F2:F10),"") -> 42 | K6: Show-Up Rate: | L6: =iferror(I7/I6,"") -> 0.80952381 | N6: Fear | O6: =IFERROR(COUNTIFS(N13:N286, "fear"),"") -> 1 | Q6: Facebook | R6: =IFERROR(COUNTIF(H13:H286,Q6),"") -> 0 | S6: TikTok | T6: =IFERROR(COUNTIF(H13:H286,S6),"") -> 0
B7: Total Won : | C7: =IFERROR(F2+F3,"") -> 18 | E7: Drag Over & Show: | F7: =IFERROR(COUNTIFS(I13:I287, "Drag Over & Show"),"") -> 0 | H7: Shows: | I7: =IFERROR(SUM(F2:F7),"") -> 34 | K7: Conducted Rate: | L7: =IFERROR(I8/I6,"") -> 0.80952381 | N7: Value | O7: =IFERROR(COUNTIFS(N14:N287, "value"),"") -> 0 | Q7: Facebook Ads | R7: =IFERROR(COUNTIF(H13:H286,Q7),"") -> 0 | S7: Google | T7: =IFERROR(COUNTIF(H13:H286,S7),"") -> 0
B8: Total Lost : | C8: =COUNTIF(I13:I286,"offer & didn't buy")+countif(I13:I286,"deposit")+countif(I13:I286,"bad fit & no offer") -> 16 | E8: Rescheduled: | F8: =IFERROR(COUNTIFS(I13:I287, "Rescheduled"),"") -> 2 | H8: Calls: | I8: =IFERROR(SUM(F2:F6),"") -> 34 | Q8: LinkedIn | R8: =IFERROR(COUNTIF(H13:H286,Q8),"") -> 0 | S8: Referral | T8: =IFERROR(COUNTIF(H13:H286,S8),"") -> 0
B9: Closing % : | C9: =iferror(SUM(C7/C6),"") -> 0.52941176 | E9: Cancelled: | F9: =IFERROR(COUNTIFS(I13:I287, "Cancelled"),"") -> 3 | H9: Offers: | I9: =IFERROR(sum(F2:F5),"") -> 34
C10: =C3/C6 -> 4764.7059 | E10: No-Show: | F10: =IFERROR(COUNTIFS(I13:I287, "No-Show"),"") -> 3 | H10: Deals | I10: =F2+F3 -> 18
B12: Date | C12: Name | E12: Phone No. | F12: Ig navn | H12: Source | I12: Outcome | K12: Revenue | L12: Cash | N12: Objection | O12: Objection Notes | Q12: Length | R12: Recording Link | S12: Follow Up/Next Steps | T12: Call Summary
B13: 1. Juli | C13: Emma Dybdal Knudsen | E13: 28964056 | F13: https://www.instagram.com/emma__knudsen/ | H13: Setter | I13: Split-pay | K13: 9000 | L13: 3000 | N13: Money | O13: Skulle tjekke om det kunne lade sig gøre, mistanke om der er noget fear | Q13: 5 måneder | S13: Closed | T13: Syntes vi havde en virkeligt god snak, hun var så tæt på, men skulle lige tænke over det økonomiske. Ringer til hende igen i morgen
B14: 4. juli | C14: Amma Kvist | E14: 54320193 | F14: https://www.instagram.com/a_kvist/ | H14: Setter | I14: Split-pay | K14: 9000 | L14: 3000 | Q14: 5 måneder | S14: Closed | T14: Hun havde egenligt sagt nu nok ikke havde pengene, men havde slet ingen objections, så hun må jo have være solgt. Hun havde ingen internet, så hun kunne ikke svare på mailsene, men vil gøre det i dag
B15: 6. juli | C15: Mia Rørdam Støckel | E15: 42910033 | F15: https://www.instagram.com/miastockel/ | H15: Setter | I15: Split-pay | K15: 9000 | L15: 2800 | Q15: 5 måneder | S15: Closed | T15: Hun var bare klar på der skulle ske noget, havde lidt en objection om hendes arbejde fyldte en del men, fik hende i gang
B16: 7. juli | C16: Mathilde Knudsen | E16: 29275838 | F16: @matildeknudsen04 | H16: Setter | I16: Offer & Didn't Buy | N16: Partner | O16: Skulle vende den med forældrene og så vil hun tænke over det til i morgen | S16: X | T16: Fik et depositum, lød virkeligt hooked, men skulle så lige vende den med forældrene og ville gerne have pengene igen for en sikkerhedsskyld. Følte allerede hun var solgt, så challenged hende ikke nok og sprang over nogle spørgsmål og dykkede ikke nok ned i hendes pain og især hendes commitment og motivation
B17: 8. juli | C17: Marie Christina Gryndahl | E17: 20949289 | F17: https://www.instagram.com/mariechristina75/ | H17: Setter | I17: Offer & Didn't Buy | N17: Time | O17: Hun sagde tiden ikke var den rigtige, det var meget på tapetet, mistænker også fear | S17: X | T17: Var allerede fra startet ikke afklaret med det var noget hun ville det her. Var en hård nød at knække. Kunne sku ikke få hende solgt
B18: 8. juli | C18: Nanna Cajer | E18: 25734947 | F18: https://www.instagram.com/nannacajar/ | H18: Setter | I18: Offer & Didn't Buy | N18: Money | O18: Skulle vende den med sin bankrådgiver | S18: X | T18: Lød meget positivt, hun ville vende tilbage i morgen i forhold til hvad bankrådgiveren siger, hun mente selv, det kunne lade sig gøre.
B19: 9. juli | C19: Helle Toft Hansen | E19: 53620100 | F19: helle_t_hansen | H19: Setter | I19: Full-Pay | K19: 9000 | L19: 9000 | Q19: 5 måneder | S19: Closed | T19: Klasse samtale, energi var der bare og tonailty spillede. Vigtigst af alt jeg var hjælpende
B20: 9. juli | C20: Mads Gøsta Brøgger | E20: 29888407 | F20: @kunmads | H20: Setter | I20: Full-Pay | K20: 9000 | L20: 9000 | Q20: 5 måneder | S20: Closed | T20: Skulle lige flytte rundt på nogle penge, ville sende når han kom hjem i aften
B21: 10. juli | C21: Maya B Laursen | E21: 22877779 | F21: https://www.instagram.com/mayabetaklaursen/ | H21: Setter | I21: Offer & Didn't Buy | L21: 1500 | N21: Fear | S21: X | T21: Hun skulle lige have tænker over det, hun var ikke i tvivl om værdien og hun havde pengene. Skulle have spurgt, hvad det var hun skulle tænke over, i stedet for at gå for deposit
B22: 11. juli | C22: Merle Iversen | E22: 25696521 | F22: https://www.instagram.com/merle_iversen_/ | H22: Setter | I22: No-Show
B23: 13. juli | C23: Mikkel Lohse | E23: 21578559 | F23: https://www.instagram.com/lohse_fyren/ | H23: Setter | I23: Rescheduled
B24: 14. juli | C24: Lea Marie W. Wesselhoff | E24: 27129310 | F24: https://www.instagram.com/leawesselhoff/ | H24: Setter | I24: Cancelled
B25: 14. juli | C25: Benjamin Kyoo Dysager | E25: 61462357 | F25: https://www.instagram.com/benjamin_dysager/ | H25: Setter | I25: Cancelled
B26: 14. juli | C26: August Rothstein | E26: 30499574 | F26: https://www.instagram.com/august_rothstein/ | H26: Setter | I26: Offer & Didn't Buy | N26: Money | O26: havde sagt han ikke havde pengene at de ville være et problem på forhånd er kun 17 | S26: Follow Up Set | T26: God snak, følger egenligt jeg fik ham solgt, men jo ikke nok kan man sige. Kunne godt have skubbet mere på i forhold til at han ikke havde pengene, men han siger 100 eller 500 kr. ville ødelægge hans budget, kunne først gøre noget d. 1 august
B27: 14. juli | C27: Mathilde Sund | E27: 30560719 | F27: https://www.instagram.com/mathilde_dannow/ | H27: Setter | I27: Offer & Didn't Buy | N27: Money | O27: På SU havde ikke pengene | S27: Follow Up Set | T27: Kunne nok godt få hende solgt mere på og fundet mere pain. Når alt kom til alt havde hun bare ikke pengene, sad med hende i 15-20 min for at prøve at få det til at lade sig gøre, ved ikke lige hvad jeg skulle gøre i sådan en situation ellers. Følger op på hende på om et par måneder, det var det vi aftalte
B28: 14. juli | C28: Jakob Haakenstad | E28: 25778050 | F28: https://www.instagram.com/jakob_haakenstad/ | H28: Setter | I28: Split-pay | K28: 9000 | L28: 1500 | Q28: 5 måneder | S28: Closed | T28: Havde ikke pengene nu, fik først løn d. 1 august så der kommer 2500 kr. mere ind
B29: 15. juli | C29: Maria Thygsen | E29: 51896148 | F29: https://www.instagram.com/thygesen88/ | H29: Setter | I29: Offer & Didn't Buy | N29: Money | O29: Hun havde bare ikke pegene | S29: Follow Up Set | T29: Vender tilbage til hende d. 1 september
B30: 15. juli | C30: Line Svendsen | E30: 60156529 | F30: https://www.instagram.com/linelindgaardsvendsen/ | H30: Setter | I30: Rescheduled | S30: Follow Up
B31: 15. juli | C31: Johanne Fredslund | E31: 61683219 | F31: https://www.instagram.com/johanneaagaardd/ | H31: Setter | I31: Offer & Didn't Buy | N31: Money | O31: Havde ikke pengene | S31: X | T31: Syntes det var en svær snak, tænker hun var mere nysgerrig på en samtale en villig til at gøre noget. Klart pengene der holdte hende tilbage
B32: 16. Juli | C32: Heidi Henriksen | E32: 53614922 | F32: @henriksen1397 | H32: Setter | I32: Offer & Didn't Buy | N32: Money | O32: Havde ikke pengene | S32: Follow Up Set | T32: Skal snakke med hende igen om en uge, for at se om hun kan skaffe pengene. Skulle have dykket mere ned i hendes pain hun nævnte hun følte sig grim, skulle bare have stukket den fucking kniv ind, fandme dumt
B33: 17. juli | C33: Rebecca Storm Olesen | E33: 42607807 | F33: Rebecca_s_olesen | H33: Setter | I33: Split-pay | K33: 9000 | L33: 1500 | Q33: 5 måneder | S33: Closed
B34: 20. Juli | C34: Christian Andersen | E34: 51863021 | F34: candersen725@gmail.com | H34: Landing page | I34: Full-Pay | K34: 9000 | L34: 9000 | Q34: 5 måneder | S34: Closed
B35: 21. juli | C35: Gustav Jeremiassen | E35: 71703230 | F35: @gustavjeremiassen | H35: Setter | I35: Full-Pay | K35: 9000 | L35: 9000 | Q35: 5 måneder | S35: Closed
B36: 21. juli | C36: Mikkel Lohse | E36: 21578559 | F36: https://www.instagram.com/lohse_fyren/ | H36: Setter | I36: No-Show
B37: 21. juli | C37: Julie Lorenzen | E37: 26937770 | F37: @julielorenzen24 | H37: Setter | I37: Cancelled
B38: 22. juli | C38: Kristoffer Wiedemann | E38: 28629575 | F38: kristofferwiedemann@gmail.com | H38: Landing page | I38: Full-Pay | K38: 9000 | L38: 9000 | Q38: 5 måneder
B39: 22. juli | C39: Lise Kjærsgaard | E39: 20778306 | F39: @lisekg | H39: Setter | I39: Offer & Didn't Buy | N39: Money | O39: Hun havde brug for at afdække markedet, siger hun er sådan hun ikke gør noget impulsivt | S39: Follow Up Set | T39: Snakke med hende igen 3. august. Får hende jo klart ikke solgt godt nok. Hun sagde pengene ikke var et problem, men det skulle priorteres, kunne godt have fået kørt det på en bedre måde efter det, og faktisk spurgt hvad var mest værd. Fik presset hende for meget i stedet for.
B40: 23. juli | C40: Laura Mearun | E40: 41914040 | F40: @lauraraun | H40: Setter | I40: Offer & Didn't Buy | N40: Money | O40: Nåede ikke objection handling fordi hun skulle til læge. WTF! | S40: X | T40: Lidt en mærkeligt snak, gav ikke ret meget af sig selv og forstod ikke hvad jeg spurgte om. Havde ikke sat tid af til snakken
B41: 25. juli | C41: Ida Hakansson | E41: 30 49 41 72 | F41: https://www.instagram.com/idamarie.hakansson/ | H41: Setter | I41: Offer & Didn't Buy | N41: Money | O41: 100 procent pengene | S41: Follow Up Set | T41: Har en rigtigt god fornemmelse med den her follow up
...

Sheet Aug
B1: Rep: | C1: Name | E1: Outcome | H1: KPIs% | K1: Show Rate | N1: Objections | Q1: Source | U1: Tracking
E2: Full-Pay: | F2: =IFERROR(COUNTIFS(I13:I287, "Full-Pay"),"") -> 3 | H2: Conversion Rate: | I2: =iferror(I10/I8,"") -> 0.4137931 | K2: Rescheduling Rate: | L2: =iferror(F8/I6,"") -> 0.03125 | N2: Think About It | O2: =IFERROR(COUNTIFS(N13:N286, "think about it"),"") -> 2 | Q2: Reschedule | R2: =IFERROR(COUNTIF(H13:H286,Q2),"") -> 0 | S2: Cold Call | T2: =IFERROR(COUNTIF(H13:H286,S2),"") -> 0
B3: Revenue | C3: =IFERROR(SUM(K13:K283),"") -> 111000 | E3: Split-Pay: | F3: =IFERROR(COUNTIFS(I13:I287, "Split-Pay"),"") -> 9 | H3: Offer To Close Rate: | I3: =IFERROR(I10/I9,"") -> 0.4137931 | K3: Cancellation Rate: | L3: =iferror(F9/I6,"") -> 0 | N3: Money | O3: =IFERROR(COUNTIFS(N13:N286, "money"),"") -> 9 | Q3: YouTube | R3: =IFERROR(COUNTIF(H13:H286,Q3),"") -> 0 | S3: Twitter | T3: =IFERROR(COUNTIF(H13:H286,S3),"") -> 0
B4: Cash | C4: =IFERROR(SUM(L13:L284),"") -> 43875 | E4: Deposits: | F4: =IFERROR(COUNTIFS(I13:I287, "Deposit"),"") -> 1 | H4: Call To Offer Rate: | I4: =IFERROR(I9/I8,"") -> 1 | K4: No-Shows Rate: | L4: =iferror(F10/I6,"") -> 0.0625 | N4: Time | O4: =IFERROR(COUNTIFS(N13:N286, "time"),"") -> 1 | Q4: YouTube Ads | R4: =IFERROR(COUNTIF(H13:H286,Q4),"") -> 0 | S4: Skool | T4: =IFERROR(COUNTIF(H13:H286,S4),"") -> 0
E5: Offer & Didn't Buy: | F5: =IFERROR(COUNTIFS(I13:I287, "Offer & Didn't Buy"),"") -> 16 | H5: Drag Over Rate: | I5: =IFERROR(F7/(C6+F7+F8),"") -> 0 | K5: Drag Over Rate: | L5: =iferror(F7/I6,"") -> 0 | N5: Partner | O5: =IFERROR(COUNTIFS(N13:N286, "partner"),"") -> 0 | Q5: Email | R5: =IFERROR(COUNTIF(H13:H286,Q5),"") -> 0 | S5: Instagram | T5: =IFERROR(COUNTIF(H13:H286,S5),"") -> 0
B6: Total Calls : | C6: =IFERROR(SUM(F2:F6),"") -> 29 | E6: Bad Fit & No Offer: | F6: =IFERROR(COUNTIFS(I13:I287, "Bad Fit & No Offer"),"") -> 0 | H6: Bookings: | I6: =IFERROR(SUM(F2:F10),"") -> 32 | K6: Show-Up Rate: | L6: =iferror(I7/I6,"") -> 0.90625 | N6: Fear | O6: =IFERROR(COUNTIFS(N13:N286, "fear"),"") -> 2 | Q6: Facebook | R6: =IFERROR(COUNTIF(H13:H286,Q6),"") -> 0 | S6: TikTok | T6: =IFERROR(COUNTIF(H13:H286,S6),"") -> 0
B7: Total Won : | C7: =IFERROR(F2+F3,"") -> 12 | E7: Drag Over & Show: | F7: =IFERROR(COUNTIFS(I13:I287, "Drag Over & Show"),"") -> 0 | H7: Shows: | I7: =IFERROR(SUM(F2:F7),"") -> 29 | K7: Conducted Rate: | L7: =IFERROR(I8/I6,"") -> 0.90625 | N7: Value | O7: =IFERROR(COUNTIFS(N14:N287, "value"),"") -> 3 | Q7: Facebook Ads | R7: =IFERROR(COUNTIF(H13:H286,Q7),"") -> 0 | S7: Google | T7: =IFERROR(COUNTIF(H13:H286,S7),"") -> 0
B8: Total Lost : | C8: =COUNTIF(I13:I286,"offer & didn't buy")+countif(I13:I286,"deposit")+countif(I13:I286,"bad fit & no offer") -> 17 | E8: Rescheduled: | F8: =IFERROR(COUNTIFS(I13:I287, "Rescheduled"),"") -> 1 | H8: Calls: | I8: =IFERROR(SUM(F2:F6),"") -> 29 | Q8: LinkedIn | R8: =IFERROR(COUNTIF(H13:H286,Q8),"") -> 0 | S8: Referral | T8: =IFERROR(COUNTIF(H13:H286,S8),"") -> 0
B9: Closing % : | C9: =iferror(SUM(C7/C6),"") -> 0.4137931 | E9: Cancelled: | F9: =IFERROR(COUNTIFS(I13:I287, "Cancelled"),"") -> 0 | H9: Offers: | I9: =IFERROR(sum(F2:F5),"") -> 29
B10: Rev per lead | C10: =C3/C6 -> 3827.5862 | E10: No-Show: | F10: =IFERROR(COUNTIFS(I13:I287, "No-Show"),"") -> 2 | H10: Deals | I10: =F2+F3 -> 12
B12: Date | C12: Name | E12: Phone No. | F12: IG | H12: Source | I12: Outcome | K12: Revenue | L12: Cash | N12: Objection | O12: Objection Notes | Q12: Length | R12: Recording Link | S12: Follow Up/Next Steps | T12: Call Summary
B13: 45870 | C13: Thomas Vasegaard | E13: 21 39 50 36 | F13: https://www.instagram.com/thomas_vasegaard/ | H13: Setter | I13: Offer & Didn't Buy | N13: Fear | O13: Lagde på da han skulle betale | S13: X
B14: 45880 | C14: Magnus Hagmann | E14: 29 87 42 00 | F14: https://www.instagram.com/magnus_hamann/ | H14: Setter | I14: Split-pay | K14: 13500 | L14: 3375 | Q14: 8 måneder | S14: Closed
B15: 45880 | C15: Zilas Andersen | E15: 21 22 09 53 | F15: https://www.instagram.com/zilaswinzini/ | H15: Setter | I15: Offer & Didn't Buy | L15: 500 | N15: Money | O15: Skulle finde ud af om mor kunne betale lidt til det og lige have den vendt med hende | S15: X | T15: Follow up onsdag kl 16
B16: 45880 | C16: Lukas Lind | E16: 23 93 79 21 | F16: https://www.instagram.com/lukas_lind_737/ | H16: Setter | I16: No-Show | S16: X
B17: 45880 | C17: Nicklas Burkal | E17: 20 35 41 33 | F17: https://www.instagram.com/nicklas.burkal/ | H17: Setter | I17: Full-Pay | K17: 9000 | L17: 3000 | Q17: 5 måneder | S17: Closed
B18: 45880 | C18: Oliver Rosenvinge | E18: 30 24 23 71 | F18: https://www.instagram.com/olirosenvinge/ | H18: Setter | I18: Rescheduled | S18: X
B19: 45881 | C19: Christian Rasmussen | E19: 22 89 44 83 | F19: https://www.instagram.com/_christian_rasmussen_/ | H19: Setter | I19: Offer & Didn't Buy | N19: Money | O19: Havde ikke pengene sagde han kun havde et par 100 om måneden | S19: X | T19: Vidste på forhånd han nok ikke havde pengene og sagde det ogsåp tidligt i samtalen, men kørte på alligvel
B20: 45882 | C20: Mikkel Overgaard Vængtoft | E20: 22 42 65 14 | F20: https://www.instagram.com/mikkelovergaardvaengtoft/ | H20: Setter | I20: Full-Pay | K20: 9000 | L20: 9000 | Q20: 5 måneder | S20: Closed
B21: 45883 | C21: Ofelia Branco | E21: 60 20 08 33 | F21: https://www.instagram.com/ofelia_branco7/ | H21: Setter | I21: Offer & Didn't Buy | S21: X
B22: 45883 | C22: Mikkel Vielsted | E22: 22302167 | H22: Landing page | I22: Split-pay | K22: 9000 | L22: 3000 | Q22: 5 måneder | S22: Closed
B23: 45885 | C23: Cathrine Ottzen | E23: 21 90 50 48 | F23: https://www.instagram.com/cath_ottzen/ | H23: Setter | I23: Split-pay | K23: 9000 | L23: 3000 | Q23: 5 måneder | S23: Closed
B24: 45886 | C24: Andreas Olesen | E24: 24 67 36 87 | F24: https://www.instagram.com/andreas.ole/ | H24: Setter | I24: Split-pay | K24: 9000 | L24: 3000 | Q24: 5 måneder | S24: Closed
B25: 45887 | C25: Victoria Taulbæk | E25: 21 22 17 85 | F25: https://www.instagram.com/victoriataulbaek/ | H25: Setter | I25: Offer & Didn't Buy | N25: Money | O25: Var alt for mange penge | S25: X | T25: Ikke det rigtige fit, hun var fast besluttet på hun kun skulle have en træningsplan, og hun allerde følte hun havde meldt det kun var det for hendes økonomi slet ikke var til det. Så hun var egenligt lidt ærgerlig over at have brug tid på det når vi ikke kunne imødekomme hendes behov
B26: 45887 | C26: Brit Knudsen | E26: 60 12 59 75 | F26: https://www.instagram.com/brit_knudsen/ | H26: Setter | I26: No-Show | S26: Follow Up
B27: 45888 | C27: Mikkel Holm | E27: 30 95 89 69 | F27: https://www.instagram.com/mikkelholm__/ | H27: Setter | I27: Offer & Didn't Buy | N27: Think About It | S27: X | T27: Han ville fucking skulle bare tænke over det og sove på den kunne ikke få ham overbevidt om han bare skulle gøre
B28: 45888 | C28: Arnaq Pjettursson | E28: 28 96 98 67 | F28: https://www.instagram.com/arnaqpjettursson/ | H28: Setter | I28: Offer & Didn't Buy | N28: Time | O28: Skulle til Grønland | S28: X | T28: Hun starter op 1. september, Modtog en SMS her til aften, så havde hun bare lige glemt hun skulle på Grønland til sin hjemby så det kunne ikke lade sig gøre alligevel
B29: 45889 | C29: Signe Holck | E29: 22 43 44 30 | F29: https://www.instagram.com/signeholck93/ | H29: Setter | I29: Offer & Didn't Buy | N29: Money | O29: Hun siger hun skal tænke over det, men det nok faktisk var pengene | S29: Follow Up Set | T29: Hun vil super gerne også noget der var vigtigt for hende at finde en løsning på, hun skulle bare lige vende den om det var det hun skulle. Følger op på hende 5. september
B30: 45889 | C30: Kristine Aagaard | E30: 30 29 33 30 | F30: https://www.instagram.com/kristineaagaard/ | H30: Setter | I30: Offer & Didn't Buy | N30: Value | O30: Vidste ikke om det ville være pengene værd i forhold til hvor hun stod. Vil også rigtigt gerne have noget på skrift | S30: X | T30: Har aftalt at ringe til hende om en uge eller 2. Syntes egenligt jeg finder noget pain og hun havde et mål om at stå skarpt til sit bryllup, men vidste ikke om det værd pengene, og vil gerne undersøge andre muligheder og om hun kunne gøre det selv eller der var et alternativ
B31: 45891 | C31: Emma Juliane | E31: 25 79 76 90 | F31: https://www.instagram.com/emma_juliane05/ | H31: Setter | I31: Split-pay | K31: 7500 | L31: 3000 | N31: Money | O31: Skulle være sikker på det kunne løbe rundt og have hjælp af mor til at få lagt et budget | Q31: Indtil 1. december | S31: Closed | T31: Var frisk på det hele syntes det var det helt rigtige, hun skulle bare være sikker på hun kunne få det til at ske økonomisk, fordi hun havde en meget ustabil inkomst. Ringer til hende i morgen før kl 13
B32: 45891 | C32: Simone Schønning Larsen | E32: 29 87 58 50 | F32: https://www.instagram.com/simone_schonning1/ | H32: Setter | I32: Offer & Didn't Buy | N32: Money | O32: Sagde det var pengene, men var noget fear | S32: X | T32: Ringer på mandag til hende kl 16. Syntes snakken var god og hun var klar og sagde egenligt ja, men så kom undskuldninger og fik dem krydset godt af, det var helt irrationelt at hun skulle tænke over det
B33: 45892 | C33: Leonie Simsch | E33: 71 48 71 43 | F33: https://www.instagram.com/leoniesimsch/ | H33: Setter | I33: Split-pay | K33: 9000 | L33: 3000 | N33: Value | O33: Om det virkeligt var noget hun ville prioriterer frem for en skiferie eller en racercykel | Q33: 5 måneder | S33: Closed | T33: Syntes vi havde en god snak og fik lagt en rigtigt god plan for hende, hendes store bekymring var om det var pengene værd, hun siger egenligt det ville være og var klar til at gennemgå økonomien med mig, men det sagde hun at hun ikke havde tid til, så det gør vi på tirsdag
B34: 45892 | C34: Sophia de Linde | E34: 31 38 06 05 | F34: https://www.instagram.com/sophiadelinde/ | H34: Setter | I34: Split-pay | K34: 9000 | L34: 3000 | Q34: 5 måneder | S34: Closed | T34: Så god snak fik hende bar solgt
B35: 45892 | C35: Sara Eram | E35: 61 67 10 07 | F35: https://www.instagram.com/s_eram/ | H35: Setter | I35: Offer & Didn't Buy | N35: Fear | O35: Hun havde meget svært ved at få hjælp ude fra havde altid klaret tingene selv | S35: X | T35: Det var det rigtige for hende og hun fik Tony Robins talen og det hele og var milimeter fra at sige ja, men hun har bare så svært ved at be om hjælp fordi hun ser sig selv som den her stærke kvinde, der ikke har brug for hjælp
B36: 45894 | C36: Emilia Børresen | E36: 60 61 51 04 | F36: https://www.instagram.com/_emilia_borresen_/ | H36: Setter | I36: Deposit
B37: 45894 | C37: Simon Sloth | E37: 61 71 24 73 | F37: https://www.instagram.com/simon_sloth_/ | H37: Landing page | I37: Offer & Didn't Buy | N37: Think About It | O37: Havde allerede booket møde med en anden coach | S37: X | T37: Han sagde det var det helt rigtige for ham, men ville hører hvad en anden kunne tilbyde og om det bare var det "samme" og så gå med det billigste. Spørger ham om det det billigste også var det bedst "nej det var det jo ikke så kunen det være man ikke gik lige små meget op i det. Follow up i morgen kl 12
B38: 45895 | C38: Christina Vammen Andreassen | E38: 28 19 88 56 | F38: https://www.instagram.com/christinavammen88/ | H38: Setter | I38: Offer & Didn't Buy | N38: Money | O38: Nogle måneder havde hun pengene, men andre havde hun ikke | S38: Follow Up Set | T38: Hun var så klar og syntes det var mega fedt. Hun var bare ikke sikker på om hun kunne skrabe 1500 kr. sammen alle månederne da hun pt gik sygmeldt. Så vi har lagt en plan for hun laver et budget og jeg ringer til hende igen d. 1 Sep. Skulle have været lidt bedre i objection handling følg nu bare det script og få krydset en ting af ad gangen
B39: 45897 | C39: Mette Lassen Matthiasen | E39: 22 77 67 77 | F39: https://www.instagram.com/mettelassen86/ | H39: Setter | I39: Offer & Didn't Buy | N39: Value | O39: At den energi hun havde set og faktisk købt ind i fra både mig men også Daniel var det hun fik | S39: Follow Up Set | T39: Fandt super meget pain og brugt lang tid på det, og hun siger det lød som det rigtige for hende især efter tidligere dårlige oplevelser med coaching, det her var meget mere hende. Kunne ikke nå at negotiate, fordi hun fakitsk var på arbejde og ikke havde mere tid. Booker en snak ind til hende med Daniel på mandag
B40: 45897 | C40: Mia Vejrum | E40: 25 70 06 44 | F40: https://www.instagram.com/mia_vejrum/ | H40: Setter | I40: Split-pay | K40: 9000 | L40: 500 | Q40: 5 måneder | S40: Closed | T40: Syntes det var en mega god snak, kom hurtigt til pointe og hendes pain, og fik hende bare solgt godt. De kunne først betale til oktober, men kunne smide 500 kr. nu og så komme i gang, og så betale første invoice til oktober
B41: 45897 | C41: Frederik Lüth | E41: 60 53 06 09 | F41: https://www.instagram.com/friddeluth?igsh=MTRrcGg4MGM3cHFmdQ== | H41: Setter | I41: Offer & Didn't Buy | N41: Money | O41: Syntes det var mange penge og skulle tænke over det for han budget var ret høj | S41: X | T41: Vi vibede ret godt og lavede nogle jokes undervejs, han ville passe perfekt ind. Var svær at finde noget pain ved, men fandt da noget, kunne sagtens have været bedre. Kunne godt have objection handlede bedre også
...

Sheet Sep
B1: Rep: | C1: Name | E1: Anton KPI's | H1: Outcome | K1: KPIs% | N1: Show Rate | Q1: Objections | S1: kvinde/mand
E2: Rev per call | F2: =C3/C6 -> 3319.6721 | H2: Full-Pay: | I2: =IFERROR(COUNTIFS(I13:I286, "Full-Pay"),"") -> 1 | K2: Conversion Rate: | L2: =iferror(L10/L8,"") -> 0.31147541 | N2: Rescheduling Rate: | O2: =iferror(I8/L6,"") -> 0.071428571 | Q2: Think About It | R2: =IFERROR(COUNTIFS(N13:N285, "think about it"),"") -> 1 | S2: Kvinde kald | T2: =COUNTIF(F13:F359,"Kvinde") -> 0
B3: Revenue | C3: =IFERROR(SUM(K13:K282),"") -> 202500 | E3: Cash per call | F3: =C4/C6 -> 904.09836 | H3: Split-Pay: | I3: =IFERROR(COUNTIFS(I13:I286, "Split-Pay"),"") -> 18 | K3: Offer To Close Rate: | L3: =IFERROR(L10/L9,"") -> 0.3220339 | N3: Cancellation Rate: | O3: =iferror(I9/L6,"") -> 0.042857143 | Q3: Money | R3: =IFERROR(COUNTIFS(N13:N285, "money"),"") -> 26 | S3: Mande kald | T3: =COUNTIF(F13:F359,"Mand") -> 0
B4: Cash | C4: =IFERROR(SUM(L13:L283),"") -> 55150 | E4: Cash upfront % | F4: =C4/C3*100 -> 27.234568 | H4: Deposits: | I4: =IFERROR(COUNTIFS(I13:I286, "Deposit"),"") -> 8 | K4: Call To Offer Rate: | L4: =IFERROR(L9/L8,"") -> 0.96721311 | N4: No-Shows Rate: | O4: =iferror(I10/L6,"") -> 0.014285714 | Q4: Time | R4: =IFERROR(COUNTIFS(N13:N285, "time"),"") -> 6 | S4: Kvinde salg | T4: =COUNTIFS($F13:$F359,E2,$I13:$I359,"Split-pay","Full-pay") -> #N/A
E5: PIF % | F5: =I2/C7*100 -> 5.2631579 | H5: Offer & Didn't Buy: | I5: =IFERROR(COUNTIFS(I13:I286, "Offer & Didn't Buy"),"") -> 32 | K5: Drag Over Rate: | L5: =IFERROR(I7/(C6+I7+I8),"") -> 0 | N5: Drag Over Rate: | O5: =iferror(I7/L6,"") -> 0 | Q5: Partner | R5: =IFERROR(COUNTIFS(N13:N285, "partner"),"") -> 6 | S5: Mande salg | T5: =IFERROR(COUNTIF(G13:G285,S5),"") -> 0
B6: Total Calls : | C6: =IFERROR(SUM(I2:I6),"") -> 61 | E6: Average Binding | F6: =AVERAGE(Q13:Q103) -> 6.2222222 | H6: Bad Fit & No Offer: | I6: =IFERROR(COUNTIFS(I13:I286, "Bad Fit & No Offer"),"") -> 2 | K6: Bookings: | L6: =IFERROR(SUM(I2:I10),"") -> 70 | N6: Show-Up Rate: | O6: =iferror(L7/L6,"") -> 0.87142857 | Q6: Fear | R6: =IFERROR(COUNTIFS(N13:N285, "fear"),"") -> 3 | S6: Kvinde closing % | T6: =IFERROR(COUNTIF(G13:G285,S6),"") -> 0
B7: Total Won : | C7: =IFERROR(I2+I3,"") -> 19 | E7: Average deal | F7: =C3/C7 -> 10657.895 | H7: Drag Over & Show: | I7: =IFERROR(COUNTIFS(I13:I286, "Drag Over & Show"),"") -> 0 | K7: Shows: | L7: =IFERROR(SUM(I2:I7),"") -> 61 | N7: Conducted Rate: | O7: =IFERROR(L8/L6,"") -> 0.87142857 | Q7: Value | R7: =IFERROR(COUNTIFS(N14:N286, "value"),"") -> 0 | S7: Mande closing % | T7: =IFERROR(COUNTIF(G13:G285,S7),"") -> 0
B8: Total Lost : | C8: =COUNTIF(I13:I285,"offer & didn't buy")+countif(I13:I285,"deposit")+countif(I13:I285,"bad fit & no offer") -> 42 | E8: Average cash | F8: =C4/C7 -> 2902.6316 | H8: Rescheduled: | I8: =IFERROR(COUNTIFS(I13:I286, "Rescheduled"),"") -> 5 | K8: Calls: | L8: =IFERROR(SUM(I2:I6),"") -> 61
B9: Closing % : | C9: =iferror(SUM(C7/C6),"") -> 0.31147541 | H9: Cancelled: | I9: =IFERROR(COUNTIFS(I13:I286, "Cancelled"),"") -> 3 | K9: Offers: | L9: =IFERROR(sum(I2:I5),"") -> 59
H10: No-Show: | I10: =IFERROR(COUNTIFS(I13:I286, "No-Show"),"") -> 1 | K10: Deals | L10: =I2+I3 -> 19
B12: Date | C12: Name | E12: Phone No. | F12: Ig | H12: Source | I12: Outcome | K12: Revenue | L12: Cash | N12: Objection | O12: Objection Notes | Q12: Length | R12: Recording Link | S12: Follow Up/Next Steps | T12: Call Summary
B13: 45901 | C13: Mikkel Vielsted | E13: 22302167 | H13: Landing page | I13: Split-pay | K13: 9000 | L13: 3000 | Q13: 5 | S13: Closed
B14: 45902 | C14: Josephine Alexandra Abildtrup | E14: 51 15 03 22 | H14: Setter | I14: Full-Pay | K14: 9000 | L14: 9000 | Q14: 5 | S14: Closed
B15: 45902 | C15: Jonathan Mikkelsen | E15: 61 28 53 09 | H15: Setter | I15: Bad Fit & No Offer | N15: Partner | S15: Follow Up | T15: Han havde nogle fysiske og mentale udfordringer, og stod ikke selv for sin økonomi. Fandt rigtigt meget pain og han ville også gøre det, hvis han selv stod for sin økonomi, men det er desværre forældrene, der gør det. Så har aftalt han skriver til sin forældre, om de har tid. Han nævnte hans forældre var ligeglad med ham og hvordan han havde og de ikke ville støtte ham
B16: 45903 | C16: Jesper Stubkjær Hummelmose Brühl | E16: 28 34 95 83 | H16: Setter | I16: Offer & Didn't Buy | N16: Time | S16: Follow Up | T16: Sagde flere gange til at starte med at det ikke var et forløb han var ude i han det troede det var var en guidet snak, men syntes egenligt jeg fik ham overtalt og endte dag også med at pitche for ham, men han skulle føle sig klar mentalt og havde også en brækket hånd der skulle styr på. Var nødt til at afslutte samtalen fordi hans børn stod og råbte i baggrunden
B17: 45903 | C17: Lucas Denker | E17: 53 82 56 58 | H17: Setter | I17: No-Show | S17: Follow Up
B18: 45904 | C18: Emil Engel | E18: 20 72 55 62 | H18: Setter | I18: Bad Fit & No Offer | O18: Havde ingen intentioner om at starte op og mener det kun var "Daniel dert havde presset på i forhold til en samtale" | S18: Follow Up
B19: 45906 | C19: Linda Hvidberg Sørensen | E19: 24 22 88 47 | H19: Setter | I19: Split-pay | K19: 10500 | L19: 2650 | N19: Time | O19: Hun havde nogle blodprøver fra læge som hun lige skulle have svar på, på mandag | S19: Closed | T19: Ringer til hende igen på mandag
B20: 45906 | C20: Pola Karim | E20: 31 17 16 86 | H20: Setter | I20: Split-pay | K20: 10500 | L20: 3000 | Q20: 6 | S20: Closed
B21: 45907 | C21: Michael Rasmussen | E21: 60 27 73 39 | H21: Setter | I21: Offer & Didn't Buy | N21: Fear | S21: Follow Up | T21: Kunne ikke få sig selv til at gøre det og tage i mod hjælpen, gjorde alt der stod i min magt
B22: 45907 | C22: Magnus Lazarotti | E22: 30 86 51 86 | H22: Setter | I22: Offer & Didn't Buy | N22: Partner | O22: Det er han forældre der styrer hans økonomi | S22: Follow Up | T22: Han var så frisk på det, men var nervøs for hans forældre ikke ville se værdien i det og syntes det var for mange penge, så får et kald med ham og dem på onsdag eller i weekenden
B23: 45908 | C23: Mia Frederiksen | E23: 21 51 08 09 | H23: Setter | I23: Split-pay | K23: 13500 | L23: 3000 | Q23: 8 | S23: Closed
B24: 45908 | C24: Bertram A. Rosendal Fagerlind | E24: 25 19 17 27 | H24: Setter | I24: Offer & Didn't Buy | N24: Money | O24: Havde pengene, men hvis ha brugte dem på det her havde han ikke penge til noget andet | S24: Follow Up | T24: Ringer til ham igen i morgen. Syntes egenligt jeg var god på snakken. Han sagde han havde 100 kr. tilbage, hvis han brugte pengene på det så vil undersøge om han kunne tage noget fra opsparringen, men havde ikke selv adgang til den så skulle spørge en af sin forældre
B25: 45910 | C25: Therese S. Langfjord | E25: 42 83 04 42 | H25: Setter | I25: Offer & Didn't Buy | N25: Time | O25: En blanding af timing ifht. job og økonomien så hun var 100 procent klar | S25: Follow Up Set | T25: Follow-up Fredag kl 13. Hun ville sygt gerne hun skulle bare have alle brikkerne til at falde på plads, så følte faktisk ikke jeg ville presse hende for meget, for hun virkede virkeligt oprigtig og ærlig
